Workbook
Name \0: #REF!
Name \A: #REF!
Name \B: #REF!
Name \C: #REF!
Name \E: #REF!
Name \F: #REF!
Name \G: #REF!
Name \J: #REF!
Name \K: #REF!
Name \L: #REF!
Name \P: #REF!
Name \R: #REF!
Name \RL: #REF!
Name \S: #REF!
Name \U: #REF!
Name \v: #REF!
Name \X: #REF!
Name \Y: #REF!
Name _: #REF!
Name __: #REF!
Name ___: #REF!
Name ____: #REF!
Name _____: #REF!
Name _____gas87: #REF!
Name _____gas91: #REF!
Name _____gas93: #REF!
Name _____gas95: #REF!
Name ____gas87: #REF!
Name ____gas91: #REF!
Name ____gas93: #REF!
Name ____gas95: #REF!
Name ___gas87: #REF!
Name ___gas91: #REF!
Name ___gas93: #REF!
Name ___gas95: #REF!
Name __gas87: #REF!
Name __gas91: #REF!
Name __gas93: #REF!
Name __gas95: #REF!
Name _1: #REF!
Name _1_: #REF!
Name _10: #REF!
Name _10t__WT: #REF!
Name _11: #REF!
Name _12: #REF!
Name _12WSOL: #REF!
Name _13: #REF!
Name _14: #REF!
Name _14W__WS: #REF!
Name _15: #REF!
Name _16: #REF!
Name _17: #REF!
Name _18: #REF!
Name _19: #REF!
Name _2: #REF!
Name _2_: #REF!
Name _20: #REF!
Name _21: #REF!
Name _2G: #REF!
Name _3: #REF!

Sheet Golden Rulebook-CDErule level
A1: DED Phase 2 | Golden DQ Rulebook – Single Source of Truth
A2: SCOPE / CDE BASELINE | H2: SUBMISSION FORMAT | AE2: REVIEW & SIGN-OFF
A3: Sprint | B3: Table Name | C3: Table ID | D3: Attribute Name | E3: Attribute ID | F3: Silver Technical ID | G3: Bronze Technical ID | H3: DQ_Rule_Key | I3: Rule ID | J3: Rule_Name_Title | K3: Business Rule Description | L3: DQ Dimension | M3: Scope_Granularity | N3: Data_Domain | O3: Business_Owner | P3: Technical_Owner | Q3: Data_Source_System | R3: Data_Table_ID | S3: Attribute_ID | T3: Rule_Type | U3: Rule_Expression_Logic | V3: Expected_Outcome_Threshold | W3: Frequency_Execution_Schedule | X3: Data_Quality_Metric_KPI | Y3: Priority_Criticality | Z3: Exceptions_Exclusions | AA3: Status | AB3: Updated_Date | AC3: Remediation_ID | AD3: Business/ Tech Rule | AE3: Business Review Required? | AF3: Business Review Status | AG3: 1st Business Review: Date & Comments | AH3: 2nd Business Review: Date & Comments | AI3: 3rd Business Review: Date & Comments | AJ3: IT Review Required? | AK3: IT Review Status | AL3: Technical Owner | AM3: 1st Technical Review: Date & Comments | AN3: 2nd Technical Review: Date & Comments | AO3: DED Data Sign-off | AP3: DED Data Comments | AQ3: C.4.4 Failed Record Log Ref | AR3: Issue Description | AS3: Remediation Action
A4: Sprint 3 | B4: basic_information | C4: DED_Data_Table_181 | D4: identification_number | E4: DED_Attribute_2717 | F4: 2f3bea9d-2853-41ed-bcbb-d2257f0248e5 | G4: 4313a3f7-b41d-4eee-9947-9d6f548d3d17 | H4: DQP-4005 | I4: DQO-4005 | J4: Val_Chk-basic_information-identification_number | K4: Check that non-null identification numbers are positive whole-number identifiers containing digits only, with no decimals, zero, negatives or non-numeric characters. | L4: Validity | M4: Attribute | N4: Business Registration & Licensing | تسجيل الأعمال والتراخيص | O4: rfmdaas@adra.gov.ae, bmalkindi@adra.gov.ae, aiaalsheebani@ded.abudhabi.ae | P4: asalmehiry@adra.gov.ae, rfmdaas@adra.gov.ae, sraalbadi@ded.abudhabi.ae | Q4: Accela | R4: DED_Data_Table_181 | S4: DED_Attribute_2717 | T4: CustomSQL | U4: identification_number RLIKE '^[1-9][0-9]*$' | V4: 1 | W4: Weekly | X4: DQI | Y4: High | Z4: basic_information | AA4: Active | AB4: 46310 | AD4: Technical | AE4: No | AF4: In Review | AJ4: Yes | AK4: Approved | AL4: Samer | AM4: 02/10/2026 - Yes - Yes means conditional technical feasibility, subject to the conditions below; it is not business approval. Apply only to basic_information.identification_number records linked to the approved Group / Type / Subtype / Category combinations in columns J:M; validate actual four-level service combinations, not a Cartesian product of the listed values. Evaluate populated identification_number only; null/blank values belong to a separately approved completeness rule. Use an explicit null/blank policy so SQL UNKNOWN is not silently counted as pass or fail. Character-format check only; it does not establish accuracy or lookup membership. Confirm the execution engine and test the regex on actual Arabic/English source samples. Pattern rejects zero and leading zeros; business must confirm this is valid for this identifier/value. Preserve identifiers as text. Translate platform-specific syntax if execution is on Oracle; otherwise validate on the nominated DQ engine. Technical assessment only, based on supplied metadata; source mapping and execution are unverified. Business owner MUST document approval of applicability, four-level service mapping, mandatory/optional status, allowed values and exceptions before implementation. Implementation team must verify final logic/filters and failed-record extracts against Accela before DED validation. | AO4: Signed Off
A5: Sprint 3 | B5: amendment_type | C5: DED_Data_Table_179 | D5: trade_name_amendment | E5: DED_Attribute_2616 | F5: d49d9cae-da9a-4eea-a69f-ef64efae366b | G5: 8f74a657-bc00-41df-b0c5-0eeb5c09d408 | H5: DQP-2926 | I5: DQO-2926 | J5: Compl_Check-amendment_type-trade_name_amendment | K5: Validate that the critical data element amendment_type.trade_name_amendment is populated and not blank for in-scope records.Profiling results were used to identify current null/blank exposure where available. | L5: Completeness | M5: Attribute | N5: Business Registration & Licensing | تسجيل الأعمال والتراخيص | O5: rfmdaas@adra.gov.ae, bmalkindi@adra.gov.ae | P5: asalmehiry@adra.gov.ae, rfmdaas@adra.gov.ae | Q5: Accela | R5: DED_Data_Table_179 | S5: DED_Attribute_2616 | T5: Custom | U5: !isNull({trade_name_amendment}) | V5: 0.95 | W5: Weekly | X5: DQI | Y5: High | Z5: {rec_status} == 'A' | AA5: Active | AB5: 46310 | AD5: Technical | AE5: No | AF5: In Review | AJ5: Yes | AK5: Approved | AL5: Samer | AM5: 30/09/2026 - Yes Service: Industrial / License / License / NA. REC_STATUS = 'A'; evaluate only where trade_name_amendment is mandatory for the service/stage; Confirm applicable amendment options; do not require every flag to be selected; an explicit No counts as populated; Non-applicable records excluded from denominator. Business confirmation required. | AO5: Signed Off
A6: Sprint 3 | B6: amendment_type | C6: DED_Data_Table_179 | D6: company_address_amendment | E6: DED_Attribute_2617 | F6: 30d50e4d-ee01-4de4-8d7a-bab188a6b7c0 | G6: 65c9373e-be12-48a8-9f08-0e854aefc158 | H6: DQP-2927 | I6: DQO-2927 | J6: Compl_Chk-amend_type-company_address_amendment | K6: Validate that the critical data element amendment_type.company_address_amendment is populated and not blank for in-scope records.Profiling results were used to identify current null/blank exposure where available. | L6: Completeness | M6: Attribute | N6: Business Registration & Licensing | تسجيل الأعمال والتراخيص | O6: rfmdaas@adra.gov.ae, bmalkindi@adra.gov.ae | P6: asalmehiry@adra.gov.ae, rfmdaas@adra.gov.ae | Q6: Accela | R6: DED_Data_Table_179 | S6: DED_Attribute_2617 | T6: Custom | U6: !isNull({company_address_amendment}) | V6: 0.95 | W6: Weekly | X6: DQI | Y6: High | Z6: {rec_status} == 'A' | AA6: Active | AB6: 46310 | AD6: Technical | AE6: No | AF6: In Review | AJ6: Yes | AK6: Approved | AL6: Samer | AM6: 30/09/2026 - Yes Approved exact four-level service paths from O:R; do not cross-combine listed subtypes/categories. REC_STATUS = 'A'; evaluate only where company_address_amendment is mandatory for the service/stage; Confirm applicable amendment options; do not require every flag to be selected; an explicit No counts as populated; Non-applicable records excluded from denominator. Business confirmation required. | AO6: Signed Off
A7: Sprint 3 | B7: amendment_type | C7: DED_Data_Table_179 | D7: partners_amendment | E7: DED_Attribute_2618 | F7: 2d6ea40f-bf95-473c-8bf9-3b6923dddf91 | G7: e9f66a7a-07da-46d4-b981-2af1f88966a2 | H7: DQP-2928 | I7: DQO-2928 | J7: Compl_Check-amendment_type-partners_amendment | K7: Validate that the critical data element amendment_type.partners_amendment is populated and not blank for in-scope records.Profiling results were used to identify current null/blank exposure where available. | L7: Completeness | M7: Attribute | N7: Business Registration & Licensing | تسجيل الأعمال والتراخيص | O7: rfmdaas@adra.gov.ae, bmalkindi@adra.gov.ae | P7: asalmehiry@adra.gov.ae, rfmdaas@adra.gov.ae | Q7: Accela | R7: DED_Data_Table_179 | S7: DED_Attribute_2618 | T7: Custom | U7: !isNull({partners_amendment}) | V7: 0.95 | W7: Weekly | X7: DQI | Y7: High | Z7: {rec_status} == 'A' | AA7: Active | AB7: 46310 | AD7: Technical | AE7: No | AF7: In Review | AJ7: Yes | AK7: Approved | AL7: Samer | AM7: 30/09/2026 - Yes Service: Industrial / License / License / NA. REC_STATUS = 'A'; evaluate only where partners_amendment is mandatory for the service/stage; Confirm applicable amendment options; do not require every flag to be selected; an explicit No counts as populated; Non-applicable records excluded from denominator. Business confirmation required. | AO7: Signed Off
A8: Sprint 3 | B8: amendment_type | C8: DED_Data_Table_179 | D8: raw_material_amendment | E8: DED_Attribute_2619 | F8: 81494825-2a7d-49bf-9c02-49c15a23eea0 | G8: d6b366e8-b292-442b-8781-15282aa657ec | H8: DQP-2929 | I8: DQO-2929 | J8: Compl_Chk-amendment_type-raw_material_amendment | K8: Validate that the critical data element amendment_type.raw_material_amendment is populated and not blank for in-scope records.Profiling results were used to identify current null/blank exposure where available. | L8: Completeness | M8: Attribute | N8: Business Registration & Licensing | تسجيل الأعمال والتراخيص | O8: rfmdaas@adra.gov.ae, bmalkindi@adra.gov.ae | P8: asalmehiry@adra.gov.ae, rfmdaas@adra.gov.ae | Q8: Accela | R8: DED_Data_Table_179 | S8: DED_Attribute_2619 | T8: Custom | U8: !isNull({raw_material_amendment}) | V8: 0.95 | W8: Weekly | X8: DQI | Y8: High | Z8: {rec_status} == 'A' | AA8: Active | AB8: 46310 | AD8: Technical | AE8: No | AF8: In Review | AJ8: Yes | AK8: Approved | AL8: Samer | AM8: 30/09/2026 - Yes Approved exact four-level service paths from O:R; do not cross-combine listed subtypes/categories. REC_STATUS = 'A'; evaluate only where raw_material_amendment is mandatory for the service/stage; Confirm applicable amendment options; do not require every flag to be selected; an explicit No counts as populated; Non-applicable records excluded from denominator. Business confirmation required. | AO8: Signed Off
A9: Sprint 3 | B9: amendment_type | C9: DED_Data_Table_179 | D9: activity_amendment | E9: DED_Attribute_2620 | F9: 73b50fcf-a942-475c-b122-0af54333b82b | G9: fe79f012-4600-4093-b0fa-75513d370326 | H9: DQP-2930 | I9: DQO-2930 | J9: Compl_Check-amendment_type-activity_amendment | K9: Validate that the critical data element amendment_type.activity_amendment is populated and not blank for in-scope records.Profiling results were used to identify current null/blank exposure where available. | L9: Completeness | M9: Attribute | N9: Business Registration & Licensing | تسجيل الأعمال والتراخيص | O9: rfmdaas@adra.gov.ae, bmalkindi@adra.gov.ae | P9: asalmehiry@adra.gov.ae, rfmdaas@adra.gov.ae | Q9: Accela | R9: DED_Data_Table_179 | S9: DED_Attribute_2620 | T9: Custom | U9: !isNull({activity_amendment}) | V9: 0.95 | W9: Weekly | X9: DQI | Y9: High | Z9: {rec_status} == 'A' | AA9: Active | AB9: 46310 | AD9: Technical | AE9: No | AF9: In Review | AJ9: Yes | AK9: Approved | AL9: Samer | AM9: 30/09/2026 - Yes Approved exact four-level service paths from O:R; do not cross-combine listed subtypes/categories. REC_STATUS = 'A'; evaluate only where activity_amendment is mandatory for the service/stage; Confirm applicable amendment options; do not require every flag to be selected; an explicit No counts as populated; Non-applicable records excluded from denominator. Business confirmation required. | AO9: Signed Off
A10: Sprint 3 | B10: amendment_type | C10: DED_Data_Table_179 | D10: service_amendment | E10: DED_Attribute_2621 | F10: 66e72d2f-f7ab-4331-99ed-53728eb1f65e | G10: 95623e78-5286-46dd-9059-0f66531b9d4c | H10: DQP-2931 | I10: DQO-2931 | J10: Compl_Check-amendment_type-service_amendment | K10: Validate that the critical data element amendment_type.service_amendment is populated and not blank for in-scope records.Profiling results were used to identify current null/blank exposure where available. | L10: Completeness | M10: Attribute | N10: Business Registration & Licensing | تسجيل الأعمال والتراخيص | O10: rfmdaas@adra.gov.ae, bmalkindi@adra.gov.ae | P10: asalmehiry@adra.gov.ae, rfmdaas@adra.gov.ae | Q10: Accela | R10: DED_Data_Table_179 | S10: DED_Attribute_2621 | T10: Custom | U10: !isNull({service_amendment}) | V10: 0.95 | W10: Weekly | X10: DQI | Y10: High | Z10: {rec_status} == 'A' | AA10: Active | AB10: 46310 | AD10: Technical | AE10: No | AF10: In Review | AJ10: Yes | AK10: Approved | AL10: Samer | AM10: 30/09/2026 - Yes Approved exact four-level service paths from O:R; do not cross-combine listed subtypes/categories. REC_STATUS = 'A'; evaluate only where service_amendment is mandatory for the service/stage; Confirm applicable amendment options; do not require every flag to be selected; an explicit No counts as populated; Non-applicable records excluded from denominator. Business confirmation required. | AO10: Signed Off
A11: Sprint 3 | B11: amendment_type | C11: DED_Data_Table_179 | D11: investment_amendment | E11: DED_Attribute_2622 | F11: f0caffc5-be9d-4de5-aa9f-9ccb5d8e7244 | G11: 1a51593e-19fa-43f4-b5fa-5a32f35b73a7 | H11: DQP-2932 | I11: DQO-2932 | J11: Compl_Check-amendment_type-investment_amendment | K11: Validate that the critical data element amendment_type.investment_amendment is populated and not blank for in-scope records.Profiling results were used to identify current null/blank exposure where available. | L11: Completeness | M11: Attribute | N11: Business Registration & Licensing | تسجيل الأعمال والتراخيص | O11: rfmdaas@adra.gov.ae, bmalkindi@adra.gov.ae | P11: asalmehiry@adra.gov.ae, rfmdaas@adra.gov.ae | Q11: Accela | R11: DED_Data_Table_179 | S11: DED_Attribute_2622 | T11: Custom | U11: !isNull({investment_amendment}) | V11: 0.95 | W11: Weekly | X11: DQI | Y11: High | Z11: {rec_status} == 'A' | AA11: Active | AB11: 46310 | AD11: Technical | AE11: No | AF11: In Review | AJ11: Yes | AK11: Approved | AL11: Samer | AM11: 30/09/2026 - Yes Approved exact four-level service paths from O:R; do not cross-combine listed subtypes/categories. REC_STATUS = 'A'; evaluate only where investment_amendment is mandatory for the service/stage; Confirm applicable amendment options; do not require every flag to be selected; an explicit No counts as populated; Only where an investment contract/project is applicable; Non-applicable records excluded from denominator. Business confirmation required. | AO11: Signed Off
A12: Sprint 3 | B12: amendment_type | C12: DED_Data_Table_179 | D12: normal_license_to_foreign_investor_amendment | E12: DED_Attribute_2623 | F12: 41d3ce98-9d1f-486d-a45a-633217ceacde | G12: 8787cdd2-ce79-4093-b8fa-e977746a4096 | H12: DQP-2933 | I12: DQO-2933 | J12: Comp_Chk-amen_typ-normal_lice_to_fore_inve_amen | K12: Validate that the critical data element amendment_type.normal_license_to_foreign_investor_amendment is populated and not blank for in-scope records.Profiling results were used to identify current null/blank exposure where available. | L12: Completeness | M12: Attribute | N12: Business Registration & Licensing | تسجيل الأعمال والتراخيص | O12: rfmdaas@adra.gov.ae, bmalkindi@adra.gov.ae | P12: asalmehiry@adra.gov.ae, rfmdaas@adra.gov.ae | Q12: Accela | R12: DED_Data_Table_179 | S12: DED_Attribute_2623 | T12: Custom | U12: !isNull({normal_license_to_foreign_investor_amendment}) | V12: 0.95 | W12: Weekly | X12: DQI | Y12: High | Z12: {rec_status} == 'A' | AA12: Active | AB12: 46310 | AD12: Technical | AE12: No | AF12: In Review | AJ12: Yes | AK12: Approved | AL12: Samer | AM12: 30/09/2026 - Yes Approved exact four-level service paths from O:R; do not cross-combine listed subtypes/categories. REC_STATUS = 'A'; evaluate only where normal_license_to_foreign_investor_amendment is mandatory for the service/stage; Confirm applicable amendment options; do not require every flag to be selected; an explicit No counts as populated; Non-applicable records excluded from denominator. Business confirmation required. | AO12: Signed Off
A13: Sprint 3 | B13: amendment_type | C13: DED_Data_Table_179 | D13: legal_type_amendment | E13: DED_Attribute_2624 | F13: 5daab735-2fce-45dc-9dea-a922c398a4d6 | G13: c2d627ef-5821-4d79-99d6-d55576d37f2c | H13: DQP-2934 | I13: DQO-2934 | J13: Compl_Check-amendment_type-legal_type_amendment | K13: Validate that the critical data element amendment_type.legal_type_amendment is populated and not blank for in-scope records.Profiling results were used to identify current null/blank exposure where available. | L13: Completeness | M13: Attribute | N13: Business Registration & Licensing | تسجيل الأعمال والتراخيص | O13: rfmdaas@adra.gov.ae, bmalkindi@adra.gov.ae | P13: asalmehiry@adra.gov.ae, rfmdaas@adra.gov.ae | Q13: Accela | R13: DED_Data_Table_179 | S13: DED_Attribute_2624 | T13: Custom | U13: !isNull({legal_type_amendment}) | V13: 0.95 | W13: Weekly | X13: DQI | Y13: High | Z13: {rec_status} == 'A' | AA13: Active | AB13: 46310 | AD13: Technical | AE13: No | AF13: In Review | AJ13: Yes | AK13: Approved | AL13: Samer | AM13: 30/09/2026 - Yes Approved exact four-level service paths from O:R; do not cross-combine listed subtypes/categories. REC_STATUS = 'A'; evaluate only where legal_type_amendment is mandatory for the service/stage; Confirm applicable amendment options; do not require every flag to be selected; an explicit No counts as populated; Non-applicable records excluded from denominator. Business confirmation required. | AO13: Signed Off
A14: Sprint 3 | B14: amendment_type | C14: DED_Data_Table_179 | D14: hse_details_amendment | E14: DED_Attribute_2625 | F14: 23514162-2ce4-4e70-adb9-0a05a4995dbd | G14: 08a928ea-96af-4d8a-a078-62a9b4ed58a9 | H14: DQP-2935 | I14: DQO-2935 | J14: Compl_Chk-amendment_type-hse_details_amendment | K14: Validate that the critical data element amendment_type.hse_details_amendment is populated and not blank for in-scope records.Profiling results were used to identify current null/blank exposure where available. | L14: Completeness | M14: Attribute | N14: Business Registration & Licensing | تسجيل الأعمال والتراخيص | O14: rfmdaas@adra.gov.ae, bmalkindi@adra.gov.ae | P14: asalmehiry@adra.gov.ae, rfmdaas@adra.gov.ae | Q14: Accela | R14: DED_Data_Table_179 | S14: DED_Attribute_2625 | T14: Custom | U14: !isNull({hse_details_amendment}) | V14: 0.95 | W14: Weekly | X14: DQI | Y14: High | Z14: {rec_status} == 'A' | AA14: Active | AB14: 46310 | AD14: Technical | AE14: No | AF14: In Review | AJ14: Yes | AK14: Approved | AL14: Samer | AM14: 30/09/2026 - Yes Approved exact four-level service paths from O:R; do not cross-combine listed subtypes/categories. REC_STATUS = 'A'; evaluate only where hse_details_amendment is mandatory for the service/stage; Confirm applicable amendment options; do not require every flag to be selected; an explicit No counts as populated; Non-applicable records excluded from denominator. Business confirmation required. | AO14: Signed Off
A15: Sprint 3 | B15: amendment_type | C15: DED_Data_Table_179 | D15: partners_shares_amendment | E15: DED_Attribute_2626 | F15: 6624d091-ad95-4178-8568-450d51de9bda | G15: a669c62b-30b1-47be-93a5-692b547f1a97 | H15: DQP-2936 | I15: DQO-2936 | J15: Compl_Chk-amendm_type-partners_shares_amendment | K15: Validate that the critical data element amendment_type.partners_shares_amendment is populated and not blank for in-scope records.Profiling results were used to identify current null/blank exposure where available. | L15: Completeness | M15: Attribute | N15: Business Registration & Licensing | تسجيل الأعمال والتراخيص | O15: rfmdaas@adra.gov.ae, bmalkindi@adra.gov.ae | P15: asalmehiry@adra.gov.ae, rfmdaas@adra.gov.ae | Q15: Accela | R15: DED_Data_Table_179 | S15: DED_Attribute_2626 | T15: Custom | U15: !isNull({partners_shares_amendment}) | V15: 0.95 | W15: Weekly | X15: DQI | Y15: High | Z15: {rec_status} == 'A' | AA15: Active | AB15: 46310 | AD15: Technical | AE15: No | AF15: In Review | AJ15: Yes | AK15: Approved | AL15: Samer | AM15: 30/09/2026 - Yes Service: Industrial / License / License / NA. REC_STATUS = 'A'; evaluate only where partners_shares_amendment is mandatory for the service/stage; Confirm applicable amendment options; do not require every flag to be selected; an explicit No counts as populated; Non-applicable records excluded from denominator. Business confirmation required. | AO15: Signed Off
... A32: Sprint 3 | B32: amendment_type | C32: DED_Data_Table_179 | D32: signboard_amendment | E32: DED_Attribute_2644 | F32: 5bd0197f-c8d1-4e61-bc4c-76fd0b7f3746 | G32: 8fd8f4a3-b576-4821-ae55-438fc9d9d905 | H32: DQP-2953 | I32: DQO-2953 | J32: Compl_Chk-amendment_type-signboard_amendment | K32: Validate that the critical data element amendment_type.signboard_amendment is populated and not blank for in-scope records.Profiling results were used to identify current null/blank exposure where available. | L32: Completeness | M32: Attribute | N32: Business Registration & Licensing | تسجيل الأعمال والتراخيص | O32: rfmdaas@adra.gov.ae, bmalkindi@adra.gov.ae | P32: asalmehiry@adra.gov.ae, rfmdaas@adra.gov.ae | Q32: Accela | R32: DED_Data_Table_179 | S32: DED_Attribute_2644 | T32: Custom | U32: !isNull({signboard_amendment}) | V32: 0.95 | W32: Weekly | X32: DQI | Y32: High | Z32: {rec_status} == 'A' | AA32: Active | AB32: 46310 | AD32: Technical | AE32: No | AF32: In Review | AJ32: Yes | AK32: Rejected | AL32: Samer | AM32: 30/09/2026 - No | AO32: Signed Off
A33: Sprint 3 | B33: amendment_type | C33: DED_Data_Table_179 | D33: amend_beneficiaries | E33: DED_Attribute_2645 | F33: 7a671bfb-ea51-460f-8c51-1c22f01bcd2c | G33: de6c39a2-442a-4a77-9502-078f90e9ad45 | H33: DQP-2739 | I33: DQO-2739 | J33: Compl_Chk-amendment_type-amend_beneficiaries | K33: Validate that the critical data element amendment_type.amend_beneficiaries is populated and not blank for in-scope records.Profiling results were used to identify current null/blank exposure where available. | L33: Completeness | M33: Attribute | N33: Business Registration & Licensing | تسجيل الأعمال والتراخيص | O33: rfmdaas@adra.gov.ae, bmalkindi@adra.gov.ae | P33: asalmehiry@adra.gov.ae, rfmdaas@adra.gov.ae | Q33: Accela | R33: DED_Data_Table_179 | S33: DED_Attribute_2645 | T33: Custom | U33: !isNull({amend_beneficiaries}) | V33: 0.95 | W33: Weekly | X33: DQI | Y33: High | Z33: {rec_status} == 'A' | AA33: Active | AB33: 46310 | AD33: Business | AE33: Yes | AF33: Approved | AG33: 9/17 approve | AJ33: No | AO33: Signed Off
A34: Sprint 3 | B34: amendment_type | C34: DED_Data_Table_179 | D34: country_amendment_foreign_company | E34: DED_Attribute_2647 | F34: 90852861-3bfd-4662-b279-9c7a61842096 | G34: 169b3533-9b00-459a-8bf8-76de841e40a8 | H34: DQP-2954 | I34: DQO-2954 | J34: Comp_Chk-amen_type-country_amen_foreign_company | K34: Validate that the critical data element amendment_type.country_amendment_foreign_company is populated and not blank for in-scope records.Profiling results were used to identify current null/blank exposure where available. | L34: Completeness | M34: Attribute | N34: Business Registration & Licensing | تسجيل الأعمال والتراخيص | O34: rfmdaas@adra.gov.ae, bmalkindi@adra.gov.ae | P34: asalmehiry@adra.gov.ae, rfmdaas@adra.gov.ae | Q34: Accela | R34: DED_Data_Table_179 | S34: DED_Attribute_2647 | T34: Custom | U34: !isNull({country_amendment_foreign_company}) | V34: 0.95 | W34: Weekly | X34: DQI | Y34: High | Z34: {rec_status} == 'A' | AA34: Active | AB34: 46310 | AD34: Technical | AE34: No | AF34: In Review | AJ34: Yes | AK34: Rejected | AL34: Samer | AM34: 30/09/2026 - No | AO34: Signed Off
A35: Sprint 3 | B35: amendment_type | C35: DED_Data_Table_179 | D35: heirs_amendment | E35: DED_Attribute_2648 | F35: c03da223-44f8-40a0-8f7f-21b3b16be7d1 | G35: 83f0d5b2-d6d5-4152-8786-35306ca1866f | H35: DQP-2955 | I35: DQO-2955 | J35: Compl_Chk-amendment_type-heirs_amendment | K35: Validate that the critical data element amendment_type.heirs_amendment is populated and not blank for in-scope records.Profiling results were used to identify current null/blank exposure where available. | L35: Completeness | M35: Attribute | N35: Business Registration & Licensing | تسجيل الأعمال والتراخيص | O35: rfmdaas@adra.gov.ae, bmalkindi@adra.gov.ae | P35: asalmehiry@adra.gov.ae, rfmdaas@adra.gov.ae | Q35: Accela | R35: DED_Data_Table_179 | S35: DED_Attribute_2648 | T35: Custom | U35: !isNull({heirs_amendment}) | V35: 0.95 | W35: Weekly | X35: DQI | Y35: High | Z35: {rec_status} == 'A' | AA35: Active | AB35: 46310 | AD35: Technical | AE35: No | AF35: In Review | AJ35: Yes | AK35: Rejected | AL35: Samer | AM35: 30/09/2026 - No | AO35: Signed Off
A36: Sprint 3 | B36: amendment_type | C36: DED_Data_Table_179 | D36: capital_amendment | E36: DED_Attribute_2649 | F36: f3500d1a-7aa0-4ef8-91b6-50cfe7e28bf9 | G36: 7fa53995-7a4e-468f-87b7-e930e6bd067e | H36: DQP-2956 | I36: DQO-2956 | J36: Compl_Chk-amendment_type-capital_amendment | K36: Validate that the critical data element amendment_type.capital_amendment is populated and not blank for in-scope records.Profiling results were used to identify current null/blank exposure where available. | L36: Completeness | M36: Attribute | N36: Business Registration & Licensing | تسجيل الأعمال والتراخيص | O36: rfmdaas@adra.gov.ae, bmalkindi@adra.gov.ae | P36: asalmehiry@adra.gov.ae, rfmdaas@adra.gov.ae | Q36: Accela | R36: DED_Data_Table_179 | S36: DED_Attribute_2649 | T36: Custom | U36: !isNull({capital_amendment}) | V36: 0.95 | W36: Weekly | X36: DQI | Y36: High | Z36: {rec_status} == 'A' | AA36: Active | AB36: 46310 | AD36: Technical | AE36: No | AF36: In Review | AJ36: Yes | AK36: Rejected | AL36: Samer | AM36: 30/09/2026 - No | AO36: Signed Off
A37: Sprint 3 | B37: amendment_type | C37: DED_Data_Table_179 | D37: sponsor_amendment | E37: DED_Attribute_2650 | F37: dc60ac28-c966-4b54-9c0a-660a50fde9d3 | G37: d2e9d448-1b77-4632-8a96-f909f3f3b2e5 | H37: DQP-2957 | I37: DQO-2957 | J37: Compl_Chk-amendment_type-sponsor_amendment | K37: Validate that the critical data element amendment_type.sponsor_amendment is populated and not blank for in-scope records.Profiling results were used to identify current null/blank exposure where available. | L37: Completeness | M37: Attribute | N37: Business Registration & Licensing | تسجيل الأعمال والتراخيص | O37: rfmdaas@adra.gov.ae, bmalkindi@adra.gov.ae | P37: asalmehiry@adra.gov.ae, rfmdaas@adra.gov.ae | Q37: Accela | R37: DED_Data_Table_179 | S37: DED_Attribute_2650 | T37: Custom | U37: !isNull({sponsor_amendment}) | V37: 0.95 | W37: Weekly | X37: DQI | Y37: High | Z37: {rec_status} == 'A' | AA37: Active | AB37: 46310 | AD37: Technical | AE37: No | AF37: In Review | AJ37: Yes | AK37: Rejected | AL37: Samer | AM37: 30/09/2026 - No | AO37: Signed Off
A38: Sprint 3 | B38: amendment_type | C38: DED_Data_Table_179 | D38: location_amendment_c | E38: DED_Attribute_2651 | F38: 3c26e1fe-b44d-4645-9fb9-efcc657b3fab | G38: e5acb72f-84a4-42d9-b925-f79fc7803807 | H38: DQP-2958 | I38: DQO-2958 | J38: Compl_Chk-amendment_type-location_amendment_c | K38: Validate that the critical data element amendment_type.location_amendment_c is populated and not blank for in-scope records.Profiling results were used to identify current null/blank exposure where available. | L38: Completeness | M38: Attribute | N38: Business Registration & Licensing | تسجيل الأعمال والتراخيص | O38: rfmdaas@adra.gov.ae, bmalkindi@adra.gov.ae | P38: asalmehiry@adra.gov.ae, rfmdaas@adra.gov.ae | Q38: Accela | R38: DED_Data_Table_179 | S38: DED_Attribute_2651 | T38: Custom | U38: !isNull({location_amendment_c}) | V38: 0.95 | W38: Weekly | X38: DQI | Y38: High | Z38: {rec_status} == 'A' | AA38: Active | AB38: 46310 | AD38: Technical | AE38: No | AF38: In Review | AJ38: Yes | AK38: Rejected | AL38: Samer | AM38: 30/09/2026 - No | AO38: Signed Off
A39: Sprint 3 | B39: amendment_type | C39: DED_Data_Table_179 | D39: activity_replacement | E39: DED_Attribute_2652 | F39: c9ba16d4-85d5-4927-83d4-ae2d674a737a | G39: 4f063b30-c5ba-4c72-95ba-5324713bc93f | H39: DQP-2959 | I39: DQO-2959 | J39: Compl_Chk-amendment_type-activity_replacement | K39: Validate that the critical data element amendment_type.activity_replacement is populated and not blank for in-scope records.Profiling results were used to identify current null/blank exposure where available. | L39: Completeness | M39: Attribute | N39: Business Registration & Licensing | تسجيل الأعمال والتراخيص | O39: rfmdaas@adra.gov.ae, bmalkindi@adra.gov.ae | P39: asalmehiry@adra.gov.ae, rfmdaas@adra.gov.ae | Q39: Accela | R39: DED_Data_Table_179 | S39: DED_Attribute_2652 | T39: Custom | U39: !isNull({activity_replacement}) | V39: 0.95 | W39: Weekly | X39: DQI | Y39: High | Z39: {rec_status} == 'A' | AA39: Active | AB39: 46310 | AD39: Technical | AE39: No | AF39: In Review | AJ39: Yes | AK39: Rejected | AL39: Samer | AM39: 30/09/2026 - No | AO39: Signed Off
A40: Sprint 3 | B40: amendment_type | C40: DED_Data_Table_179 | D40: location_amendment | E40: DED_Attribute_2653 | F40: 0f99dd01-5475-4701-b0e3-b797d1741874 | G40: e972c837-d37f-4710-bef3-a547d551fffe | H40: DQP-2960 | I40: DQO-2960 | J40: Compl_Chk-amendment_type-location_amendment | K40: Validate that the critical data element amendment_type.location_amendment is populated and not blank for in-scope records.Profiling results were used to identify current null/blank exposure where available. | L40: Completeness | M40: Attribute | N40: Business Registration & Licensing | تسجيل الأعمال والتراخيص | O40: rfmdaas@adra.gov.ae, bmalkindi@adra.gov.ae | P40: asalmehiry@adra.gov.ae, rfmdaas@adra.gov.ae | Q40: Accela | R40: DED_Data_Table_179 | S40: DED_Attribute_2653 | T40: Custom | U40: !isNull({location_amendment}) | V40: 0.95 | W40: Weekly | X40: DQI | Y40: High | Z40: {rec_status} == 'A' | AA40: Active | AB40: 46310 | AD40: Technical | AE40: No | AF40: In Review | AJ40: Yes | AK40: Rejected | AL40: Samer | AM40: 30/09/2026 - No | AO40: Signed Off
A41: Sprint 3 | B41: amendment_type | C41: DED_Data_Table_179 | D41: notarisation_contracts_amendment | E41: DED_Attribute_2654 | F41: c2c1128d-734c-4c6c-a2b2-2530baae1697 | G41: 27fea252-37c9-4559-aead-32b548ef3336 | H41: DQP-2961 | I41: DQO-2961 | J41: Compl_Chk-amen_type-notarisation_cont_amendment | K41: Validate that the critical data element amendment_type.notarisation_contracts_amendment is populated and not blank for in-scope records.Profiling results were used to identify current null/blank exposure where available. | L41: Completeness | M41: Attribute | N41: Business Registration & Licensing | تسجيل الأعمال والتراخيص | O41: rfmdaas@adra.gov.ae, bmalkindi@adra.gov.ae | P41: asalmehiry@adra.gov.ae, rfmdaas@adra.gov.ae | Q41: Accela | R41: DED_Data_Table_179 | S41: DED_Attribute_2654 | T41: Custom | U41: !isNull({notarisation_contracts_amendment}) | V41: 0.95 | W41: Weekly | X41: DQI | Y41: High | Z41: {rec_status} == 'A' | AA41: Active | AB41: 46310 | AD41: Technical | AE41: No | AF41: In Review | AJ41: Yes | AK41: Approved | AL41: Samer | AM41: 30/09/2026 - Yes Approved exact four-level service paths from O:R; do not cross-combine listed subtypes/categories. REC_STATUS = 'A'; evaluate only where notarisation_contracts_amendment is mandatory for the service/stage; Confirm applicable amendment options; do not require every flag to be selected; an explicit No counts as populated; Confirm legal-form and contract applicability; Non-applicable records excluded from denominator. Business confirmation required. | AO41: Signed Off
A42: Sprint 3 | B42: amendment_type | C42: DED_Data_Table_179 | D42: amend_board_of_directors | E42: DED_Attribute_2655 | F42: 4733d60d-0cf2-44bf-b7de-396ad790a24e | G42: 23c4c4cd-70d5-4650-930e-3f1b7061d853 | H42: DQP-2740 | I42: DQO-2740 | J42: Compl_Chk-amen_type-amend_board_of_directors | K42: Validate that the critical data element amendment_type.amend_board_of_directors is populated and not blank for in-scope records.Profiling results were used to identify current null/blank exposure where available. | L42: Completeness | M42: Attribute | N42: Business Registration & Licensing | تسجيل الأعمال والتراخيص | O42: rfmdaas@adra.gov.ae, bmalkindi@adra.gov.ae | P42: asalmehiry@adra.gov.ae, rfmdaas@adra.gov.ae | Q42: Accela | R42: DED_Data_Table_179 | S42: DED_Attribute_2655 | T42: Custom | U42: !isNull({amend_board_of_directors}) | V42: 0.95 | W42: Weekly | X42: DQI | Y42: High | Z42: {rec_status} == 'A' | AA42: Active | AB42: 46310 | AD42: Business | AE42: Yes | AF42: Approved | AG42: 9/17 approve | AJ42: No | AO42: Signed Off
A43: Sprint 3 | B43: amendment_type | C43: DED_Data_Table_179 | D43: license_type_amendment | E43: DED_Attribute_2657 | F43: 239e3083-9d3b-4cca-99d7-221887cb9299 | G43: abd833d5-0e92-479e-82de-1bb6001ae414 | H43: DQP-2962 | I43: DQO-2962 | J43: Compl_Chk-amendment_type-license_type_amendment | K43: Validate that the critical data element amendment_type.license_type_amendment is populated and not blank for in-scope records.Profiling results were used to identify current null/blank exposure where available. | L43: Completeness | M43: Attribute | N43: Business Registration & Licensing | تسجيل الأعمال والتراخيص | O43: rfmdaas@adra.gov.ae, bmalkindi@adra.gov.ae | P43: asalmehiry@adra.gov.ae, rfmdaas@adra.gov.ae | Q43: Accela | R43: DED_Data_Table_179 | S43: DED_Attribute_2657 | T43: Custom | U43: !isNull({license_type_amendment}) | V43: 0.95 | W43: Weekly | X43: DQI | Y43: High | Z43: {rec_status} == 'A' | AA43: Active | AB43: 46310 | AD43: Technical | AE43: No | AF43: In Review | AJ43: Yes | AK43: Rejected | AL43: Samer | AM43: 30/09/2026 - No | AO43: Signed Off
A44: Sprint 3 | B44: amendment_type | C44: DED_Data_Table_179 | D44: legal_form_amendment | E44: DED_Attribute_2658 | F44: 897f1a1e-69d7-4e0e-9a43-0db73e1bd9a2 | G44: b69501b8-7a43-4f9d-b8f7-4b7db6927c10 | H44: DQP-2963 | I44: DQO-2963 | J44: Compl_Chk-amendment_type-legal_form_amendment | K44: Validate that the critical data element amendment_type.legal_form_amendment is populated and not blank for in-scope records.Profiling results were used to identify current null/blank exposure where available. | L44: Completeness | M44: Attribute | N44: Business Registration & Licensing | تسجيل الأعمال والتراخيص | O44: rfmdaas@adra.gov.ae, bmalkindi@adra.gov.ae | P44: asalmehiry@adra.gov.ae, rfmdaas@adra.gov.ae | Q44: Accela | R44: DED_Data_Table_179 | S44: DED_Attribute_2658 | T44: Custom | U44: !isNull({legal_form_amendment}) | V44: 0.95 | W44: Weekly | X44: DQI | Y44: High | Z44: {rec_status} == 'A' | AA44: Active | AB44: 46310 | AD44: Technical | AE44: No | AF44: In Review | AJ44: Yes | AK44: Rejected | AL44: Samer | AM44: 30/09/2026 - No | AO44: Signed Off
A45: Sprint 3 | B45: amendment_type | C45: DED_Data_Table_179 | D45: partners_shares_amendment_c | E45: DED_Attribute_2659 | F45: 2dfa443b-68d1-4205-a99f-9670e3029ec2 | G45: 7007e825-0fd2-45f0-b412-3299523f55ee | H45: DQP-2964 | I45: DQO-2964 | J45: Compl_Chk-amen_type-partners_shares_amendment_c | K45: Validate that the critical data element amendment_type.partners_shares_amendment_c is populated and not blank for in-scope records.Profiling results were used to identify current null/blank exposure where available. | L45: Completeness | M45: Attribute | N45: Business Registration & Licensing | تسجيل الأعمال والتراخيص | O45: rfmdaas@adra.gov.ae, bmalkindi@adra.gov.ae | P45: asalmehiry@adra.gov.ae, rfmdaas@adra.gov.ae | Q45: Accela | R45: DED_Data_Table_179 | S45: DED_Attribute_2659 | T45: Custom | U45: !isNull({partners_shares_amendment_c}) | V45: 0.95 | W45: Weekly | X45: DQI | Y45: High | Z45: {rec_status} == 'A' | AA45: Active | AB45: 46310 | AD45: Technical | AE45: No | AF45: In Review | AJ45: Yes | AK45: Rejected | AL45: Samer | AM45: 30/09/2026 - No | AO45: Signed Off
A46: Sprint 3 | B46: amendment_type | C46: DED_Data_Table_179 | D46: country_amendment_foreign_company_c | E46: DED_Attribute_2660 | F46: bdd142d6-4233-444a-a659-2b7e9c95fe2c | G46: e648b9b6-34cc-418c-b82e-2408440b04c4 | H46: DQP-2965 | I46: DQO-2965 | J46: Compl_Chk-amen_typ-count_amen_foreign_company_c | K46: Validate that the critical data element amendment_type.country_amendment_foreign_company_c is populated and not blank for in-scope records.Profiling results were used to identify current null/blank exposure where available. | L46: Completeness | M46: Attribute | N46: Business Registration & Licensing | تسجيل الأعمال والتراخيص | O46: rfmdaas@adra.gov.ae, bmalkindi@adra.gov.ae | P46: asalmehiry@adra.gov.ae, rfmdaas@adra.gov.ae | Q46: Accela | R46: DED_Data_Table_179 | S46: DED_Attribute_2660 | T46: Custom | U46: !isNull({country_amendment_foreign_company_c}) | V46: 0.95 | W46: Weekly | X46: DQI | Y46: High | Z46: {rec_status} == 'A' | AA46: Active | AB46: 46310 | AD46: Technical | AE46: No | AF46: In Review | AJ46: Yes | AK46: Rejected | AL46: Samer | AM46: 30/09/2026 - No | AO46: Signed Off
A47: Sprint 3 | B47: amendment_type | C47: DED_Data_Table_179 | D47: capital_amendment_c | E47: DED_Attribute_2661 | F47: 3af6af11-445b-456a-b753-9cb69a7f0cbf | G47: 1357d163-95ff-453d-b7d4-8962392363ed | H47: DQP-2966 | I47: DQO-2966 | J47: Compl_Chk-amendment_type-capital_amendment_c | K47: Validate that the critical data element amendment_type.capital_amendment_c is populated and not blank for in-scope records.Profiling results were used to identify current null/blank exposure where available. | L47: Completeness | M47: Attribute | N47: Business Registration & Licensing | تسجيل الأعمال والتراخيص | O47: rfmdaas@adra.gov.ae, bmalkindi@adra.gov.ae | P47: asalmehiry@adra.gov.ae, rfmdaas@adra.gov.ae | Q47: Accela | R47: DED_Data_Table_179 | S47: DED_Attribute_2661 | T47: Custom | U47: !isNull({capital_amendment_c}) | V47: 0.95 | W47: Weekly | X47: DQI | Y47: High | Z47: {rec_status} == 'A' | AA47: Active | AB47: 46310 | AD47: Technical | AE47: No | AF47: In Review | AJ47: Yes | AK47: Rejected | AL47: Samer | AM47: 30/09/2026 - No | AO47: Signed Off
A48: Sprint 3 | B48: amendment_type | C48: DED_Data_Table_179 | D48: activity_replacement_c | E48: DED_Attribute_2662 | F48: b5b16ce7-2527-4d6b-883d-ed4fb60e9eb2 | G48: ff3c7a87-41e4-4145-bd43-1a133ec46f8b | H48: DQP-2967 | I48: DQO-2967 | J48: Compl_Chk-amendment_type-activity_replacement_c | K48: Validate that the critical data element amendment_type.activity_replacement_c is populated and not blank for in-scope records.Profiling results were used to identify current null/blank exposure where available. | L48: Completeness | M48: Attribute | N48: Business Registration & Licensing | تسجيل الأعمال والتراخيص | O48: rfmdaas@adra.gov.ae, bmalkindi@adra.gov.ae | P48: asalmehiry@adra.gov.ae, rfmdaas@adra.gov.ae | Q48: Accela | R48: DED_Data_Table_179 | S48: DED_Attribute_2662 | T48: Custom | U48: !isNull({activity_replacement_c}) | V48: 0.95 | W48: Weekly | X48: DQI | Y48: High | Z48: {rec_status} == 'A' | AA48: Active | AB48: 46310 | AD48: Technical | AE48: No | AF48: In Review | AJ48: Yes | AK48: Rejected | AL48: Samer | AM48: 30/09/2026 - No | AO48: Signed Off
A49: Sprint 3 | B49: amendment_type | C49: DED_Data_Table_179 | D49: authorized_signatories_amendment | E49: DED_Attribute_2663 | F49: 1bf636f3-fd05-4276-88f0-3463d781525f | G49: 7125e79c-064f-4a41-8808-468548c87083 | H49: DQP-2968 | I49: DQO-2968 | J49: Comp_Chk-amen_typ-authorized_signator_amendment | K49: Validate that the critical data element amendment_type.authorized_signatories_amendment is populated and not blank for in-scope records.Profiling results were used to identify current null/blank exposure where available. | L49: Completeness | M49: Attribute | N49: Business Registration & Licensing | تسجيل الأعمال والتراخيص | O49: rfmdaas@adra.gov.ae, bmalkindi@adra.gov.ae | P49: asalmehiry@adra.gov.ae, rfmdaas@adra.gov.ae | Q49: Accela | R49: DED_Data_Table_179 | S49: DED_Attribute_2663 | T49: Custom | U49: !isNull({authorized_signatories_amendment}) | V49: 0.95 | W49: Weekly | X49: DQI | Y49: High | Z49: {rec_status} == 'A' | AA49: Active | AB49: 46310 | AD49: Technical | AE49: No | AF49: In Review | AJ49: Yes | AK49: Approved | AL49: Samer | AM49: 30/09/2026 - Yes Service: Licenses / License / Amendment / NA. REC_STATUS = 'A'; evaluate only where authorized_signatories_amendment is mandatory for the service/stage; Confirm applicable amendment options; do not require every flag to be selected; an explicit No counts as populated; Non-applicable records excluded from denominator. Business confirmation required. | AO49: Signed Off
A50: Sprint 3 | B50: amendment_type | C50: DED_Data_Table_179 | D50: signboard_amendment_c | E50: DED_Attribute_2664 | F50: bd2d4717-c077-4673-9186-6613ab1cfb84 | G50: b9012925-d964-4fe1-a174-3b7226564938 | H50: DQP-2969 | I50: DQO-2969 | J50: Compl_Chk-amendment_type-signboard_amendment_c | K50: Validate that the critical data element amendment_type.signboard_amendment_c is populated and not blank for in-scope records.Profiling results were used to identify current null/blank exposure where available. | L50: Completeness | M50: Attribute | N50: Business Registration & Licensing | تسجيل الأعمال والتراخيص | O50: rfmdaas@adra.gov.ae, bmalkindi@adra.gov.ae | P50: asalmehiry@adra.gov.ae, rfmdaas@adra.gov.ae | Q50: Accela | R50: DED_Data_Table_179 | S50: DED_Attribute_2664 | T50: Custom | U50: !isNull({signboard_amendment_c}) | V50: 0.95 | W50: Weekly | X50: DQI | Y50: High | Z50: {rec_status} == 'A' | AA50: Active | AB50: 46310 | AD50: Technical | AE50: No | AF50: In Review | AJ50: Yes | AK50: Rejected | AL50: Samer | AM50: 30/09/2026 - No | AO50: Signed Off
A51: Sprint 3 | B51: amendment_type | C51: DED_Data_Table_179 | D51: trade_name_amendment_c | E51: DED_Attribute_2665 | F51: dcc0a4ea-586b-4e2c-8293-28495b4753c9 | G51: b4adee4a-40b2-494a-b2ea-c902521019ca | H51: DQP-2970 | I51: DQO-2970 | J51: Compl_Chk-amendment_type-trade_name_amendment_c | K51: Validate that the critical data element amendment_type.trade_name_amendment_c is populated and not blank for in-scope records.Profiling results were used to identify current null/blank exposure where available. | L51: Completeness | M51: Attribute | N51: Business Registration & Licensing | تسجيل الأعمال والتراخيص | O51: rfmdaas@adra.gov.ae, bmalkindi@adra.gov.ae | P51: asalmehiry@adra.gov.ae, rfmdaas@adra.gov.ae | Q51: Accela | R51: DED_Data_Table_179 | S51: DED_Attribute_2665 | T51: Custom | U51: !isNull({trade_name_amendment_c}) | V51: 0.95 | W51: Weekly | X51: DQI | Y51: High | Z51: {rec_status} == 'A' | AA51: Active | AB51: 46310 | AD51: Technical | AE51: No | AF51: In Review | AJ51: Yes | AK51: Rejected | AL51: Samer | AM51: 30/09/2026 - No | AO51: Signed Off
A52: Sprint 3 | B52: amendment_type | C52: DED_Data_Table_179 | D52: manager_amendment_c | E52: DED_Attribute_2666 | F52: 0a30d424-bd38-4fce-9614-3b56ce5d2dcd | G52: e7c9d715-3d3f-4633-9f9e-dc3da8a8cc66 | H52: DQP-2971 | I52: DQO-2971 | J52: Compl_Chk-amendment_type-manager_amendment_c | K52: Validate that the critical data element amendment_type.manager_amendment_c is populated and not blank for in-scope records.Profiling results were used to identify current null/blank exposure where available. | L52: Completeness | M52: Attribute | N52: Business Registration & Licensing | تسجيل الأعمال والتراخيص | O52: rfmdaas@adra.gov.ae, bmalkindi@adra.gov.ae | P52: asalmehiry@adra.gov.ae, rfmdaas@adra.gov.ae | Q52: Accela | R52: DED_Data_Table_179 | S52: DED_Attribute_2666 | T52: Custom | U52: !isNull({manager_amendment_c}) | V52: 0.95 | W52: Weekly | X52: DQI | Y52: High | Z52: {rec_status} == 'A' | AA52: Active | AB52: 46310 | AD52: Technical | AE52: No | AF52: In Review | AJ52: Yes | AK52: Rejected | AL52: Samer | AM52: 30/09/2026 - No | AO52: Signed Off
A53: Sprint 3 | B53: amendment_type | C53: DED_Data_Table_179 | D53: technical_amendment | E53: DED_Attribute_2667 | F53: 4b8a9abf-c937-4228-a672-6ff9e6ae2684 | G53: db21bb2b-2cc5-435a-9fde-2e3b992ec855 | H53: DQP-2741 | I53: DQO-2741 | J53: Compl_Chk-amendment_type-technical_amendment | K53: Validate that the critical data element amendment_type.technical_amendment is populated and not blank for in-scope records.Profiling results were used to identify current null/blank exposure where available. | L53: Completeness | M53: Attribute | N53: Business Registration & Licensing | تسجيل الأعمال والتراخيص | O53: rfmdaas@adra.gov.ae, bmalkindi@adra.gov.ae | P53: asalmehiry@adra.gov.ae, rfmdaas@adra.gov.ae | Q53: Accela | R53: DED_Data_Table_179 | S53: DED_Attribute_2667 | T53: Custom | U53: !isNull({technical_amendment}) | V53: 0.95 | W53: Weekly | X53: DQI | Y53: High | Z53: {rec_status} == 'A' | AA53: Active | AB53: 46310 | AD53: Business | AE53: Yes | AF53: Approved | AG53: 9/17 approve | AJ53: No | AO53: Signed Off
A54: Sprint 3 | B54: amendment_type | C54: DED_Data_Table_179 | D54: amend_managers | E54: DED_Attribute_2668 | F54: 743ee8fa-7013-4a5c-9283-81240cad9db5 | G54: c8fbe611-e4cc-4f73-8f20-13dbe3848a30 | H54: DQP-2972 | I54: DQO-2972 | J54: Compl_Chk-amendment_type-amend_managers | K54: Validate that the critical data element amendment_type.amend_managers is populated and not blank for in-scope records.Profiling results were used to identify current null/blank exposure where available. | L54: Completeness | M54: Attribute | N54: Business Registration & Licensing | تسجيل الأعمال والتراخيص | O54: rfmdaas@adra.gov.ae, bmalkindi@adra.gov.ae | P54: asalmehiry@adra.gov.ae, rfmdaas@adra.gov.ae | Q54: Accela | R54: DED_Data_Table_179 | S54: DED_Attribute_2668 | T54: Custom | U54: !isNull({amend_managers}) | V54: 0.95 | W54: Weekly | X54: DQI | Y54: High | Z54: {rec_status} == 'A' | AA54: Active | AB54: 46310 | AD54: Technical | AE54: No | AF54: In Review | AJ54: Yes | AK54: Approved | AL54: Samer | AM54: 30/09/2026 - Yes Approved exact four-level service paths from O:R; do not cross-combine listed subtypes/categories. REC_STATUS = 'A'; evaluate only where amend_managers is mandatory for the service/stage; Confirm applicable amendment options; do not require every flag to be selected; an explicit No counts as populated; Non-applicable records excluded from denominator. Business confirmation required. | AO54: Signed Off
A55: Sprint 3 | B55: amendment_type | C55: DED_Data_Table_179 | D55: heirs_amendment_c | E55: DED_Attribute_2669 | F55: b1696f47-0b4f-467f-be92-88f693a0776e | G55: 3eb7994c-0fe4-4275-b1c4-7392fcba6471 | H55: DQP-2973 | I55: DQO-2973 | J55: Compl_Chk-amendment_type-heirs_amendment_c | K55: Validate that the critical data element amendment_type.heirs_amendment_c is populated and not blank for in-scope records.Profiling results were used to identify current null/blank exposure where available. | L55: Completeness | M55: Attribute | N55: Business Registration & Licensing | تسجيل الأعمال والتراخيص | O55: rfmdaas@adra.gov.ae, bmalkindi@adra.gov.ae | P55: asalmehiry@adra.gov.ae, rfmdaas@adra.gov.ae | Q55: Accela | R55: DED_Data_Table_179 | S55: DED_Attribute_2669 | T55: Custom | U55: !isNull({heirs_amendment_c}) | V55: 0.95 | W55: Weekly | X55: DQI | Y55: High | Z55: {rec_status} == 'A' | AA55: Active | AB55: 46310 | AD55: Technical | AE55: No | AF55: In Review | AJ55: Yes | AK55: Rejected | AL55: Samer | AM55: 30/09/2026 - No | AO55: Signed Off
A56: Sprint 3 | B56: amendment_type | C56: DED_Data_Table_179 | D56: license_type_amendment_c | E56: DED_Attribute_2670 | F56: 63635034-e526-4fdc-9a7c-db914c781bb5 | G56: bb22074b-2df1-43e6-a259-82cd076d068f | H56: DQP-2974 | I56: DQO-2974 | J56: Comp_Chk-amendme_type-license_type_amendment_c | K56: Validate that the critical data element amendment_type.license_type_amendment_c is populated and not blank for in-scope records.Profiling results were used to identify current null/blank exposure where available. | L56: Completeness | M56: Attribute | N56: Business Registration & Licensing | تسجيل الأعمال والتراخيص | O56: rfmdaas@adra.gov.ae, bmalkindi@adra.gov.ae | P56: asalmehiry@adra.gov.ae, rfmdaas@adra.gov.ae | Q56: Accela | R56: DED_Data_Table_179 | S56: DED_Attribute_2670 | T56: Custom | U56: !isNull({license_type_amendment_c}) | V56: 0.95 | W56: Weekly | X56: DQI | Y56: High | Z56: {rec_status} == 'A' | AA56: Active | AB56: 46310 | AD56: Technical | AE56: No | AF56: In Review | AJ56: Yes | AK56: Rejected | AL56: Samer | AM56: 30/09/2026 - No | AO56: Signed Off
...

Sheet In-scope Tables
B1: Total Tables
B2: =COUNTA(_xlfn.UNIQUE($B$5:$B$142)) -> 138
E3: Aligned with DRS, Jude latest confirmed 5 tables, Shweta confirmation of 2 tables descrepencies with Samer
A4: No. | B4: Data Asset ID | C4: Data Asset Name (English, Silver) | D4: Sprint | E4: Domain | F4: Bronze Name | G4: DATA AT SOURCE | H4: DATA AT BRONZE | I4: COMMENTS | J4: LAST UPDATED AT | K4: TABLE_TYPE | L4: Accela Table | M4: Accela Variable | O4: Sprint | P4: TABLE_TYPE | Q4: COMMENTS | R4: Count of DATA AT SOURCE | S4: Count of DATA AT BRONZE
A5: 1 | B5: DED_Data_Table_001 | C5: Financial_Audit_Trail | D5: Sprint 1 | E5: Financial Information | F5: ACCOUNTING_AUDIT_TRAIL | G5: DATA AVAILABLE | H5: OUTDATED DATA AVAILABLE | I5: Updated filter logic provided by Samer, blocked by Pipeline error | J5: 46252 | K5: P | L5: All Module | M5: Payments | O5: Sprint 1 | P5: P | Q5: Updated filter logic provided by Samer, blocked by Pipeline error | R5: 31 | S5: 31
A6: 2 | B6: DED_Data_Table_002 | C6: Status_Lookup | D6: Sprint 1 | E6: Economic Licenses | F6: APP_STATUS_GROUP | G6: DATA AVAILABLE | H6: OUTDATED DATA AVAILABLE | I6: Updated filter logic provided by Samer, blocked by Pipeline error | J6: 46252 | K6: P | P6: V | Q6: (blank) | R6: 18 | S6: 18
A7: 3 | B7: DED_Data_Table_003 | C7: Status_Lookup_Language | D7: Sprint 1 | E7: Economic Licenses | F7: APP_STATUS_GROUP_I18N | G7: DATA AVAILABLE | H7: OUTDATED DATA AVAILABLE | I7: Updated filter logic provided by Samer, blocked by Pipeline error | J7: 46252 | K7: P | O7: Sprint 2 | P7: P | Q7: Updated filter logic provided by Samer, blocked by Pipeline error | R7: 2 | S7: 2
A8: 4 | B8: DED_Data_Table_004 | C8: Application_Master | D8: Sprint 1 | E8: Economic Licenses | F8: B1PERMIT | G8: DATA AVAILABLE | H8: OUTDATED DATA AVAILABLE | I8: Updated filter logic provided by Samer, blocked by Pipeline error | J8: 46252 | K8: P | L8: All Module | M8: Record | Q8: (blank) | R8: 4 | S8: 4
A9: 5 | B9: DED_Data_Table_005 | C9: License_Expiration | D9: Sprint 1 | E9: Economic Licenses | F9: B1_EXPIRATION | G9: DATA AVAILABLE | H9: OUTDATED DATA AVAILABLE | I9: Updated filter logic provided by Samer, blocked by Pipeline error | J9: 46252 | K9: P | L9: All Module | M9: Renewal info | P9: V | Q9: (blank) | R9: 28 | S9: 28
A10: 6 | B10: DED_Data_Table_006 | C10: Application_Address | D10: Sprint 1 | E10: Economic Licenses | F10: B3ADDRES | G10: DATA AVAILABLE | H10: OUTDATED DATA AVAILABLE | I10: Updated filter logic provided by Samer, blocked by Pipeline error | J10: 46252 | K10: P | L10: All Module | M10: Address | P10: VP | Q10: (blank) | R10: 3 | S10: 3
A11: 7 | B11: DED_Data_Table_007 | C11: Application_District | D11: Sprint 1 | E11: Economic Licenses | F11: B3ADDRES_DISTRICT | G11: DATA AVAILABLE | H11: OUTDATED DATA AVAILABLE | I11: Updated filter logic provided by Samer, blocked by Pipeline error | J11: 46252 | K11: P | O11: Sprint 3 | P11: VP | Q11: (blank)
A12: 8 | B12: DED_Data_Table_008 | C12: Investor | D12: Sprint 1 | E12: Economic Licenses | F12: B3CONTACT | G12: DATA AVAILABLE | H12: OUTDATED DATA AVAILABLE | I12: Updated filter logic provided by Samer, blocked by Pipeline error | J12: 46252 | K12: P | L12: All Module | M12: Contact | O12: Grand Total | R12: 86 | S12: 86
A13: 9 | B13: DED_Data_Table_009 | C13: Company_Name | D13: Sprint 1 | E13: Economic Licenses | F13: B3CONTRA | G13: DATA AVAILABLE | H13: OUTDATED DATA AVAILABLE | I13: Updated filter logic provided by Samer, blocked by Pipeline error | J13: 46252 | K13: P | L13: All Module | M13: Licenses
A14: 10 | B14: DED_Data_Table_010 | C14: Requirement_Condition | D14: Sprint 1 | E14: Economic Licenses | F14: B6CONDIT | G14: DATA AVAILABLE | H14: OUTDATED DATA AVAILABLE | I14: Updated filter logic provided by Samer, blocked by Pipeline error | J14: 46252 | K14: P | L14: All Module | M14: Suspensions
A15: 11 | B15: DED_Data_Table_011 | C15: Requirement_Condition_Dtl | D15: Sprint 1 | E15: Economic Licenses | F15: B6CONDIT_DETAIL | G15: DATA AVAILABLE | H15: OUTDATED DATA AVAILABLE | I15: Updated filter logic provided by Samer, blocked by Pipeline error | J15: 46252 | K15: P
A16: 12 | B16: DED_Data_Table_012 | C16: Requirement_Condition_Dtl_Language | D16: Sprint 1 | E16: Economic Licenses | F16: B6CONDIT_DETAIL_I18N | G16: DATA AVAILABLE | H16: OUTDATED DATA AVAILABLE | I16: Updated filter logic provided by Samer, blocked by Pipeline error | J16: 46252 | K16: P
A17: 13 | B17: DED_Data_Table_013 | C17: Requirement_Condition_History | D17: Sprint 1 | E17: Economic Licenses | F17: B6CONDIT_HISTORY | G17: DATA AVAILABLE | H17: OUTDATED DATA AVAILABLE | I17: Updated filter logic provided by Samer, blocked by Pipeline error | J17: 46252 | K17: P | L17: All Module | M17: Suspensions / Condition History
A18: 14 | B18: DED_Data_Table_014 | C18: Requirement_Condition_History_Dtl | D18: Sprint 1 | E18: Economic Licenses | F18: B6CONDIT_HISTORY_DETAIL | G18: DATA AVAILABLE | H18: OUTDATED DATA AVAILABLE | I18: Updated filter logic provided by Samer, blocked by Pipeline error | J18: 46252 | K18: P
A19: 15 | B19: DED_Data_Table_015 | C19: Requirement_Condition_Language | D19: Sprint 1 | E19: Economic Licenses | F19: B6CONDIT_I18N | G19: DATA AVAILABLE | H19: OUTDATED DATA AVAILABLE | I19: Updated filter logic provided by Samer, blocked by Pipeline error | J19: 46252 | K19: P
A20: 16 | B20: DED_Data_Table_017 | C20: Application_Master_Dtl | D20: Sprint 1 | E20: Economic Licenses | F20: BPERMIT_DETAIL | G20: DATA AVAILABLE | H20: OUTDATED DATA AVAILABLE | I20: Updated filter logic provided by Samer, blocked by Pipeline error | J20: 46252 | K20: P | L20: All Module | M20: Record
A21: 17 | B21: DED_Data_Table_019 | C21: Application_Fee | D21: Sprint 1 | E21: Financial Information | F21: F4FEEITEM | G21: DATA AVAILABLE | H21: OUTDATED DATA AVAILABLE | I21: Updated filter logic provided by Samer, blocked by Pipeline error | J21: 46252 | K21: P | L21: All Module | M21: Fees / Fee Detail
A22: 18 | B22: DED_Data_Table_020 | C22: Application_Fee_Audit | D22: Sprint 1 | E22: Financial Information | F22: F4FEEITEM_AUDIT_TRAIL | G22: DATA AVAILABLE | H22: OUTDATED DATA AVAILABLE | I22: Updated filter logic provided by Samer, blocked by Pipeline error | J22: 46252 | K22: P
A23: 19 | B23: DED_Data_Table_021 | C23: Application_Invoice | D23: Sprint 1 | E23: Financial Information | F23: F4INVOICE | G23: DATA AVAILABLE | H23: OUTDATED DATA AVAILABLE | I23: Updated filter logic provided by Samer, blocked by Pipeline error | J23: 46252 | K23: P | L23: All Module | M23: Fees
A24: 20 | B24: DED_Data_Table_022 | C24: Application_Payment | D24: Sprint 1 | E24: Financial Information | F24: F4PAYMENT | G24: DATA AVAILABLE | H24: OUTDATED DATA AVAILABLE | I24: Updated filter logic provided by Samer, blocked by Pipeline error | J24: 46252 | K24: P | L24: All Module | M24: Payments / Transactions
A25: 21 | B25: DED_Data_Table_023 | C25: Application_Receipt | D25: Sprint 1 | E25: Financial Information | F25: F4RECEIPT | G25: DATA AVAILABLE | H25: OUTDATED DATA AVAILABLE | I25: Updated filter logic provided by Samer, blocked by Pipeline error | J25: 46252 | K25: P | L25: All Module | M25: Payments / Transactions
A26: 22 | B26: DED_Data_Table_024 | C26: Investor_Reference | D26: Sprint 1 | E26: Economic Licenses | F26: G3CONTACT | G26: DATA AVAILABLE | H26: OUTDATED DATA AVAILABLE | I26: Updated filter logic provided by Samer, blocked by Pipeline error | J26: 46252 | K26: P | L26: All Module | M26: Reference Contact
A27: 23 | B27: DED_Data_Table_025 | C27: Inspection_Suspension | D27: Sprint 1 | E27: Inspection | F27: G6ACTION | G27: DATA AVAILABLE | H27: OUTDATED DATA AVAILABLE | I27: Updated filter logic provided by Samer, blocked by Pipeline error | J27: 46252 | K27: P | L27: All Module | M27: Inspections
A28: 24 | B28: DED_Data_Table_028 | C28: Workflow | D28: Sprint 1 | E28: Economic Licenses | F28: GPROCESS | G28: DATA AVAILABLE | H28: OUTDATED DATA AVAILABLE | I28: Updated filter logic provided by Samer, blocked by Pipeline error | J28: 46252 | K28: P | L28: All Module | M28: Workflow
A29: 25 | B29: DED_Data_Table_032 | C29: Workflow_Language | D29: Sprint 1 | E29: Economic Licenses | F29: GPROCESS_I18N | G29: DATA AVAILABLE | H29: OUTDATED DATA AVAILABLE | I29: Updated filter logic provided by Samer, blocked by Pipeline error | J29: 46252 | K29: P | L29: All Module | M29: Workflow
A30: 26 | B30: DED_Data_Table_034 | C30: Application_Address_Reference | D30: Sprint 1 | E30: Economic Licenses | F30: L3ADDRES | G30: DATA AVAILABLE | H30: OUTDATED DATA AVAILABLE | I30: Updated filter logic provided by Samer, blocked by Pipeline error | J30: 46252 | K30: P | L30: All Module | M30: Refrence Address
A31: 27 | B31: DED_Data_Table_035 | C31: Application_District_Reference | D31: Sprint 1 | E31: Economic Licenses | F31: L3ADDRES_DISTRICT | G31: DATA AVAILABLE | H31: OUTDATED DATA AVAILABLE | I31: Updated filter logic provided by Samer, blocked by Pipeline error | J31: 46252 | K31: P | L31: All Module | M31: Refrence Address / District
A32: 28 | B32: DED_Data_Table_038 | C32: application_Configuration_Language | D32: Sprint 1 | E32: Economic Licenses | F32: R3APPTYP_I18N | G32: DATA AVAILABLE | H32: OUTDATED DATA AVAILABLE | I32: Updated filter logic provided by Samer, blocked by Pipeline error | J32: 46252 | K32: P
A33: 29 | B33: DED_Data_Table_041 | C33: Application_Fee_Reference | D33: Sprint 1 | E33: Financial Information | F33: RFEEITEM | G33: DATA AVAILABLE | H33: OUTDATED DATA AVAILABLE | I33: Updated filter logic provided by Samer, blocked by Pipeline error | J33: 46252 | K33: P | L33: All Module | M33: AA / Fee Item
A34: 30 | B34: DED_Data_Table_043 | C34: Inspection_Types | D34: Sprint 1 | E34: Inspection | F34: RINSPTYP | G34: DATA AVAILABLE | H34: OUTDATED DATA AVAILABLE | I34: Updated filter logic provided by Samer, blocked by Pipeline error | J34: 46252 | K34: P | L34: All Module | M34: AA / Inspection
A35: 31 | B35: DED_Data_Table_044 | C35: Inspection_Types_Language | D35: Sprint 1 | E35: Inspection | F35: RINSPTYP_I18N | G35: DATA AVAILABLE | H35: OUTDATED DATA AVAILABLE | I35: Updated filter logic provided by Samer, blocked by Pipeline error | J35: 46252 | K35: P | L35: All Module | M35: AA / Inspection
A36: 32 | B36: DED_Data_Table_045 | C36: Inspection_Relationship | D36: Sprint 2 | E36: Inspection | F36: RINSP_RESULT_GROUP | G36: DATA AVAILABLE | H36: DATA AVAILABLE | J36: 46252 | K36: P | L36: All Module | M36: Inspections
A37: 33 | B37: DED_Data_Table_046 | C37: Inspection_Relationship_Language | D37: Sprint 2 | E37: Inspection | F37: RINSP_RESULT_GROUP_I18N | G37: NO DATA | H37: NEED DE WORK FOR INGESTION | I37: Updated filter logic provided by Samer, blocked by Pipeline error | J37: 46252 | K37: P
A38: 34 | B38: DED_Data_Table_047 | C38: License_Professional | D38: Sprint 2 | E38: Economic Licenses | F38: RSTATE_LIC | G38: DATA AVAILABLE | H38: DATA AVAILABLE | J38: 46252 | K38: P | L38: Licenses | M38: License Professional
A39: 35 | B39: DED_Data_Table_048 | C39: Application_Status_History | D39: Sprint 2 | E39: Economic Licenses | F39: STATUS_HISTORY | G39: DATA AVAILABLE | H39: DATA AVAILABLE | J39: 46252 | K39: P | L39: Licenses | M39: License History
