Workbook
Name \0: #REF!
Name \66: '[8](2)'!#REF!
Name \A: #REF!
Name \B: #REF!
Name \C: #REF!
Name \E: #REF!
Name \F: #REF!
Name \G: #REF!
Name \J: #REF!
Name \K: #REF!
Name \L: #REF!
Name \M: '[9]EXH4A '!#REF!
Name \N: '[9]EXH4A '!#REF!
Name \P: #REF!
Name \R: #REF!
Name \RL: #REF!
Name \S: #REF!
Name \T: '[9]EXH4A '!#REF!
Name \U: #REF!
Name \v: #REF!
Name \W: '[9]EXH4A '!#REF!
Name \X: #REF!
Name \Y: #REF!
Name _: #REF!
Name __: #REF!
Name ___: #REF!
Name ____: #REF!
Name _____: #REF!
Name _____gas87: #REF!
Name _____gas91: #REF!
Name _____gas93: #REF!
Name _____gas95: #REF!
Name ____gas87: #REF!
Name ____gas91: #REF!
Name ____gas93: #REF!
Name ____gas95: #REF!
Name ___gas87: #REF!
Name ___gas91: #REF!
Name ___gas93: #REF!
Name ___gas95: #REF!
Name __gas87: #REF!
Name __gas91: #REF!
Name __gas93: #REF!
Name __gas95: #REF!
Name _01_Oct_08: '[3]Time(SA)'!#REF!
Name _1: #REF!
Name _1_: #REF!
Name _10: #REF!
Name _10t__WT: #REF!
Name _11: #REF!
Name _12: #REF!
Name _12WSOL: #REF!
Name _13: #REF!
Name _14: #REF!
Name _14W__WS: #REF!
Name _15: #REF!
Name _16: #REF!
Name _17: #REF!
Name _18: #REF!
Name _19: #REF!

Sheet Mapping-Table
A1: Column | B1: Requirement | C1: Explanation / Description from Manual | D1: Input | E1: Purview Mapping | F1: Column Name | G1: Comments
A2: Data Asset ID (English) | B2: Mandatory | C2: A unique identifier for the data table within the ADGE, provided in English (for example, Employee_Records). | D2: SSOT | E2: Existing | F2: Data Asset ID English
A3: Data Asset ID (Arabic) | B3: Optional | C3: A unique identifier for the Data Table, provided in Arabic (in digits). | D3: N/A | E3: Existing | F3: Data Asset ID Arabic
A4: Bronze Table | B4: Not for Submission | C4: N/A | D4: SSOT | E4: Not for Purview | F4: N/A
A5: Data Asset Name (English) | B5: Mandatory | C5: The data table name in English. | D5: SSOT | E5: Existing | F5: Data Asset Name English
A6: Data Asset Name (Arabic) | B6: Mandatory | C6: The data table name in Arabic. | D6: Inventory / DED | E6: Existing | F6: Data Asset Name Arabic
A7: Data Asset Description (English) | B7: Mandatory | C7: A brief description of the Data Table's contents and purpose, in English (for example, "This contains all records of government employees for the year 2024"). | D7: Inventory / DED | E7: Existing | F7: Data Asset Description English
A8: Data Asset Description (Arabic) | B8: Mandatory | C8: A brief description of the Data Table's contents and purpose, in Arabic. | D8: Inventory / DED | E8: Existing | F8: Data Asset Description Arabic
A9: Data Owner | B9: Mandatory | C9: Email address of the individual or group accountable for the data asset (for example, firstname.lastname@dge.ae). | D9: SSOT / DED Email | E9: Existing | F9: Owners
A10: Data Steward | B10: Mandatory | C10: Email address of the individual or group responsible for managing and overseeing the data, if designated. | D10: SSOT / DED Email | E10: Existing | F10: Experts
A11: Source System | B11: Mandatory | C11: The business-friendly name or type of the application system where the data originates (for example, "HR Management System"). | D11: Accela | E11: Existing | F11: Source System
A12: Domain ID | B12: Mandatory | C12: The unique identifier for the data domain or subject area aligned to the canonical list of Domains governed under the Government Information Model (GIM) and is defined in Section 7 | D12: SSOT / DED Email | E12: New | F12: Domain ID
A13: Domain Name | B13: Mandatory | C13: The business name of the data domain in English. | D13: SSOT / DED Email | E13: New | F13: Domain Name
... A32: Scope | B32: Mandatory | C32: Sprint 1/2/3 | D32: SSOT | E32: Not for Purview | F32: N/A

Sheet Mapping-Attribute
A1: Attribute Level | D1: Inputs From | E1: Comments
A2: Attribute ID (English) | B2: Mandatory | C2: A unique identifier for the attribute within the Data Table, provided in English (for example, Employee_ID).
A3: Attribute ID (Arabic) | B3: Optional | C3: A unique identifier for the attribute, provided in Arabic (if available).
A5: Attribute Description (English) | B5: Mandatory | C5: A detailed explanation or definition of the attribute in English (for example, "Unique identifier for each government employee").
A6: Attribute Description (Arabic) | B6: Optional | C6: A detailed explanation or definition of the attribute in Arabic, if available.
A7: Data Asset ID | B7: Mandatory | C7: The Data Asset ID of the Data Table to which the attribute belongs. The value must match an entry in Data Catalog - Data Table.
A8: Created Date | B8: Mandatory | C8: The date when the attribute was originally created (MM/DD/YYYY).
A9: Last Update Date | B9: Mandatory | C9: The most recent date when the attribute was updated (MM/DD/YYYY).
A10: Nullable (Y/N) | B10: Mandatory | C10: Indicates whether the attribute can accept null values (Y or N).
A11: Data Type | B11: Mandatory | C11: The type of data stored in the attribute (for example, integer, string, date).
A12: Data Length | B12: Mandatory | C12: The maximum length of data that can be stored in the attribute (for example, 10).
A13: Primary Key (Y/N) | B13: Mandatory | C13: Indicates whether the attribute serves as a primary key for the Data Table (Y or N).
A14: Foreign Key Data Asset | B14: Optional | C14: The Data Asset ID to which this attribute is linked as a foreign key, if applicable.
... A30: Data Steward | B30: Mandatory | C30: Email address of the individual or team responsible for managing and overseeing the attribute, if designated.

Sheet Purview-Catalogue
A1: TABLE LEVEL | F1: ATTRIBUTE LEVEL
A2: Document Column Name | B2: Purview Column Name | C2: New or Existing? | D2: New Column Name | F2: Document Column Name | G2: Purview Column Name | H2: New or Existing? | I2: New Column Name
A3: Data Asset ID (English) | B3: Data Asset ID English | C3: Existing | F3: Attribute ID (English) | G3: Attribute ID English | H3: Existing
A4: Data Asset ID (Arabic) | B4: Data Asset ID Arabic | C4: Existing | F4: Attribute ID (Arabic)
A5: Data Asset Name (English) | B5: Data Asset Name English | C5: Existing | F5: Attribute Description (English) | G5: Attribute Description English | H5: Existing
A6: Data Asset Name (Arabic) | B6: Data Asset Name Arabic | C6: Existing | F6: Attribute Description (Arabic) | G6: Attribute Description Arabic | H6: Existing
A7: Data Asset Description (English) | B7: Data Asset Description English | C7: Existing | F7: Data Asset ID | G7: Data Asset ID | H7: Existing
A8: Data Asset Description (Arabic) | B8: Data Asset Description Arabic | C8: Existing | F8: Created Date | G8: Created Date | H8: Existing
A9: Data Owner | B9: Owners | C9: Existing | F9: Last Update Date | H9: New | I9: Last Update Date
A10: Data Steward | B10: Experts | C10: Existing | F10: Nullable (Y/N) | G10: Is Nullable | H10: New | I10: Nullable Y_N
A11: Source System | B11: Source System | C11: Existing | F11: Data Type | G11: Data Type | H11: Existing
A12: Domain ID | C12: New | D12: Domain ID | F12: Data Length | G12: Data Length | H12: Existing
A13: Domain Name | C13: New | D13: Domain Name | F13: Primary Key (Y/N) | G13: Is Primary Key | H13: New | I13: Primary Key Y_N
A14: Created Date | B14: Created Date | C14: Existing | F14: Foreign Key Data Asset
A15: Last Update Date | C15: New | D15: Last Update Date | F15: Data Classification | G15: Data Classification | H15: Existing
A16: Retention Policy (Y/N) | B16: Retention Policy | C16: Existing | F16: Is Calculated? (Y/N) | G16: Is Calculated | H16: New | I16: Is Calculated Y_N
A17: Security Controls | B17: Security Controls | C17: Existing | F17: Calculation Logic | G17: Calculation Logic | H17: Existing
A18: Backup Interval | B18: Backup Interval | C18: Existing | F18: Business Validation Logic | G18: Business Validation Logic | H18: Existing
A19: Recovery | B19: Recovery | C19: Existing | F19: Data Completeness | H19: New | I19: Data Completeness
A20: Audit Logs | B20: Audit Logs | C20: Existing | F20: Data Completeness Target | H20: New | I20: Data Completeness Target
A21: Data Consumption (Direct) | B21: Data Consumption Direct | C21: Existing | F21: Missing Data Handling (Y/N) | G21: Missing Data Handling Y_N | H21: Existing
A22: Data Consumption (Indirect) | B22: Data Consumption Indirect | C22: Existing | F22: Missing Data Handling Process | G22: Missing Data Handling Process | H22: Existing
A23: Data Refresh Frequency | B23: Data Refresh Frequency | C23: Existing | F23: Duplicate Data Handling (Y/N) | G23: Duplicate Data Handling Y_N | H23: Existing
A24: Function / Business Unit | B24: Function or Business Unit | C24: Existing | F24: Duplicate Data Handling Process | G24: Duplicate Data Handling Process | H24: Existing
A25: ADGOV Data Classification | B25: ADGOV Data Classification | C25: Existing | F25: Duplicate (Y/N) | H25: New | I25: Duplicate Y_N
A26: Data Glossary | B26: Data Glossary/Glossary terms | C26: Existing | F26: Data Quality Issues | G26: Data Quality Issues | H26: Existing
A27: Publish to Platform (Y/N) | B27: Publish to Exchange Platform Y_N | C27: Existing | F27: Uniqueness Target | G27: Uniqueness Target | H27: Existing
A28: Integrate To WofG (Y/N) | C28: New | D28: Integrate To WofG (Y/N) | F28: Data Glossary | G28: Data Glossary | H28: Existing
A29: Data Source Name | B29: Data Source Name | C29: Existing | F29: Data Owner | G29: Data Owner | H29: Existing
A30: Data Asset Source Path | B30: Data Asset Source Path | C30: Existing | F30: Data Steward | G30: Data Steward | H30: Existing
A31: Data Asset Type | B31: Data Asset Type | C31: Existing

Sheet B1.2 Catalogue Table
A1: mandatory | B1: optional | C1: Not for Submission | D1: mandatory | E1: mandatory | F1: mandatory | G1: mandatory | H1: mandatory | I1: mandatory | J1: mandatory | K1: mandatory | L1: mandatory | M1: mandatory | N1: mandatory | O1: mandatory | P1: optional | Q1: optional | R1: optional | S1: optional | T1: optional | U1: optional | V1: mandatory | W1: mandatory | X1: mandatory | Y1: mandatory | Z1: Not for submission | AA1: mandatory | AB1: mandatory | AC1: mandatory | AD1: mandatory | AE1: mandatory | AF1: Not for purview
A2: Data Asset ID (English) | B2: Data Asset ID (Arabic) | C2: Bronze Table | D2: Data Asset Name (English) | E2: Data Asset Name (Arabic) | F2: Data Asset Description (English) | G2: Data Asset Description (Arabic) | H2: Data Owner | I2: Data Steward | J2: Source System | K2: Domain ID | L2: Domain Name | M2: Created Date | N2: Last Update Date | O2: Retention Policy (Y/N) | P2: Security Controls | Q2: Backup Interval | R2: Recovery | S2: Audit Logs | T2: Data Consumption (Direct) | U2: Data Consumption (Indirect) | V2: Data Refresh Frequency | W2: Function / Business Unit | X2: ADGOV Data Classification | Y2: Data Glossary | Z2: Formula for Data Glossary | AA2: Publish to Platform (Y/N) | AB2: Integrate To WofG (Y/N) | AC2: Data Source Name | AD2: Data Asset Source Path | AE2: Data Asset Type | AF2: Scope
A3: DED_Data_Table_001 | C3: ACCOUNTING_AUDIT_TRAIL | D3: Financial_Audit_Trail | E3: مسار_التدقيق_المالي | F3: Information of Accounting audit trail. | G3: معلومات سجل تدقيق المحاسبة. | H3: aiaalsheebani@ded.abudhabi.ae, rfmdaas@adra.gov.ae | I3: sraalbadi@ded.abudhabi.ae, rfmdaas@adra.gov.ae | J3: Accela | K3: DED_Domain_05 | L3: Financial Information | M3: 46175 | N3: 46273 | O3: Y | V3: Weekly | W3: =Table1[[#This Row],[Domain Name]] -> Financial Information | X3: Sensitive | Y3: Record Service Provider Code, Application ID, Financial Audit Sequence Number, Invoice ID, Receipt ID, Payment ID, Receipt Amount, Action, Application Fee ID, Payment Method Type Code, Payment Reference Number, Register Number, Record Status, Insert Timestamp, Update Timestamp, Row Hash, Business Key Hash, Processing Run ID, System Record Date | Z3: {=_xlfn.TEXTJOIN(", ",TRUE,_xlfn.UNIQUE(_xlfn._xlws.FILTER('B1.3 Catalogue Attribute'!AJ:AJ,'B1.3 Catalogue Attribute'!L:L=A3,"")))} -> Record Service Provider Code, Application ID, Financial Audit Sequence Number, Invoice ID, Receipt ID, Payment ID, Receipt Amount, Action, Application Fee ID, Payment Method Type Code, Payment Reference Number, Register Number, Record Status, Insert Timestamp, Update Timestamp, Row Hash, Business Key Hash, Processing Run ID, System Record Date | AA3: Y | AB3: Y | AC3: Oracle DB | AD3: =_xlfn.CONCAT("accelapr/",Table1[[#This Row],[Bronze Table]]) -> accelapr/ACCOUNTING_AUDIT_TRAIL | AE3: Table | AF3: Sprint 1
A4: DED_Data_Table_019 | C4: F4FEEITEM | D4: Application_Fee | E4: رسوم_الطلب | F4: Information of finance module application fee item. | G4: يحتوي على بيانات بنود الرسوم المرتبطة بالطلبات والمعاملات ضمن النظام المالي. | H4: aiaalsheebani@ded.abudhabi.ae, rfmdaas@adra.gov.ae | I4: sraalbadi@ded.abudhabi.ae, rfmdaas@adra.gov.ae | J4: Accela | K4: DED_Domain_05 | L4: Financial Information | M4: 46175 | N4: 46273 | O4: Y | V4: Weekly | W4: =Table1[[#This Row],[Domain Name]] -> Financial Information | X4: Sensitive | Y4: Record Service Provider Code, Application ID, Application Fee ID, Fee Formula Value, Unit Count, Unit Description, Fee Amount, Fee Apply Date, Fee Sub Group Type Code, Is Fee Calculated Indicator, Application Fee Item Status Description, Record Status, Application Fee Group Code, Pos Transaction Sequence Number, Fee Note Text, Parent Fee Item Sequence Number, Insert Timestamp, Update Timestamp, Processing Run ID, Row Hash, Business Key Hash, Fee Period, Fee Item Code, Version Code, System Record Date | Z4: {=_xlfn.TEXTJOIN(", ",TRUE,_xlfn.UNIQUE(_xlfn._xlws.FILTER('B1.3 Catalogue Attribute'!AJ:AJ,'B1.3 Catalogue Attribute'!L:L=A4,"")))} -> Record Service Provider Code, Application ID, Application Fee ID, Fee Formula Value, Unit Count, Unit Description, Fee Amount, Fee Apply Date, Fee Sub Group Type Code, Is Fee Calculated Indicator, Application Fee Item Status Description, Record Status, Application Fee Group Code, Pos Transaction Sequence Number, Fee Note Text, Parent Fee Item Sequence Number, Insert Timestamp, Update Timestamp, Processing Run ID, Row Hash, Business Key Hash, Fee Period, Fee Item Code, Version Code, System Record Date | AA4: Y | AB4: Y | AC4: Oracle DB | AD4: =_xlfn.CONCAT("accelapr/",Table1[[#This Row],[Bronze Table]]) -> accelapr/F4FEEITEM | AE4: Table | AF4: Sprint 1
A5: DED_Data_Table_020 | C5: F4FEEITEM_AUDIT_TRAIL | D5: Application_Fee_Audit | E5: تدقيق_رسوم_الطلب | F5: Information of finance module fee item audit trail which is before invoicing. | G5: يحتوي على السجل التدقيقي للتغييرات التي تطرأ على بنود الرسوم قبل إصدار الفواتير. | H5: aiaalsheebani@ded.abudhabi.ae, rfmdaas@adra.gov.ae | I5: sraalbadi@ded.abudhabi.ae, rfmdaas@adra.gov.ae | J5: Accela | K5: DED_Domain_05 | L5: Financial Information | M5: 46175 | N5: 46273 | O5: Y | V5: Weekly | W5: =Table1[[#This Row],[Domain Name]] -> Financial Information | X5: Sensitive | Y5: Record Service Provider Code, Fee Audit Trail Sequence Number, Application ID, Application Fee ID, Fee Period, Fee Item Code, Account Code, Account Code Level 3, Unit Count, Fee Amount, Fee Apply Date, Fee Sub Group Type Code, Application Fee Item Status Description, Record Status, Application Fee Group Code, Version Code, Fee Note Text, Insert Timestamp, Update Timestamp, Processing Run ID, Row Hash, Business Key Hash, System Record Date | Z5: {=_xlfn.TEXTJOIN(", ",TRUE,_xlfn.UNIQUE(_xlfn._xlws.FILTER('B1.3 Catalogue Attribute'!AJ:AJ,'B1.3 Catalogue Attribute'!L:L=A5,"")))} -> Record Service Provider Code, Fee Audit Trail Sequence Number, Application ID, Application Fee ID, Fee Period, Fee Item Code, Account Code, Account Code Level 3, Unit Count, Fee Amount, Fee Apply Date, Fee Sub Group Type Code, Application Fee Item Status Description, Record Status, Application Fee Group Code, Version Code, Fee Note Text, Insert Timestamp, Update Timestamp, Processing Run ID, Row Hash, Business Key Hash, System Record Date | AA5: Y | AB5: Y | AC5: Oracle DB | AD5: =_xlfn.CONCAT("accelapr/",Table1[[#This Row],[Bronze Table]]) -> accelapr/F4FEEITEM_AUDIT_TRAIL | AE5: Table | AF5: Sprint 1
A6: DED_Data_Table_021 | C6: F4INVOICE | D6: Application_Invoice | E6: فاتورة_الطلب | F6: Information of finance module invoice. It includes invoice number, amount, date, and so on. | G6: يحتوي على بيانات الفواتير، بما في ذلك رقم الفاتورة والمبلغ وتاريخ الإصدار وغيرها من التفاصيل المالية ذات الصلة. | H6: aiaalsheebani@ded.abudhabi.ae, rfmdaas@adra.gov.ae | I6: sraalbadi@ded.abudhabi.ae, rfmdaas@adra.gov.ae | J6: Accela | K6: DED_Domain_05 | L6: Financial Information | M6: 46175 | N6: 46273 | O6: Y | V6: Weekly | W6: =Table1[[#This Row],[Domain Name]] -> Financial Information | X6: Sensitive | Y6: Record Service Provider Code, Invoice ID, Invoice Status Description, Invoice Due Amount, Invoice Amount, Invoice Date, Invoice Batch Number, Printed Invoice Code, Record Status, Customized Invoice Code, Insert Timestamp, Update Timestamp, Processing Run ID, Business Key Hash, Row Hash | Z6: {=_xlfn.TEXTJOIN(", ",TRUE,_xlfn.UNIQUE(_xlfn._xlws.FILTER('B1.3 Catalogue Attribute'!AJ:AJ,'B1.3 Catalogue Attribute'!L:L=A6,"")))} -> Record Service Provider Code, Invoice ID, Invoice Status Description, Invoice Due Amount, Invoice Amount, Invoice Date, Invoice Batch Number, Printed Invoice Code, Record Status, Customized Invoice Code, Insert Timestamp, Update Timestamp, Processing Run ID, Business Key Hash, Row Hash | AA6: Y | AB6: Y | AC6: Oracle DB | AD6: =_xlfn.CONCAT("accelapr/",Table1[[#This Row],[Bronze Table]]) -> accelapr/F4INVOICE | AE6: Table | AF6: Sprint 1
A7: DED_Data_Table_022 | C7: F4PAYMENT | D7: Application_Payment | E7: دفعة_الطلب | F7: Information of finance module application payment. | G7: معلومات الفاتورة ضمن وحدة المالية، وتشمل رقم الفاتورة، المبلغ، التاريخ، وغيرها. | H7: aiaalsheebani@ded.abudhabi.ae, rfmdaas@adra.gov.ae | I7: sraalbadi@ded.abudhabi.ae, rfmdaas@adra.gov.ae | J7: Accela | K7: DED_Domain_05 | L7: Financial Information | M7: 46175 | N7: 46273 | O7: Y | V7: Weekly | W7: =Table1[[#This Row],[Domain Name]] -> Financial Information | X7: Sensitive | Y7: Record Service Provider Code, Application ID, Payment ID, Receipt ID, Payment Method Type Code, Payment Date & Time, Payment Amount, Not Allocated Amount, Payment Status Code, Record Status, Pos Transaction Sequence Number, Total Invoice Amount, Total Payment Amount, Batch Transaction Number, Payment Group Number, Insert Timestamp, Update Timestamp, Processing Run ID, Row Hash, Business Key Hash | Z7: {=_xlfn.TEXTJOIN(", ",TRUE,_xlfn.UNIQUE(_xlfn._xlws.FILTER('B1.3 Catalogue Attribute'!AJ:AJ,'B1.3 Catalogue Attribute'!L:L=A7,"")))} -> Record Service Provider Code, Application ID, Payment ID, Receipt ID, Payment Method Type Code, Payment Date & Time, Payment Amount, Not Allocated Amount, Payment Status Code, Record Status, Pos Transaction Sequence Number, Total Invoice Amount, Total Payment Amount, Batch Transaction Number, Payment Group Number, Insert Timestamp, Update Timestamp, Processing Run ID, Row Hash, Business Key Hash | AA7: Y | AB7: Y | AC7: Oracle DB | AD7: =_xlfn.CONCAT("accelapr/",Table1[[#This Row],[Bronze Table]]) -> accelapr/F4PAYMENT | AE7: Table | AF7: Sprint 1
A8: DED_Data_Table_023 | C8: F4RECEIPT | D8: Application_Receipt | E8: إيصال_الطلب | F8: Information of finance module receipt. | G8: يحتوي على بيانات الإيصالات المالية المرتبطة بالطلبات والمعاملات، | H8: aiaalsheebani@ded.abudhabi.ae, rfmdaas@adra.gov.ae | I8: sraalbadi@ded.abudhabi.ae, rfmdaas@adra.gov.ae | J8: Accela | K8: DED_Domain_05 | L8: Financial Information | M8: 46175 | N8: 46273 | O8: Y | V8: Weekly | W8: =Table1[[#This Row],[Domain Name]] -> Financial Information | X8: Sensitive | Y8: Record Service Provider Code, Receipt ID, Receipt Date, Register Number, Receipt Amount, Receipt Batch Number, Receipt Batch Date, Receipt Status Code, Receipt Customized Number, Total Invoice Amount, Total Payment Amount, Insert Timestamp, Update Timestamp, Processing Run ID, Row Hash, Business Key Hash | Z8: {=_xlfn.TEXTJOIN(", ",TRUE,_xlfn.UNIQUE(_xlfn._xlws.FILTER('B1.3 Catalogue Attribute'!AJ:AJ,'B1.3 Catalogue Attribute'!L:L=A8,"")))} -> Record Service Provider Code, Receipt ID, Receipt Date, Register Number, Receipt Amount, Receipt Batch Number, Receipt Batch Date, Receipt Status Code, Receipt Customized Number, Total Invoice Amount, Total Payment Amount, Insert Timestamp, Update Timestamp, Processing Run ID, Row Hash, Business Key Hash | AA8: Y | AB8: Y | AC8: Oracle DB | AD8: =_xlfn.CONCAT("accelapr/",Table1[[#This Row],[Bronze Table]]) -> accelapr/F4RECEIPT | AE8: Table | AF8: Sprint 1
A9: DED_Data_Table_041 | C9: RFEEITEM | D9: Application_Fee_Reference | E9: مرجع_رسوم_الطلب | F9: Information of reference fee item. | G9: معلومات بند الرسوم المرجعي. | H9: aiaalsheebani@ded.abudhabi.ae, rfmdaas@adra.gov.ae | I9: sraalbadi@ded.abudhabi.ae, rfmdaas@adra.gov.ae | J9: Accela | K9: DED_Domain_05 | L9: Financial Information | M9: 46175 | N9: 46273 | O9: Y | V9: Weekly | W9: =Table1[[#This Row],[Domain Name]] -> Financial Information | X9: Confidential | Y9: Record Service Provider Code, Application Fee Group Code, Fee Period, Fee Item Code, Account Code, Account Code Level 3, Record Status, Fee Note Text, Version Code, Resource ID, Insert Timestamp, Update Timestamp, Processing Run ID, Row Hash, Business Key Hash | Z9: {=_xlfn.TEXTJOIN(", ",TRUE,_xlfn.UNIQUE(_xlfn._xlws.FILTER('B1.3 Catalogue Attribute'!AJ:AJ,'B1.3 Catalogue Attribute'!L:L=A9,"")))} -> Record Service Provider Code, Application Fee Group Code, Fee Period, Fee Item Code, Account Code, Account Code Level 3, Record Status, Fee Note Text, Version Code, Resource ID, Insert Timestamp, Update Timestamp, Processing Run ID, Row Hash, Business Key Hash | AA9: Y | AB9: Y | AC9: Oracle DB | AD9: =_xlfn.CONCAT("accelapr/",Table1[[#This Row],[Bronze Table]]) -> accelapr/RFEEITEM | AE9: Table | AF9: Sprint 1
A10: DED_Data_Table_087 | C10: VIRTUAL_OUTSTANDING_FEES | D10: Outstanding_Fees | E10: الرسوم_المستحقة | F10: Stores outstanding fee items, approving-entity references, amounts, and payment status. | G10: يحتوي على تفاصيل الرسوم المستحقة، بما في ذلك مراجع جهات الاعتماد والمبالغ وحالة السداد. | H10: aiaalsheebani@ded.abudhabi.ae, rfmdaas@adra.gov.ae | I10: sraalbadi@ded.abudhabi.ae, rfmdaas@adra.gov.ae | J10: Accela | K10: DED_Domain_05 | L10: Financial Information | M10: 46175 | N10: 46273 | O10: Y | V10: Weekly | W10: =Table1[[#This Row],[Domain Name]] -> Financial Information | X10: Sensitive | Y10: Record Service Provider Code, Application ID, Record Group, Approving Entity Reference Date, Approving Entity Reference Number, Approving Entity, Outstanding Fees Comments, Fee Item Code, Fee Entry By, Fee Entry Date, Fee Entry Time, Fee Schedule, Fees, Status, Transaction Number, Record Type, System Record Date, Record Status, Row Index, Insert Timestamp, Update Timestamp, Business Key Hash, Row Hash, Processing Run ID | Z10: {=_xlfn.TEXTJOIN(", ",TRUE,_xlfn.UNIQUE(_xlfn._xlws.FILTER('B1.3 Catalogue Attribute'!AJ:AJ,'B1.3 Catalogue Attribute'!L:L=A10,"")))} -> Record Service Provider Code, Application ID, Record Group, Approving Entity Reference Date, Approving Entity Reference Number, Approving Entity, Outstanding Fees Comments, Fee Item Code, Fee Entry By, Fee Entry Date, Fee Entry Time, Fee Schedule, Fees, Status, Transaction Number, Record Type, System Record Date, Record Status, Row Index, Insert Timestamp, Update Timestamp, Business Key Hash, Row Hash, Processing Run ID | AA10: Y | AB10: N | AC10: Oracle DB | AD10: =_xlfn.CONCAT("accelapr/",Table1[[#This Row],[Bronze Table]]) -> accelapr/VIRTUAL_OUTSTANDING_FEES | AE10: Table | AF10: Sprint 2
A11: DED_Data_Table_109 | C11: VIRTUAL_VIOLATIONS_RECORD | D11: Violations_Record | E11: سجل_المخالفات | F11: Stores violation details, categories, amounts, inspectors, and update history. | G11: يخزن تفاصيل المخالفات، الفئات، المبالغ، المفتش، وتاريخ التحديثات. | H11: aiaalsheebani@ded.abudhabi.ae, rfmdaas@adra.gov.ae | I11: sraalbadi@ded.abudhabi.ae, rfmdaas@adra.gov.ae | J11: Accela | K11: DED_Domain_06 | L11: Fines & Violations | M11: 46175 | N11: 46273 | O11: Y | V11: Weekly | W11: =Table1[[#This Row],[Domain Name]] -> Fines & Violations | X11: Sensitive | Y11: Record Service Provider Code, Application ID, Record Group, Inspector, Update Date, Updated Record ID, Violation Amount, Violation Category, Violation Code, Violation Date, Violation Description, Violation Fee Sequence Number, Violation Level, Violation Status, Violation Type, System Record Date, Record Status, Row Index, Insert Timestamp, Update Timestamp, Business Key Hash, Row Hash, Processing Run ID | Z11: {=_xlfn.TEXTJOIN(", ",TRUE,_xlfn.UNIQUE(_xlfn._xlws.FILTER('B1.3 Catalogue Attribute'!AJ:AJ,'B1.3 Catalogue Attribute'!L:L=A11,"")))} -> Record Service Provider Code, Application ID, Record Group, Inspector, Update Date, Updated Record ID, Violation Amount, Violation Category, Violation Code, Violation Date, Violation Description, Violation Fee Sequence Number, Violation Level, Violation Status, Violation Type, System Record Date, Record Status, Row Index, Insert Timestamp, Update Timestamp, Business Key Hash, Row Hash, Processing Run ID | AA11: Y | AB11: N | AC11: Oracle DB | AD11: =_xlfn.CONCAT("accelapr/",Table1[[#This Row],[Bronze Table]]) -> accelapr/VIRTUAL_VIOLATIONS_RECORD | AE11: Table | AF11: Sprint 2
A12: DED_Data_Table_185 | C12: br_capital_type | D12: capital_type | E12: نوع_رأس_المال | F12: Provides capital information, including capital value, capital payable, recorded capital, total number of shares, bank name, and issuance place. | G12: يتضمن معلومات رأس المال، مثل قيمة رأس المال، والمبلغ الواجب دفعه، ورأس المال المسجل، وإجمالي عدد الأسهم، واسم البنك، ومكان الإصدار. | H12: aiaalsheebani@ded.abudhabi.ae, rfmdaas@adra.gov.ae | I12: sraalbadi@ded.abudhabi.ae, rfmdaas@adra.gov.ae | J12: Accela | K12: DED_Domain_05 | L12: Financial Information | M12: 46175 | N12: 46273 | O12: Y | V12: Weekly | W12: =Table1[[#This Row],[Domain Name]] -> Financial Information | X12: Confidential | Y12: Record Service Provider Code, Application ID, Application Service Type Code, Application Request Type Code, Capital Value, Capital to Be Paid, Capital, Total Number of Shares, Bank Name, Issuance Place, Issuance Date, Issuance Number, Capital Deposit Date, Record Status, Insert Timestamp, Update Timestamp, Processing Run ID, Business Key Hash, Row Hash | Z12: {=_xlfn.TEXTJOIN(", ",TRUE,_xlfn.UNIQUE(_xlfn._xlws.FILTER('B1.3 Catalogue Attribute'!AJ:AJ,'B1.3 Catalogue Attribute'!L:L=A12,"")))} -> Record Service Provider Code, Application ID, Application Service Type Code, Application Request Type Code, Capital Value, Capital to Be Paid, Capital, Total Number of Shares, Bank Name, Issuance Place, Issuance Date, Issuance Number, Capital Deposit Date, Record Status, Insert Timestamp, Update Timestamp, Processing Run ID, Business Key Hash, Row Hash | AA12: Y | AB12: Y | AC12: Oracle DB | AD12: accelapr/bchckbox | AE12: Table | AF12: Sprint 3
A13: DED_Data_Table_190 | C13: br_creditor_information | D13: creditor_information | E13: معلومات_الدائن | F13: Provides creditor information, including licence number, phone number, name, English and Arabic trade names, and email address. | G13: يتضمن معلومات الدائن، مثل رقم الرخصة، ورقم الهاتف، والاسم، والاسم التجاري بالإنجليزية والعربية، والبريد الإلكتروني. | H13: aiaalsheebani@ded.abudhabi.ae, rfmdaas@adra.gov.ae | I13: sraalbadi@ded.abudhabi.ae, rfmdaas@adra.gov.ae | J13: Accela | K13: DED_Domain_05 | L13: Financial Information | M13: 46175 | N13: 46273 | O13: Y | V13: Weekly | W13: =Table1[[#This Row],[Domain Name]] -> Financial Information | X13: Confidential | Y13: Record Service Provider Code, Application ID, Application Service Type Code, Application Request Type Code, Economic License Number, Phone Number, Name, Trade Name (English), Trade Name (Arabic), Email Address, Record Status, Insert Timestamp, Update Timestamp, Processing Run ID, Business Key Hash, Row Hash | Z13: {=_xlfn.TEXTJOIN(", ",TRUE,_xlfn.UNIQUE(_xlfn._xlws.FILTER('B1.3 Catalogue Attribute'!AJ:AJ,'B1.3 Catalogue Attribute'!L:L=A13,"")))} -> Record Service Provider Code, Application ID, Application Service Type Code, Application Request Type Code, Economic License Number, Phone Number, Name, Trade Name (English), Trade Name (Arabic), Email Address, Record Status, Insert Timestamp, Update Timestamp, Processing Run ID, Business Key Hash, Row Hash | AA13: Y | AB13: Y | AC13: Oracle DB | AD13: accelapr/bchckbox | AE13: Table | AF13: Sprint 3
A14: DED_Data_Table_025 | C14: G6ACTION | D14: Inspection_Suspension | E14: تعليق_التفتيش | F14: Information of Application inspections - Inspector, Department, and other attributes. | G14: معلومات تركيبة المستويات السبعة للغات المتعددة، وهي: الجهة، الإدارة، القسم، الوحدة، المجموعة، المجموعة الفرعية، والمكتب. | H14: amnalharthi@ded.abudhabi.ae, rfmdaas@adra.gov.ae | I14: ajmalhammadi@adra.gov.ae, fbakerbi@adra.gov.ae, rfmdaas@adra.gov.ae | J14: Accela | K14: DED_Domain_03 | L14: Inspection | M14: 46175 | N14: 46273 | O14: Y | V14: Weekly | W14: =Table1[[#This Row],[Domain Name]] -> Inspection | X14: Confidential | Y14: Record Service Provider Code, Application ID, Ispection Suspention ID, Inspection Bureau Code, Inspection Division Code, Inspection Branch Office Code, Inspection Section Code, Inspection Group Code, Inspection Scheduled Date, Inspection Type Description, Inspection Completion Date, Inspection Status, Inspection Submited Date, Record Status, Inspection Type Code, Insert Timestamp, Update Timestamp, Processing Run ID, Business Key Hash, Row Hash | Z14: {=_xlfn.TEXTJOIN(", ",TRUE,_xlfn.UNIQUE(_xlfn._xlws.FILTER('B1.3 Catalogue Attribute'!AJ:AJ,'B1.3 Catalogue Attribute'!L:L=A14,"")))} -> Record Service Provider Code, Application ID, Ispection Suspention ID, Inspection Bureau Code, Inspection Division Code, Inspection Branch Office Code, Inspection Section Code, Inspection Group Code, Inspection Scheduled Date, Inspection Type Description, Inspection Completion Date, Inspection Status, Inspection Submited Date, Record Status, Inspection Type Code, Insert Timestamp, Update Timestamp, Processing Run ID, Business Key Hash, Row Hash | AA14: Y | AB14: Y | AC14: Oracle DB | AD14: =_xlfn.CONCAT("accelapr/",Table1[[#This Row],[Bronze Table]]) -> accelapr/G6ACTION | AE14: Table | AF14: Sprint 1
A15: DED_Data_Table_043 | C15: RINSPTYP | D15: Inspection_Types | E15: أنواع_التفتيش | F15: Information of inspection types. | G15: معلومات بنود ورقة إرشادات التفتيش المرجعية للغات المتعددة. | H15: amnalharthi@ded.abudhabi.ae, rfmdaas@adra.gov.ae | I15: ajmalhammadi@adra.gov.ae, fbakerbi@adra.gov.ae, rfmdaas@adra.gov.ae | J15: Accela | K15: DED_Domain_03 | L15: Inspection | M15: 46175 | N15: 46273 | O15: Y | V15: Weekly | W15: =Table1[[#This Row],[Domain Name]] -> Inspection | X15: Sensitive | Y15: Record Service Provider Code, Inspection Type Code, Inspection Type Description, Record Status, Inspection Result Group, Resource ID, Insert Timestamp, Update Timestamp, Processing Run ID, Business Key Hash, Row Hash | Z15: {=_xlfn.TEXTJOIN(", ",TRUE,_xlfn.UNIQUE(_xlfn._xlws.FILTER('B1.3 Catalogue Attribute'!AJ:AJ,'B1.3 Catalogue Attribute'!L:L=A15,"")))} -> Record Service Provider Code, Inspection Type Code, Inspection Type Description, Record Status, Inspection Result Group, Resource ID, Insert Timestamp, Update Timestamp, Processing Run ID, Business Key Hash, Row Hash | AA15: Y | AB15: Y | AC15: Oracle DB | AD15: =_xlfn.CONCAT("accelapr/",Table1[[#This Row],[Bronze Table]]) -> accelapr/RINSPTYP | AE15: Table | AF15: Sprint 1
A16: DED_Data_Table_044 | C16: RINSPTYP_I18N | D16: Inspection_Types_Language | E16: لغات_أنواع_التفتيش | F16: Stores multilingual names and descriptions of inspection types used in the system. | G16: يحتوي على تفاصيل وأوصاف شروط المتطلبات المرتبطة بالطلبات بمختلف اللغات المعتمدة في النظام. | H16: amnalharthi@ded.abudhabi.ae, rfmdaas@adra.gov.ae | I16: ajmalhammadi@adra.gov.ae, fbakerbi@adra.gov.ae, rfmdaas@adra.gov.ae | J16: Accela | K16: DED_Domain_03 | L16: Inspection | M16: 46175 | N16: 46273 | O16: Y | V16: Weekly | W16: =Table1[[#This Row],[Domain Name]] -> Inspection | X16: Sensitive | Y16: Record Service Provider Code, Resource ID, Language ID, Inspection Type Description (Arabic), Inspection Group Type Code, Record Status, Inspection Group Type Name, Insert Timestamp, Update Timestamp, Processing Run ID, Business Key Hash, Row Hash | Z16: {=_xlfn.TEXTJOIN(", ",TRUE,_xlfn.UNIQUE(_xlfn._xlws.FILTER('B1.3 Catalogue Attribute'!AJ:AJ,'B1.3 Catalogue Attribute'!L:L=A16,"")))} -> Record Service Provider Code, Resource ID, Language ID, Inspection Type Description (Arabic), Inspection Group Type Code, Record Status, Inspection Group Type Name, Insert Timestamp, Update Timestamp, Processing Run ID, Business Key Hash, Row Hash | AA16: Y | AB16: Y | AC16: Oracle DB | AD16: =_xlfn.CONCAT("accelapr/",Table1[[#This Row],[Bronze Table]]) -> accelapr/RINSPTYP_I18N | AE16: Table | AF16: Sprint 1
A17: DED_Data_Table_045 | C17: RINSP_RESULT_GROUP | D17: Inspection_Relationship | E17: علاقة_التفتيش | F17: Information of the definition of the inspection group and the relationship between the inspection result and the inspection status. | G17: معلومات أنواع التفتيش للغات المتعددة. | H17: amnalharthi@ded.abudhabi.ae, rfmdaas@adra.gov.ae | I17: ajmalhammadi@adra.gov.ae, fbakerbi@adra.gov.ae, rfmdaas@adra.gov.ae | J17: Accela | K17: DED_Domain_03 | L17: Inspection | M17: 46175 | N17: 46273 | O17: Y | V17: Weekly | W17: =Table1[[#This Row],[Domain Name]] -> Inspection | X17: Sensitive | Y17: Record Service Provider Code, Inspection Result Group, Inspection Result, Record Status, Resource ID, Inspection Result Category, Insert Timestamp, Update Timestamp, Business Key Hash, Row Hash, Processing Run ID | Z17: {=_xlfn.TEXTJOIN(", ",TRUE,_xlfn.UNIQUE(_xlfn._xlws.FILTER('B1.3 Catalogue Attribute'!AJ:AJ,'B1.3 Catalogue Attribute'!L:L=A17,"")))} -> Record Service Provider Code, Inspection Result Group, Inspection Result, Record Status, Resource ID, Inspection Result Category, Insert Timestamp, Update Timestamp, Business Key Hash, Row Hash, Processing Run ID | AA17: Y | AB17: Y | AC17: Oracle DB | AD17: =_xlfn.CONCAT("accelapr/",Table1[[#This Row],[Bronze Table]]) -> accelapr/RINSP_RESULT_GROUP | AE17: Table | AF17: Sprint 2
A18: DED_Data_Table_046 | C18: RINSP_RESULT_GROUP_I18N | D18: Inspection_Relationship_Language | E18: لغات_علاقة_التفتيش | F18: Stores multilingual definitions of inspection groups and the relationships between inspection results and inspection statuses. | G18: يحتوي على أسماء وأوصاف شروط الطلبات بمختلف اللغات، بما في ذلك شروط القفل والتعليق والتنبيه. | H18: amnalharthi@ded.abudhabi.ae, rfmdaas@adra.gov.ae | I18: ajmalhammadi@adra.gov.ae, fbakerbi@adra.gov.ae, rfmdaas@adra.gov.ae | J18: Accela | K18: DED_Domain_03 | L18: Inspection | M18: 46175 | N18: 46273 | O18: Y | V18: Weekly | W18: =Table1[[#This Row],[Domain Name]] -> Inspection | X18: Sensitive | Y18: Record Service Provider Code, Resource ID, Language ID, Record Status, Inspection Result, Insert Timestamp, Update Timestamp, Business Key Hash, Row Hash, Processing Run ID | Z18: {=_xlfn.TEXTJOIN(", ",TRUE,_xlfn.UNIQUE(_xlfn._xlws.FILTER('B1.3 Catalogue Attribute'!AJ:AJ,'B1.3 Catalogue Attribute'!L:L=A18,"")))} -> Record Service Provider Code, Resource ID, Language ID, Record Status, Inspection Result, Insert Timestamp, Update Timestamp, Business Key Hash, Row Hash, Processing Run ID | AA18: Y | AB18: Y | AC18: Oracle DB | AD18: =_xlfn.CONCAT("accelapr/",Table1[[#This Row],[Bronze Table]]) -> accelapr/RINSP_RESULT_GROUP_I18N | AE18: Table | AF18: Sprint 2
A19: DED_Data_Table_074 | C19: VIRTUAL_INSPECTORCOORDINATES | D19: Inspector_Coordinates | E19: إحداثيات_المفتش | F19: Stores inspector geolocation coordinates captured during inspection activities. | G19: يحتوي على إحداثيات الموقع الجغرافي التي يتم تسجيلها أثناء تنفيذ أنشطة التفتيش. | H19: amnalharthi@ded.abudhabi.ae, rfmdaas@adra.gov.ae | I19: ajmalhammadi@adra.gov.ae, fbakerbi@adra.gov.ae, rfmdaas@adra.gov.ae | J19: Accela | K19: DED_Domain_03 | L19: Inspection | M19: 46175 | N19: 46273 | O19: Y | V19: Weekly | W19: =Table1[[#This Row],[Domain Name]] -> Inspection | X19: Confidential | Y19: Record Service Provider Code, Application ID, Record Group, Inspector Date & Time, Inspection ID, Inspector X Coordinate, Inspector Y Coordinate, Inspector Record Date, Record Status, Row Index, Insert Timestamp, Update Timestamp, Processing Run ID, Inspector Coordinates ID, Effective From Timestamp, Effective Till Timestamp, Active Flag, Business Key Hash, Row Hash | Z19: {=_xlfn.TEXTJOIN(", ",TRUE,_xlfn.UNIQUE(_xlfn._xlws.FILTER('B1.3 Catalogue Attribute'!AJ:AJ,'B1.3 Catalogue Attribute'!L:L=A19,"")))} -> Record Service Provider Code, Application ID, Record Group, Inspector Date & Time, Inspection ID, Inspector X Coordinate, Inspector Y Coordinate, Inspector Record Date, Record Status, Row Index, Insert Timestamp, Update Timestamp, Processing Run ID, Inspector Coordinates ID, Effective From Timestamp, Effective Till Timestamp, Active Flag, Business Key Hash, Row Hash | AA19: Y | AB19: N | AC19: Oracle DB | AD19: =_xlfn.CONCAT("accelapr/",Table1[[#This Row],[Bronze Table]]) -> accelapr/VIRTUAL_INSPECTORCOORDINATES | AE19: Table | AF19: Sprint 1
A20: DED_Data_Table_110 | C20: VIRTUAL_VIRTUAL_INSPECTION | D20: Virtual_Inspection | E20: التفتيش_الافتراضي | F20: Stores virtual-inspection identifiers, status, users, and update dates. | G20: يخزن معرفات الفحص الافتراضي، الحالة، المستخدمين، وتواريخ التحديث. | H20: amnalharthi@ded.abudhabi.ae, rfmdaas@adra.gov.ae | I20: ajmalhammadi@adra.gov.ae, fbakerbi@adra.gov.ae, rfmdaas@adra.gov.ae | J20: Accela | K20: DED_Domain_03 | L20: Inspection | M20: 46175 | N20: 46273 | O20: Y | V20: Weekly | W20: =Table1[[#This Row],[Domain Name]] -> Inspection | X20: Confidential | Y20: Record Service Provider Code, Application ID, Record Group, Inspection ID, Inspection Status, Update Date, User ID, System Record Date, Record Status, Row Index, Insert Timestamp, Update Timestamp, Business Key Hash, Row Hash, Processing Run ID | Z20: {=_xlfn.TEXTJOIN(", ",TRUE,_xlfn.UNIQUE(_xlfn._xlws.FILTER('B1.3 Catalogue Attribute'!AJ:AJ,'B1.3 Catalogue Attribute'!L:L=A20,"")))} -> Record Service Provider Code, Application ID, Record Group, Inspection ID, Inspection Status, Update Date, User ID, System Record Date, Record Status, Row Index, Insert Timestamp, Update Timestamp, Business Key Hash, Row Hash, Processing Run ID | AA20: Y | AB20: N | AC20: Oracle DB | AD20: =_xlfn.CONCAT("accelapr/",Table1[[#This Row],[Bronze Table]]) -> accelapr/VIRTUAL_VIRTUAL_INSPECTION | AE20: Table | AF20: Sprint 2
A21: DED_Data_Table_235 | C21: br_virtual_inspection_confirmation | D21: virtual_inspection_confirmation | E21: تأكيد_التفتيش_الافتراضي | F21: Provides virtual-inspection information. | G21: يتضمن معلومات التفتيش الافتراضي. | H21: amnalharthi@ded.abudhabi.ae, rfmdaas@adra.gov.ae | I21: ajmalhammadi@adra.gov.ae, fbakerbi@adra.gov.ae, rfmdaas@adra.gov.ae | J21: Accela | K21: DED_Domain_03 | L21: Inspection | M21: 46175 | N21: 46273 | O21: Y | V21: Weekly | W21: =Table1[[#This Row],[Domain Name]] -> Inspection | X21: Confidential | Y21: Record Service Provider Code, Application ID, Application Service Type Code, Application Request Type Code, Virtual, Record Status, Insert Timestamp, Update Timestamp, Processing Run ID, Business Key Hash, Row Hash | Z21: {=_xlfn.TEXTJOIN(", ",TRUE,_xlfn.UNIQUE(_xlfn._xlws.FILTER('B1.3 Catalogue Attribute'!AJ:AJ,'B1.3 Catalogue Attribute'!L:L=A21,"")))} -> Record Service Provider Code, Application ID, Application Service Type Code, Application Request Type Code, Virtual, Record Status, Insert Timestamp, Update Timestamp, Processing Run ID, Business Key Hash, Row Hash | AA21: Y | AB21: Y | AC21: Oracle DB | AD21: accelapr/bchckbox | AE21: Table | AF21: Sprint 3
A22: DED_Data_Table_002 | C22: APP_STATUS_GROUP | D22: Status_Lookup | E22: مرجع_الحالات | F22: Information of application status group name. | G22: معلومات سجل تدقيق المحاسبة. | H22: bmalkindi@adra.gov.ae, rfmdaas@adra.gov.ae | I22: asalmehiry@adra.gov.ae, rfmdaas@adra.gov.ae | J22: Accela | K22: DED_Domain_01 | L22: Economic Licenses | M22: 46175 | N22: 46273 | O22: Y | V22: Weekly | W22: =Table1[[#This Row],[Domain Name]] -> Economic Licenses | X22: Sensitive | Y22: Application Status Code, Application Status Description, Record Status, Record Service Provider Code, Resource ID, Insert Timestamp, Update Timestamp, Processing Run ID, Row Hash, Business Key Hash | Z22: {=_xlfn.TEXTJOIN(", ",TRUE,_xlfn.UNIQUE(_xlfn._xlws.FILTER('B1.3 Catalogue Attribute'!AJ:AJ,'B1.3 Catalogue Attribute'!L:L=A22,"")))} -> Application Status Code, Application Status Description, Record Status, Record Service Provider Code, Resource ID, Insert Timestamp, Update Timestamp, Processing Run ID, Row Hash, Business Key Hash | AA22: Y | AB22: Y | AC22: Oracle DB | AD22: =_xlfn.CONCAT("accelapr/",Table1[[#This Row],[Bronze Table]]) -> accelapr/APP_STATUS_GROUP | AE22: Table | AF22: Sprint 1
A23: DED_Data_Table_003 | C23: APP_STATUS_GROUP_I18N | D23: Status_Lookup_Language | E23: لغات_مرجع_الحالات | F23: Stores multilingual names and descriptions of application status groups used in the system. | G23: يحتوي على أسماء وأوصاف مجموعات حالات الطلبات بمختلف اللغات المعتمدة في النظام. | H23: bmalkindi@adra.gov.ae, rfmdaas@adra.gov.ae | I23: asalmehiry@adra.gov.ae, rfmdaas@adra.gov.ae | J23: Accela | K23: DED_Domain_01 | L23: Economic Licenses | M23: 46175 | N23: 46273 | O23: Y | V23: Weekly | W23: =Table1[[#This Row],[Domain Name]] -> Economic Licenses | X23: Sensitive | Y23: Record Service Provider Code, Resource ID, Language ID, Application Status Description (Arabic), Record Status, Insert Timestamp, Update Timestamp, Processing Run ID, Row Hash, Business Key Hash | Z23: {=_xlfn.TEXTJOIN(", ",TRUE,_xlfn.UNIQUE(_xlfn._xlws.FILTER('B1.3 Catalogue Attribute'!AJ:AJ,'B1.3 Catalogue Attribute'!L:L=A23,"")))} -> Record Service Provider Code, Resource ID, Language ID, Application Status Description (Arabic), Record Status, Insert Timestamp, Update Timestamp, Processing Run ID, Row Hash, Business Key Hash | AA23: Y | AB23: Y | AC23: Oracle DB | AD23: =_xlfn.CONCAT("accelapr/",Table1[[#This Row],[Bronze Table]]) -> accelapr/APP_STATUS_GROUP_I18N | AE23: Table | AF23: Sprint 1
A24: DED_Data_Table_004 | C24: B1PERMIT | D24: Application_Master | E24: الطلب_الرئيسي | F24: Stores the core information of applications and records, including application number, classification, type, category, creation date, and other key attributes. | G24: يحتوي على البيانات الأساسية للطلبات والسجلات، بما في ذلك رقم الطلب وتصنيفاته ونوعه وفئته وتاريخ إنشائه وغيرها من الخصائص الرئيسية. | H24: bmalkindi@adra.gov.ae, rfmdaas@adra.gov.ae | I24: asalmehiry@adra.gov.ae, rfmdaas@adra.gov.ae | J24: Accela | K24: DED_Domain_01 | L24: Economic Licenses | M24: 46175 | N24: 46273 | O24: Y | V24: Weekly | W24: =Table1[[#This Row],[Domain Name]] -> Economic Licenses | X24: Sensitive | Y24: Record Service Provider Code, Application ID, Application Service Group Code, Application Service Type Code, Application Request Type Code, Application Category Code, Application Submitted Date & Time, Record Status, Economic License Number, Insert Timestamp, Update Timestamp, Processing Run ID, Row Hash, Business Key Hash, Application Status Description, Application Status Code | Z24: {=_xlfn.TEXTJOIN(", ",TRUE,_xlfn.UNIQUE(_xlfn._xlws.FILTER('B1.3 Catalogue Attribute'!AJ:AJ,'B1.3 Catalogue Attribute'!L:L=A24,"")))} -> Record Service Provider Code, Application ID, Application Service Group Code, Application Service Type Code, Application Request Type Code, Application Category Code, Application Submitted Date & Time, Record Status, Economic License Number, Insert Timestamp, Update Timestamp, Processing Run ID, Row Hash, Business Key Hash, Application Status Description, Application Status Code | AA24: Y | AB24: Y | AC24: Oracle DB | AD24: =_xlfn.CONCAT("accelapr/",Table1[[#This Row],[Bronze Table]]) -> accelapr/B1PERMIT | AE24: Table | AF24: Sprint 1
A25: DED_Data_Table_005 | C25: B1_EXPIRATION | D25: License_Expiration | E25: انتهاء_صلاحية_الرخصة | F25: Information of tracing the license life cycle. It is used by license module. | G25: يحتوي على بيانات تتبع دورة حياة الترخيص ومراحله المختلفة، ويُستخدم لإدارة ومتابعة حالة الترخيص ضمن نظام التراخيص. | H25: bmalkindi@adra.gov.ae, rfmdaas@adra.gov.ae | I25: asalmehiry@adra.gov.ae, rfmdaas@adra.gov.ae | J25: Accela | K25: DED_Domain_01 | L25: Economic Licenses | M25: 46175 | N25: 46273 | O25: Y | V25: Weekly | W25: =Table1[[#This Row],[Domain Name]] -> Economic Licenses | X25: Sensitive | Y25: Record Service Provider Code, Application ID, License Expiration Rule Code, License Expiry Date, Record Status, Insert Timestamp, Update Timestamp, Processing Run ID, Row Hash, Business Key Hash | Z25: {=_xlfn.TEXTJOIN(", ",TRUE,_xlfn.UNIQUE(_xlfn._xlws.FILTER('B1.3 Catalogue Attribute'!AJ:AJ,'B1.3 Catalogue Attribute'!L:L=A25,"")))} -> Record Service Provider Code, Application ID, License Expiration Rule Code, License Expiry Date, Record Status, Insert Timestamp, Update Timestamp, Processing Run ID, Row Hash, Business Key Hash | AA25: Y | AB25: Y | AC25: Oracle DB | AD25: =_xlfn.CONCAT("accelapr/",Table1[[#This Row],[Bronze Table]]) -> accelapr/B1_EXPIRATION | AE25: Table | AF25: Sprint 1
A26: DED_Data_Table_006 | C26: B3ADDRES | D26: Application_Address | E26: عنوان_الطلب | F26: Stores address information associated with applications, including building or house number, street name, area, city, postal code, and other location details. | G26: يحتوي على بيانات العناوين المرتبطة بالطلبات، بما في ذلك رقم المبنى أو المنزل واسم الشارع والمنطقة والمدينة والرمز البريدي وغيرها من تفاصيل الموقع | H26: bmalkindi@adra.gov.ae, rfmdaas@adra.gov.ae | I26: asalmehiry@adra.gov.ae, rfmdaas@adra.gov.ae | J26: Accela | K26: DED_Domain_01 | L26: Economic Licenses | M26: 46175 | N26: 46273 | O26: Y | V26: Weekly | W26: =Table1[[#This Row],[Domain Name]] -> Economic Licenses | X26: Confidential | Y26: Record Service Provider Code, Application ID, Application Address ID, Longitude, Y Coordinate, Record Status, Master Application Address ID, Insert Timestamp, Update Timestamp, Processing Run ID, Row Hash, Business Key Hash | Z26: {=_xlfn.TEXTJOIN(", ",TRUE,_xlfn.UNIQUE(_xlfn._xlws.FILTER('B1.3 Catalogue Attribute'!AJ:AJ,'B1.3 Catalogue Attribute'!L:L=A26,"")))} -> Record Service Provider Code, Application ID, Application Address ID, Longitude, Y Coordinate, Record Status, Master Application Address ID, Insert Timestamp, Update Timestamp, Processing Run ID, Row Hash, Business Key Hash | AA26: Y | AB26: Y | AC26: Oracle DB | AD26: =_xlfn.CONCAT("accelapr/",Table1[[#This Row],[Bronze Table]]) -> accelapr/B3ADDRES | AE26: Table | AF26: Sprint 1
A27: DED_Data_Table_007 | C27: B3ADDRES_DISTRICT | D27: Application_District | E27: منطقة_الطلب | F27: Stores district information associated with application addresses, including the district or geographic area linked to the application location. | G27: يحتوي على بيانات المنطقة المرتبطة بعنوان الطلب، بما في ذلك اسم المنطقة أو النطاق الجغرافي المرتبط بموقع الطلب. | H27: bmalkindi@adra.gov.ae, rfmdaas@adra.gov.ae | I27: asalmehiry@adra.gov.ae, rfmdaas@adra.gov.ae | J27: Accela | K27: DED_Domain_01 | L27: Economic Licenses | M27: 46175 | N27: 46273 | O27: Y | V27: Weekly | W27: =Table1[[#This Row],[Domain Name]] -> Economic Licenses | X27: Confidential | Y27: Record Service Provider Code, Application ID, Address ID, District ID, Record Status, Insert Timestamp, Update Timestamp, Processing Run ID, Row Hash, Business Key Hash | Z27: {=_xlfn.TEXTJOIN(", ",TRUE,_xlfn.UNIQUE(_xlfn._xlws.FILTER('B1.3 Catalogue Attribute'!AJ:AJ,'B1.3 Catalogue Attribute'!L:L=A27,"")))} -> Record Service Provider Code, Application ID, Address ID, District ID, Record Status, Insert Timestamp, Update Timestamp, Processing Run ID, Row Hash, Business Key Hash | AA27: Y | AB27: Y | AC27: Oracle DB | AD27: =_xlfn.CONCAT("accelapr/",Table1[[#This Row],[Bronze Table]]) -> accelapr/B3ADDRES_DISTRICT | AE27: Table | AF27: Sprint 1
A28: DED_Data_Table_008 | C28: B3CONTACT | D28: Investor | E28: المستثمر | F28: Stores investor-related information associated with applications, licenses, or business activities. | G28: يحتوي على بيانات المستثمرين المرتبطة بالطلبات أو التراخيص أو الأنشطة التجارية. | H28: bmalkindi@adra.gov.ae, rfmdaas@adra.gov.ae | I28: asalmehiry@adra.gov.ae, rfmdaas@adra.gov.ae | J28: Accela | K28: DED_Domain_01 | L28: Economic Licenses | M28: 46175 | N28: 46273 | O28: Y | V28: Weekly | W28: =Table1[[#This Row],[Domain Name]] -> Economic Licenses | X28: Confidential | Y28: Record Service Provider Code, Application ID, Party ID, Investor Contact Type, Name, Investor Business Name (Arabic), Investor Address Line 1, Name (En), Country Dialing Code, Mobile Phone, Alternative 1 Mobile Number, Fax Number, E-mail, Record Status, Investor Contact ID, Insert Timestamp, Update Timestamp, Processing Run ID, Row Hash, Business Key Hash | Z28: {=_xlfn.TEXTJOIN(", ",TRUE,_xlfn.UNIQUE(_xlfn._xlws.FILTER('B1.3 Catalogue Attribute'!AJ:AJ,'B1.3 Catalogue Attribute'!L:L=A28,"")))} -> Record Service Provider Code, Application ID, Party ID, Investor Contact Type, Name, Investor Business Name (Arabic), Investor Address Line 1, Name (En), Country Dialing Code, Mobile Phone, Alternative 1 Mobile Number, Fax Number, E-mail, Record Status, Investor Contact ID, Insert Timestamp, Update Timestamp, Processing Run ID, Row Hash, Business Key Hash | AA28: Y | AB28: Y | AC28: Oracle DB | AD28: =_xlfn.CONCAT("accelapr/",Table1[[#This Row],[Bronze Table]]) -> accelapr/B3CONTACT | AE28: Table | AF28: Sprint 1
A29: DED_Data_Table_009 | C29: B3CONTRA | D29: Company_Name | E29: اسم_الشركة | F29: Stores company names associated with applications, licenses, or business records. | G29: يحتوي على أسماء الشركات المرتبطة بالطلبات أو التراخيص أو السجلات التجارية | H29: bmalkindi@adra.gov.ae, rfmdaas@adra.gov.ae | I29: asalmehiry@adra.gov.ae, rfmdaas@adra.gov.ae | J29: Accela | K29: DED_Domain_01 | L29: Economic Licenses | M29: 46175 | N29: 46273 | O29: Y | V29: Weekly | W29: =Table1[[#This Row],[Domain Name]] -> Economic Licenses | X29: Confidential | Y29: Record Service Provider Code, Application ID, Economic License Number, Service Description, Licence Type, Business Name, Licence Sequence Number, Business Name (Arabic), Insert Timestamp, Update Timestamp, Processing Run ID, Row Hash, Business Key Hash | Z29: {=_xlfn.TEXTJOIN(", ",TRUE,_xlfn.UNIQUE(_xlfn._xlws.FILTER('B1.3 Catalogue Attribute'!AJ:AJ,'B1.3 Catalogue Attribute'!L:L=A29,"")))} -> Record Service Provider Code, Application ID, Economic License Number, Service Description, Licence Type, Business Name, Licence Sequence Number, Business Name (Arabic), Insert Timestamp, Update Timestamp, Processing Run ID, Row Hash, Business Key Hash | AA29: Y | AB29: Y | AC29: Oracle DB | AD29: =_xlfn.CONCAT("accelapr/",Table1[[#This Row],[Bronze Table]]) -> accelapr/B3CONTRA | AE29: Table | AF29: Sprint 1
A30: DED_Data_Table_010 | C30: B6CONDIT | D30: Requirement_Condition | E30: شرط_المتطلب | F30: Information of application conditions. The conditions include Lock, Hold, Notice and so on. | G30: يحتوي على بيانات شروط الطلبات، بما في ذلك شروط القفل والتعليق والتنبيه وغيرها من الشروط المرتبطة بالطلبات. | H30: bmalkindi@adra.gov.ae, rfmdaas@adra.gov.ae | I30: asalmehiry@adra.gov.ae, rfmdaas@adra.gov.ae | J30: Accela | K30: DED_Domain_01 | L30: Economic Licenses | M30: 46175 | N30: 46273 | O30: Y | V30: Weekly | W30: =Table1[[#This Row],[Domain Name]] -> Economic Licenses | X30: Confidential | Y30: Record Service Provider Code, Application ID, Condition ID, Condition Description, Condition Issued Date, Condition Status Date, Condition Status Code, Condition Type Description, Record Status, Inspection ID, Source Condition ID, Insert Timestamp, Update Timestamp, Processing Run ID, Row Hash, Business Key Hash | Z30: {=_xlfn.TEXTJOIN(", ",TRUE,_xlfn.UNIQUE(_xlfn._xlws.FILTER('B1.3 Catalogue Attribute'!AJ:AJ,'B1.3 Catalogue Attribute'!L:L=A30,"")))} -> Record Service Provider Code, Application ID, Condition ID, Condition Description, Condition Issued Date, Condition Status Date, Condition Status Code, Condition Type Description, Record Status, Inspection ID, Source Condition ID, Insert Timestamp, Update Timestamp, Processing Run ID, Row Hash, Business Key Hash | AA30: Y | AB30: Y | AC30: Oracle DB | AD30: =_xlfn.CONCAT("accelapr/",Table1[[#This Row],[Bronze Table]]) -> accelapr/B6CONDIT | AE30: Table | AF30: Sprint 1
A31: DED_Data_Table_011 | C31: B6CONDIT_DETAIL | D31: Requirement_Condition_Dtl | E31: تفاصيل_شرط_المتطلب | F31: Stores detailed information about requirements, conditions, restrictions, and notices associated with applications and licenses. | G31: يحتوي على معلومات تفصيلية حول المتطلبات والشروط والقيود والتنبيهات المرتبطة بالطلبات والتراخيص. | H31: bmalkindi@adra.gov.ae, rfmdaas@adra.gov.ae | I31: asalmehiry@adra.gov.ae, rfmdaas@adra.gov.ae | J31: Accela | K31: DED_Domain_01 | L31: Economic Licenses | M31: 46175 | N31: 46273 | O31: Y | V31: Weekly | W31: =Table1[[#This Row],[Domain Name]] -> Economic Licenses | X31: Confidential | Y31: Record Service Provider Code, Condition ID, Application ID, Record Status, Resource ID, Insert Timestamp, Update Timestamp, Processing Run ID, Row Hash, Business Key Hash | Z31: {=_xlfn.TEXTJOIN(", ",TRUE,_xlfn.UNIQUE(_xlfn._xlws.FILTER('B1.3 Catalogue Attribute'!AJ:AJ,'B1.3 Catalogue Attribute'!L:L=A31,"")))} -> Record Service Provider Code, Condition ID, Application ID, Record Status, Resource ID, Insert Timestamp, Update Timestamp, Processing Run ID, Row Hash, Business Key Hash | AA31: Y | AB31: Y | AC31: Oracle DB | AD31: =_xlfn.CONCAT("accelapr/",Table1[[#This Row],[Bronze Table]]) -> accelapr/B6CONDIT_DETAIL | AE31: Table | AF31: Sprint 1
A32: DED_Data_Table_012 | C32: B6CONDIT_DETAIL_I18N | D32: Requirement_Condition_Dtl_Language | E32: لغات_تفاصيل_شرط_المتطلب | F32: Stores multilingual details and descriptions of requirement conditions associated with applications. | G32: يحتوي على تفاصيل وأوصاف شروط المتطلبات المرتبطة بالطلبات بمختلف اللغات المعتمدة في النظام. | H32: bmalkindi@adra.gov.ae, rfmdaas@adra.gov.ae | I32: asalmehiry@adra.gov.ae, rfmdaas@adra.gov.ae | J32: Accela | K32: DED_Domain_01 | L32: Economic Licenses | M32: 46175 | N32: 46273 | O32: Y | V32: Weekly | W32: =Table1[[#This Row],[Domain Name]] -> Economic Licenses | X32: Confidential | Y32: Record Service Provider Code, Resource ID, Language ID, Condition Resolution Action, Record Status, Insert Timestamp, Update Timestamp, Processing Run ID, Row Hash, Business Key Hash | Z32: {=_xlfn.TEXTJOIN(", ",TRUE,_xlfn.UNIQUE(_xlfn._xlws.FILTER('B1.3 Catalogue Attribute'!AJ:AJ,'B1.3 Catalogue Attribute'!L:L=A32,"")))} -> Record Service Provider Code, Resource ID, Language ID, Condition Resolution Action, Record Status, Insert Timestamp, Update Timestamp, Processing Run ID, Row Hash, Business Key Hash | AA32: Y | AB32: Y | AC32: Oracle DB | AD32: =_xlfn.CONCAT("accelapr/",Table1[[#This Row],[Bronze Table]]) -> accelapr/B6CONDIT_DETAIL_I18N | AE32: Table | AF32: Sprint 1
A33: DED_Data_Table_013 | C33: B6CONDIT_HISTORY | D33: Requirement_Condition_History | E33: سجل_شرط_المتطلب | F33: Information of record application condition history. | G33: يحتوي على السجل التاريخي للتغييرات التي تطرأ على شروط الطلبات والمتطلبات المرتبطة بها. | H33: bmalkindi@adra.gov.ae, rfmdaas@adra.gov.ae | I33: asalmehiry@adra.gov.ae, rfmdaas@adra.gov.ae | J33: Accela | K33: DED_Domain_01 | L33: Economic Licenses | M33: 46175 | N33: 46273 | O33: Y | V33: Weekly | W33: =Table1[[#This Row],[Domain Name]] -> Economic Licenses | X33: Confidential | Y33: Record Service Provider Code, Application Condition ID, Condition History ID, Condition History Description, Condition History Issued Date, Condition History Status Date, Condition History Status Code, Condition Type Description, Condition History Manipulation Date, Condition ID, Inspection ID, Language ID, Insert Timestamp, Update Timestamp, Processing Run ID, Row Hash, Business Key Hash | Z33: {=_xlfn.TEXTJOIN(", ",TRUE,_xlfn.UNIQUE(_xlfn._xlws.FILTER('B1.3 Catalogue Attribute'!AJ:AJ,'B1.3 Catalogue Attribute'!L:L=A33,"")))} -> Record Service Provider Code, Application Condition ID, Condition History ID, Condition History Description, Condition History Issued Date, Condition History Status Date, Condition History Status Code, Condition Type Description, Condition History Manipulation Date, Condition ID, Inspection ID, Language ID, Insert Timestamp, Update Timestamp, Processing Run ID, Row Hash, Business Key Hash | AA33: Y | AB33: Y | AC33: Oracle DB | AD33: =_xlfn.CONCAT("accelapr/",Table1[[#This Row],[Bronze Table]]) -> accelapr/B6CONDIT_HISTORY | AE33: Table | AF33: Sprint 1
... A79: DED_Data_Table_086 | C79: VIRTUAL_OFFICIAL_INFORMATION_L | D79: Official_Information_Logs | E79: سجلات_المعلومات_الرسمية | F79: Stores the change history of official information, including old and new values. | G79: يحتوي على معلومات العناية الواجبة ومؤشرات التحقق والفحص الخاصة بالأشخاص المعرضين سياسياً. | H79: bmalkindi@adra.gov.ae, rfmdaas@adra.gov.ae | I79: asalmehiry@adra.gov.ae, rfmdaas@adra.gov.ae | J79: Accela | K79: DED_Domain_01 | L79: Economic Licenses | M79: 46175 | N79: 46273 | O79: Y | V79: Weekly | W79: =Table1[[#This Row],[Domain Name]] -> Economic Licenses | X79: Sensitive | Y79: Record Service Provider Code, Application ID, Record Group, Change Type, Changed By, Change Date, New Value, Old Value, System Record Date, Record Status, Row Index, Insert Timestamp, Update Timestamp, Business Key Hash, Row Hash, Processing Run ID | Z79: {=_xlfn.TEXTJOIN(", ",TRUE,_xlfn.UNIQUE(_xlfn._xlws.FILTER('B1.3 Catalogue Attribute'!AJ:AJ,'B1.3 Catalogue Attribute'!L:L=A79,"")))} -> Record Service Provider Code, Application ID, Record Group, Change Type, Changed By, Change Date, New Value, Old Value, System Record Date, Record Status, Row Index, Insert Timestamp, Update Timestamp, Business Key Hash, Row Hash, Processing Run ID | AA79: Y | AB79: N | AC79: Oracle DB | AD79: =_xlfn.CONCAT("accelapr/",Table1[[#This Row],[Bronze Table]]) -> accelapr/VIRTUAL_OFFICIAL_INFORMATION_L | AE79: Table | AF79: Sprint 2
