Workbook

Sheet S1
A1: DQO | B1: Rule_Title_B | C1: Purview_B | D1: Rule_Title_S | E1: Purview_S | F1: Dimension | G1: Attribute_ID | H1: Attribute_Name | I1: Asset_ID | J1: Asset_Name_B | K1: Asset_Name_S | L1: Sprint | M1: Silver Active Flag
A2: DQO-475 | B2: Completeness_Ck-Virt_Umbrella-QUANT_OF_UMBRELLAS | C2: aa58b431-1fea-459d-83b3-98de26426fd0 | D2: Completeness_Ck-Permit_Umbrella-QUANT_OF_UMBRELLAS | E2: b5b2e534-8e1e-4619-83cb-b88c11a18c92 | F2: 0 | G2: DED_Attribute_1435 | H2: quantity_of_umbrellas | I2: DED_Data_Table_106 | J2: VIRTUAL_UMBRELLA | K2: permit_umbrella | L2: 1 | M2: =VLOOKUP(E2,'Sprint 1 Silver Dump'!$B$2:$K$602,10,0) -> Active
A3: DQO-476 | B3: DatTypMatch_Ck-Virtual_Umbrella-QUANT_OF_UMBRELLAS | C3: aad26c8e-2f64-4928-927a-9f6e1de6a702 | D3: DatTypMatch_Ck-Permit_Umbrella-QUANT_OF_UMBRELLAS | E3: 7f57727a-c000-442f-ad2e-fe17f21aa1bf | F3: 0 | G3: DED_Attribute_1435 | H3: quantity_of_umbrellas | I3: DED_Data_Table_106 | J3: VIRTUAL_UMBRELLA | K3: permit_umbrella | L3: 1 | M3: =VLOOKUP(E3,'Sprint 1 Silver Dump'!$B$2:$K$602,10,0) -> Active
A4: DQO-477 | B4: NumVal_Check-Virtual_Umbrella-QUANT_OF_UMBRELLAS | C4: e6a87e09-d426-4034-afd1-dd3ca15a2681 | D4: NumVal_Check-Permit_Umbrella-QUANT_OF_UMBRELLAS | E4: 0a171573-74e2-445a-8a23-7f44a3d9f3e1 | F4: Conformity | G4: N/A | H4: quantity_of_umbrellas,rec_status | I4: DED_Data_Table_106 | J4: VIRTUAL_UMBRELLA | K4: permit_umbrella | L4: 1 | M4: =VLOOKUP(E4,'Sprint 1 Silver Dump'!$B$2:$K$602,10,0) -> Active
A5: DQO-478 | B5: Timeliness-Virtual_Umbrella | C5: 76b26652-9b1b-4271-9027-2c4064bd5158 | D5: Timeliness_metadata_gap-PU-UMBRELLA_TYPE | E5: f1af842f-fde8-4ba6-b542-07b5b94f8d3b | F5: Timeliness | G5: N/A | H5: 0 | I5: DED_Data_Table_106 | J5: VIRTUAL_UMBRELLA | K5: permit_umbrella | L5: 1 | M5: =VLOOKUP(E5,'Sprint 1 Silver Dump'!$B$2:$K$602,10,0) -> Active
A6: DQO-479 | B6: Uniqueness_Check-Virtual_Umbrella | C6: c0bc4247-36f7-4a85-9702-0ecd872d1f7e | D6: Uniqueness_Check-Permit_Umbrella | E6: 5f6a172a-0471-4ab8-9ea5-571a86e85df5 | F6: Accuracy | G6: N/A | H6: b1_per_id1,b1_per_id2,b1_per_id3,serv_prov_code,row_index | I6: DED_Data_Table_106 | J6: VIRTUAL_UMBRELLA | K6: permit_umbrella | L6: 1 | M6: =VLOOKUP(E6,'Sprint 1 Silver Dump'!$B$2:$K$602,10,0) -> Active
A7: DQO-030 | B7: Completeness_Check-Virtu_Machines-machine_address | C7: 9db2ff9c-094c-45fe-8a79-86f1a200952d | D7: Completeness_Check-IDB_Machines-machine_address | E7: 4e475072-52d3-4977-87cd-de8fa8eadbb4 | F7: 0 | G7: DED_Attribute_0939 | H7: machine_address | I7: DED_Data_Table_078 | J7: VIRTUAL_MACHINES | K7: idb_machines | L7: 1 | M7: =VLOOKUP(E7,'Sprint 1 Silver Dump'!$B$2:$K$602,10,0) -> Active
A8: DQO-029 | B8: Lead_Trail_Space_Chk-Virt_Machines-MACHINE_ADDRESS | C8: d47a7e03-9736-4dcd-bef2-97d1e3ce0238 | D8: Lead_Trail_Space_Chk-IDB_Machines-MACHINE_ADDRESS | E8: 9fb55f94-911e-4970-ab9f-4ce236c49eb0 | F8: Conformity | G8: N/A | H8: machine_address,rec_status | I8: DED_Data_Table_078 | J8: VIRTUAL_MACHINES | K8: idb_machines | L8: 1 | M8: =VLOOKUP(E8,'Sprint 1 Silver Dump'!$B$2:$K$602,10,0) -> Active
A9: DQO-028 | B9: Cons_Space_Check-Virt_Machines-MACHINE_ADDRESS | C9: ec068720-d9f5-41ed-b79a-deff906674f6 | D9: Cons_Space_Check-IDB_Machines-MACHINE_ADDRESS | E9: 393046a9-4809-4174-b69d-031d58a7872c | F9: Conformity | G9: N/A | H9: machine_address,rec_status | I9: DED_Data_Table_078 | J9: VIRTUAL_MACHINES | K9: idb_machines | L9: 1 | M9: =VLOOKUP(E9,'Sprint 1 Silver Dump'!$B$2:$K$602,10,0) -> Active
A10: DQO-027 | B10: Timeliness_Check-Virtual_Machines | C10: 8bf8d252-d4e0-422c-8e1c-85186ad1f00a | D10: Timeliness_Check-IDB_Machines | E10: a28955c5-8af2-4b4c-a764-5b24deb2cc78 | F10: 0 | G10: N/A | H10: 0 | I10: DED_Data_Table_078 | J10: VIRTUAL_MACHINES | K10: idb_machines | L10: 1 | M10: =VLOOKUP(E10,'Sprint 1 Silver Dump'!$B$2:$K$602,10,0) -> Active
A11: DQO-026 | B11: Uniqueness_Check-Virtual_Machines | C11: aae13618-05aa-44f6-ace5-66eb18fcc255 | D11: Uniqueness_Check-IDB_Machines | E11: 5dbf1e98-ca3c-424c-a6b0-a0a01bfeb857 | F11: Accuracy | G11: N/A | H11: b1_per_id1,b1_per_id2,b1_per_id3,serv_prov_code,row_index | I11: DED_Data_Table_078 | J11: VIRTUAL_MACHINES | K11: idb_machines | L11: 1 | M11: =VLOOKUP(E11,'Sprint 1 Silver Dump'!$B$2:$K$602,10,0) -> Active
A12: DQO-9022 | B12: N/A | C12: N/A | D12: Consec_Chk-IDB_Machines-machine_type | E12: e5d85e67-9b3f-4ac9-904e-995aa9714e23 | F12: Conformity | G12: N/A | H12: machine_type,rec_status | I12: DED_Data_Table_078 | J12: VIRTUAL_MACHINES | K12: idb_machines | L12: 1 | M12: =VLOOKUP(E12,'Sprint 1 Silver Dump'!$B$2:$K$602,10,0) -> Active
A13: DQO-063 | B13: Completeness_Check-Virt_ISIC_4_ACT-activity_id | C13: 18eb9cfc-5cd6-48f6-8353-7e4b50b028ba | D13: Completeness_Check-Instant_Activities-activity_id | E13: f18f671c-ee78-4ac4-b72d-a941d1736576 | F13: 0 | G13: DED_Attribute_0907 | H13: activity_id | I13: DED_Data_Table_075 | J13: VIRTUAL_ISIC_4_ACTIVITIES | K13: instant_activities | L13: 1 | M13: =VLOOKUP(E13,'Sprint 1 Silver Dump'!$B$2:$K$602,10,0) -> Active
A14: DQO-064 | B14: Cons_Space_Check-Virt_ISIC_4_ACT-ACTIVITY_ID | C14: e6b42f20-30c9-4dd6-945a-dbb4c51bee16 | D14: Cons_Space_Check-Instant_Activities-ACTIVITY_ID | E14: 8edebd26-7894-49c8-b9a5-3b3b906cfb3a | F14: Conformity | G14: N/A | H14: activity_id,rec_status | I14: DED_Data_Table_075 | J14: VIRTUAL_ISIC_4_ACTIVITIES | K14: instant_activities | L14: 1 | M14: =VLOOKUP(E14,'Sprint 1 Silver Dump'!$B$2:$K$602,10,0) -> Active
A15: DQO-065 | B15: Lead_Trail_Spc_Chk-Virt_ISIC_4_ACT-ACTIVITY_ID | C15: 8b7cb4e9-82bf-4288-841a-067909186164 | D15: Lead_Trail_Spc_Chk-Instant_Activities-ACTIVITY_ID | E15: 0bbc88d9-5221-41b2-8450-8c6a5f6c3da8 | F15: Conformity | G15: N/A | H15: activity_id,rec_status | I15: DED_Data_Table_075 | J15: VIRTUAL_ISIC_4_ACTIVITIES | K15: instant_activities | L15: 1 | M15: =VLOOKUP(E15,'Sprint 1 Silver Dump'!$B$2:$K$602,10,0) -> Active
A16: DQO-066 | B16: Num_Format_Check-Virt_ISIC_4_ACT-ACTIVITY_ID | C16: c8385d7c-dcf8-44be-a414-7de6d95a47f8 | D16: Num_Format_Check-Instant_Activities-ACTIVITY_ID | E16: 045bdaf7-d766-4d98-a1ee-a0a057fd75c4 | F16: Conformity | G16: N/A | H16: activity_id,rec_status | I16: DED_Data_Table_075 | J16: VIRTUAL_ISIC_4_ACTIVITIES | K16: instant_activities | L16: 1 | M16: =VLOOKUP(E16,'Sprint 1 Silver Dump'!$B$2:$K$602,10,0) -> Active
A17: NA | B17: N/A | C17: N/A | D17: Completeness_Check-IA-ACTIVITY_NAME_AR | E17: ccbe48c0-a4db-4a19-8500-1b23f59b84fb | F17: 0 | G17: DED_Attribute_0908 | H17: activity_name_ar | I17: DED_Data_Table_075 | J17: VIRTUAL_ISIC_4_ACTIVITIES | K17: instant_activities | L17: 1 | M17: =VLOOKUP(E17,'Sprint 1 Silver Dump'!$B$2:$K$602,10,0) -> Active
A18: DQO-067 | B18: Lead_Trail_Spc_Chk-Virt_ISIC_4_ACT-ACTIVIT_NAME_AR | C18: 725df9ee-bf43-4ee1-9f3c-b41fa0519154 | D18: Lead_Trail_Spc_Chk-Instant_Act-ACTIVITY_NAME_AR | E18: 149d84a5-4128-455b-8a0e-784caded066f | F18: Conformity | G18: N/A | H18: activity_name_ar,rec_status | I18: DED_Data_Table_075 | J18: VIRTUAL_ISIC_4_ACTIVITIES | K18: instant_activities | L18: 1 | M18: =VLOOKUP(E18,'Sprint 1 Silver Dump'!$B$2:$K$602,10,0) -> Active
A19: DQO-068 | B19: Cons_Space_Chk-Virt_ISIC_4_ACT-ACTIVITY_NAME_AR | C19: 66fe371b-5f8d-4a71-8ac6-0c6624c8e6f0 | D19: Cons_Space_Chk-Instant_Activities-ACTIVITY_NAME_AR | E19: d9f00547-454d-458a-bcad-873cf5d91871 | F19: Conformity | G19: N/A | H19: activity_name_ar,rec_status | I19: DED_Data_Table_075 | J19: VIRTUAL_ISIC_4_ACTIVITIES | K19: instant_activities | L19: 1 | M19: =VLOOKUP(E19,'Sprint 1 Silver Dump'!$B$2:$K$602,10,0) -> Active
A20: DQO-069 | B20: Str_Format_Chk-Virt_ISIC_4_ACT-activity_name_ar | C20: 8ad9d3f0-38a8-4f02-93d1-89107430304a | D20: Str_Format_Chk-Instant_Activities_activity_name_ar | E20: dae4044a-1031-49c2-a9b8-4d21f3482e8b | F20: Conformity | G20: DED_Attribute_0908 | H20: activity_name_ar | I20: DED_Data_Table_075 | J20: VIRTUAL_ISIC_4_ACTIVITIES | K20: instant_activities | L20: 1 | M20: =VLOOKUP(E20,'Sprint 1 Silver Dump'!$B$2:$K$602,10,0) -> Active
A21: DQO-070 | B21: Comp_Check-Virt_ISIC_4_ACT-activity_name_en | C21: 63805840-ddeb-4321-8200-4f0d18308071 | D21: Comp_Check-Instant_Activities-activity_name_en | E21: a6ef914f-2dff-4aa9-8c64-bfff4db6b8e4 | F21: 0 | G21: DED_Attribute_0909 | H21: activity_name_en | I21: DED_Data_Table_075 | J21: VIRTUAL_ISIC_4_ACTIVITIES | K21: instant_activities | L21: 1 | M21: =VLOOKUP(E21,'Sprint 1 Silver Dump'!$B$2:$K$602,10,0) -> Active
A22: DQO-062 | B22: Lead_Trail_Spc_Chk-Virt_ISIC_4_ACT-ACTIVIT_NAME_EN | C22: 28da1e7e-b67a-469d-81bb-4a574c19c1b5 | D22: Lead_Trail_Spc_Chk-Instant_Act-ACTIVITY_NAME_EN | E22: 4b9ad871-0c4d-4dbf-af34-230ce87145f0 | F22: Conformity | G22: N/A | H22: activity_name_en,rec_status | I22: DED_Data_Table_075 | J22: VIRTUAL_ISIC_4_ACTIVITIES | K22: instant_activities | L22: 1 | M22: =VLOOKUP(E22,'Sprint 1 Silver Dump'!$B$2:$K$602,10,0) -> Active
A23: DQO-061 | B23: Cons_Space_Check-Virt_ISIC_4_ACT-ACTIVITY_NAME_EN | C23: cef4a39f-3ebf-41f2-9566-5a0b680da4bb | D23: Cons_Space_Check-Instant_Act-ACTIVITY_NAME_EN | E23: 35216e45-be3d-4731-9bf3-0f9db269963b | F23: Conformity | G23: N/A | H23: activity_name_en,rec_status | I23: DED_Data_Table_075 | J23: VIRTUAL_ISIC_4_ACTIVITIES | K23: instant_activities | L23: 1 | M23: =VLOOKUP(E23,'Sprint 1 Silver Dump'!$B$2:$K$602,10,0) -> Active
A24: DQO-060 | B24: Str_Format_Chk-Virt_ISIC_4_ACT-activity_name_en | C24: edb58996-518d-42e2-bc67-ccd0a1514f46 | D24: Str_Format_Chk-Instant_Activities_activity_name_en | E24: b1b92031-c41a-4d7b-9919-47018eb778a9 | F24: Conformity | G24: DED_Attribute_0909 | H24: activity_name_en | I24: DED_Data_Table_075 | J24: VIRTUAL_ISIC_4_ACTIVITIES | K24: instant_activities | L24: 1 | M24: =VLOOKUP(E24,'Sprint 1 Silver Dump'!$B$2:$K$602,10,0) -> Active
A25: DQO-059 | B25: Timeliness_Check-Virtual_ISIC_4_Activities | C25: 3e5e18d4-0706-4afc-848f-a73b5eda21e3 | D25: Timeliness_Check-Instant_Activities | E25: ea183c70-3465-45e4-9e30-8b8d394aa1e4 | F25: 0 | G25: N/A | H25: 0 | I25: DED_Data_Table_075 | J25: VIRTUAL_ISIC_4_ACTIVITIES | K25: instant_activities | L25: 1 | M25: =VLOOKUP(E25,'Sprint 1 Silver Dump'!$B$2:$K$602,10,0) -> Active
A26: DQO-058 | B26: Uniqueness_Check-Virtual_ISIC_4_Activities | C26: aae16bfc-74f7-4968-b7c9-294cdb71421c | D26: Uniqueness_Check-Instant_Activities | E26: c933d847-699c-4207-91f0-07354a972d71 | F26: Accuracy | G26: N/A | H26: activity_id,b1_per_id1,b1_per_id2,b1_per_id3,serv_prov_code,row_index | I26: DED_Data_Table_075 | J26: VIRTUAL_ISIC_4_ACTIVITIES | K26: instant_activities | L26: 1 | M26: =VLOOKUP(E26,'Sprint 1 Silver Dump'!$B$2:$K$602,10,0) -> Active
A27: DQO-071 | B27: Accuracy_Chk-VIRTUAL_ISIC_4_ACTIVITIES-activity_id | C27: 1dd68e1e-5e6a-4b16-87e3-1187aaa92f8a | D27: Accuracy_Chk-Instant_Activities-activity_id | E27: 249e7ebc-3057-427c-9ca1-09336187d281 | F27: 0 | G27: DED_Attribute_0907 | H27: activity_id | I27: DED_Data_Table_075 | J27: VIRTUAL_ISIC_4_ACTIVITIES | K27: instant_activities | L27: 1 | M27: =VLOOKUP(E27,'Sprint 1 Silver Dump'!$B$2:$K$602,10,0) -> Active
A28: DQO-466 | B28: Completeness_check-Virtual_Kiosk-KIOSK_ADDRESS | C28: a826b711-1386-4e3e-8df6-6a2fea9ec5c1 | D28: Completeness_check-Permit_Kiosk-KIOSK_ADDRESS | E28: 5c0cf737-071c-4025-9549-9ff85e123c70 | F28: 0 | G28: DED_Attribute_0919 | H28: kiosk_address | I28: DED_Data_Table_076 | J28: VIRTUAL_KIOSK | K28: permit_kiosk | L28: 1 | M28: =VLOOKUP(E28,'Sprint 1 Silver Dump'!$B$2:$K$602,10,0) -> Active
A29: DQO-467 | B29: Timeliness_Check-Virtual_Kiosk | C29: 179ab191-0115-4bfe-a76d-97c4c4f4e545 | D29: Timeliness_metadata_gap-Permit_Kiosk-KIOSK_ADDRESS | E29: e87e0e8a-0361-48fd-b4cd-3c52f6c942fb | F29: Timeliness | G29: N/A | H29: 0 | I29: DED_Data_Table_076 | J29: VIRTUAL_KIOSK | K29: permit_kiosk | L29: 1 | M29: =VLOOKUP(E29,'Sprint 1 Silver Dump'!$B$2:$K$602,10,0) -> Active
A30: DQO-468 | B30: Uniqueness_Check-Virtual_Kiosk | C30: 3caecea8-dd91-4568-8ccb-3c00f4d00042 | D30: Duplicate_rows_Permit_Kiosk | E30: 4d3ee107-3204-4a48-8b13-99f5eeab6a30 | F30: Accuracy | G30: N/A | H30: b1_per_id1,b1_per_id2,b1_per_id3,serv_prov_code,row_index | I30: DED_Data_Table_076 | J30: VIRTUAL_KIOSK | K30: permit_kiosk | L30: 1 | M30: =VLOOKUP(E30,'Sprint 1 Silver Dump'!$B$2:$K$602,10,0) -> Active
A31: DQO-9026 | B31: N/A | C31: N/A | D31: Consec_Chk-Permit_Kiosk-kiosk_address | E31: 290497c3-bf36-4808-a3fb-f6588eed8073 | F31: Conformity | G31: N/A | H31: kiosk_address,rec_status | I31: DED_Data_Table_076 | J31: VIRTUAL_KIOSK | K31: permit_kiosk | L31: 1 | M31: =VLOOKUP(E31,'Sprint 1 Silver Dump'!$B$2:$K$602,10,0) -> Active
A32: DQO-048 | B32: String_check-Virt_Exempt_Change_Log-CHANGE_TYPE | C32: c49792b8-f9dc-46e1-b5b6-1837c156998d | D32: String_check-Exemption_Change_Log-CHANGE_TYPE | E32: 5252f406-f0c2-4f7a-be7e-18f4cd8add74 | F32: Conformity | G32: DED_Attribute_0833 | H32: change_type | I32: DED_Data_Table_070 | J32: VIRTUAL_EXEMPTION_CHANGE_LOG | K32: exemption_change_log | L32: 1 | M32: =VLOOKUP(E32,'Sprint 1 Silver Dump'!$B$2:$K$602,10,0) -> Active
A33: DQO-049 | B33: Completeness_chck-Virt_Exempt_Change_Log-USER_NAME | C33: 41d2a319-e29d-413c-bfd5-a951118602f5 | D33: Completeness_check-Exemption_Change_Log-USER_NAME | E33: d7b003ba-a8bc-4aee-94e7-a62a2b2335cb | F33: 0 | G33: DED_Attribute_0835 | H33: user_name | I33: DED_Data_Table_070 | J33: VIRTUAL_EXEMPTION_CHANGE_LOG | K33: exemption_change_log | L33: 1 | M33: =VLOOKUP(E33,'Sprint 1 Silver Dump'!$B$2:$K$602,10,0) -> Active
A34: DQO-050 | B34: String_check-Virt_Exempt_Change_Log-USER_NAME | C34: 79ee3154-1c3e-4730-ba05-115aab7f9e58 | D34: String_check-Exemption_Change_Log-USER_NAME | E34: 3529144f-1712-4e48-a50e-9a96493ef812 | F34: 0 | G34: DED_Attribute_0835 | H34: user_name | I34: DED_Data_Table_070 | J34: VIRTUAL_EXEMPTION_CHANGE_LOG | K34: exemption_change_log | L34: 1 | M34: =VLOOKUP(E34,'Sprint 1 Silver Dump'!$B$2:$K$602,10,0) -> Active
A35: DQO-051 | B35: Timeliness_Check-Virtual_Exempt_Change_Log | C35: 13a36151-f147-4b3a-a1d6-2841813d67a4 | D35: Timeliness_Check-Exemption_Change_Log | E35: 8d8c2e4e-3d62-4309-bf09-89f39b3761fe | F35: 0 | G35: N/A | H35: 0 | I35: DED_Data_Table_070 | J35: VIRTUAL_EXEMPTION_CHANGE_LOG | K35: exemption_change_log | L35: 1 | M35: =VLOOKUP(E35,'Sprint 1 Silver Dump'!$B$2:$K$602,10,0) -> Active
A36: DQO-052 | B36: Uniqueness_Check-Virtual_Exemption_Change_Log | C36: 609bf82a-466b-4081-9c3d-ae29d5933588 | D36: Uniqueness_Check-Exemption_Change_Log | E36: 2c730e89-72d2-4e55-a078-fa34ad27614c | F36: Accuracy | G36: N/A | H36: b1_per_id1,b1_per_id2,b1_per_id3,serv_prov_code,row_index | I36: DED_Data_Table_070 | J36: VIRTUAL_EXEMPTION_CHANGE_LOG | K36: exemption_change_log | L36: 1 | M36: =VLOOKUP(E36,'Sprint 1 Silver Dump'!$B$2:$K$602,10,0) -> Active
A37: DQO-9008 | B37: N/A | C37: N/A | D37: Completeness_Chk-Exemption_Change_Log-change_type | E37: cc832c8f-8d2b-4df7-9361-659e67ac6450 | F37: 0 | G37: DED_Attribute_0833 | H37: change_type | I37: DED_Data_Table_070 | J37: VIRTUAL_EXEMPTION_CHANGE_LOG | K37: exemption_change_log | L37: 1 | M37: =VLOOKUP(E37,'Sprint 1 Silver Dump'!$B$2:$K$602,10,0) -> Active
A38: DQO-106 | B38: Completeness_Check-R3APPTYP_I18N-r1_per_grp | C38: 49c6998d-9c83-4d52-a60d-acec71505548 | D38: Comp_Chk-applctn_Config_Language-R1_PER_GROUP | E38: 3d05cdc2-72aa-4489-a2cb-4c1b3880bf6c | F38: 0 | G38: DED_Attribute_0397 | H38: r1_per_group | I38: DED_Data_Table_038 | J38: R3APPTYP_I18N | K38: application_configuration_language | L38: 1 | M38: =VLOOKUP(E38,'Sprint 1 Silver Dump'!$B$2:$K$602,10,0) -> Active
A39: DQO-107 | B39: Comp_Chk-r3apptyp_i18n-R1_PER_SUB_TYPE | C39: f3aa7426-9d58-4f4d-9f4d-d128da75243c | D39: Comp_Chk-applctn_Config_Language-R1_PER_SUB_TYPE | E39: 7a4f724b-182c-40f6-b943-0d1e4dd93217 | F39: 0 | G39: DED_Attribute_0398 | H39: r1_per_sub_type | I39: DED_Data_Table_038 | J39: R3APPTYP_I18N | K39: application_configuration_language | L39: 1 | M39: =VLOOKUP(E39,'Sprint 1 Silver Dump'!$B$2:$K$602,10,0) -> Active
A40: DQO-108 | B40: Comp_Chk-r3apptype_i18n-R1_PER_CATEGORY | C40: e2c29501-d17d-4cf9-b0b5-5f606b6e5871 | D40: Comp_Chk-applctn_Config_Language-R1_PER_CATEGORY | E40: 5e727671-7fe9-48d7-bdc0-ad0b67acdbc1 | F40: 0 | G40: DED_Attribute_0399 | H40: r1_per_category | I40: DED_Data_Table_038 | J40: R3APPTYP_I18N | K40: application_configuration_language | L40: 1 | M40: =VLOOKUP(E40,'Sprint 1 Silver Dump'!$B$2:$K$602,10,0) -> Active
...

Sheet S2
A1: DQO | B1: Rule_Title_B | C1: Purview_B | D1: Rule_Title_S | E1: Purview_S | F1: Dimension | G1: Attribute_ID | H1: Attribute_Name_From-Rule_Book | I1: Attribute_Name from file | J1: Asset_ID | K1: Asset_Name_B | L1: Asset_Name_S | M1: Sprint
A2: DQO-1060 | B2: Compl_Chk-V_BUSINESS_INTERESTS_OF_-source_of_pep | C2: 875b0bba-fcc6-4c39-9cc4-20103fd16258 | D2: Compl_Chk-RB_Business_Interests-source_of_pep | E2: cf9d3b0b-3b73-4c45-bc4e-7c312acad10b | F2: Completeness | G2: DED_Attribute_0726 | H2: source_of_pep | I2: source_of_pep,rec_status | J2: DED_Data_Table_063 | K2: VIRTUAL_BUSINESS_INTERESTS_OF_ | L2: rb_business_interests | M2: 2
A3: DQO-1146 | B3: Freshness_Chk-VIRTUAL_BUSINESS_INTERESTS_OF_ | C3: 6e665073-5207-47a9-a6aa-add03dff3f56 | D3: Freshness_Chk-RB_Business_Interests | E3: ed92f2a1-15ca-4d40-bab4-c6a74afcccd8 | F3: Timeliness | G3: N/A | H3: NA - Table level rule | I3: 0 | J3: DED_Data_Table_063 | K3: VIRTUAL_BUSINESS_INTERESTS_OF_ | L3: rb_business_interests | M3: 2
A4: DQO-1165 | B4: Uniqueness_Chk-VIRTUAL_BUSINESS_INTERESTS_OF_ | C4: 22bb90f7-81cb-4df5-a10d-76d8c6dd029d | D4: Uniqueness_Chk-RB_Business_Interests | E4: 367d5f9a-8e65-409e-a9df-772d98c0b427 | F4: Uniqueness | G4: N/A | H4: SERV_PROV_CODE, B1_PER_ID1, B1_PER_ID2, B1_PER_ID3, SYSTEM_ID | I4: serv_prov_code,b1_per_id1,b1_per_id2,b1_per_id3,system_id | J4: DED_Data_Table_063 | K4: VIRTUAL_BUSINESS_INTERESTS_OF_ | L4: rb_business_interests | M4: 2
A5: DQO-1249 | B5: Compl_Chk-V_BUSINESS_INTERESTS_OF_-date_of_join | C5: b739b54b-3c04-4a3c-8d32-42be6de9324d | D5: Compl_Chk-RB_Business_Interests-date_of_join | E5: 8c69c053-97e3-4736-ad30-a61a3c59c091 | F5: Completeness | G5: DED_Attribute_0720 | H5: date_of_join | I5: date_of_join,rec_status | J5: DED_Data_Table_063 | K5: VIRTUAL_BUSINESS_INTERESTS_OF_ | L5: rb_business_interests | M5: 2
A6: DQO-1526 | B6: Compl_Chk-V_BUSINESS_INTERESTS_OF_-entity_name | C6: 26596ec6-2fe0-48fd-82c1-ef9858ae5bcf | D6: Compl_Chk-RB_Business_Interests-entity_name | E6: f5736ffc-38c6-417e-893a-0ec6ff76f39c | F6: Completeness | G6: DED_Attribute_0721 | H6: entity_name | I6: entity_name,rec_status | J6: DED_Data_Table_063 | K6: VIRTUAL_BUSINESS_INTERESTS_OF_ | L6: rb_business_interests | M6: 2
A7: DQO-1527 | B7: Compl_Chk-V_BUSINESS_INT_OF_-share_percentage | C7: 5eebc957-4459-4f8b-a61c-7b7bb224f249 | D7: Compl_Chk-RB_Business_Interests-share_percentage | E7: e0cac0d1-39bb-4582-91f9-a38bda429e38 | F7: Completeness | G7: DED_Attribute_0724 | H7: share_percentage | I7: share_percentage,rec_status | J7: DED_Data_Table_063 | K7: VIRTUAL_BUSINESS_INTERESTS_OF_ | L7: rb_business_interests | M7: 2
A8: DQO-1528 | B8: Compl_Chk-VIRTUAL_BUSINESS_INTERESTS_OF_-status | C8: cfa04b82-287e-43e6-a029-12fa6bf9df2b | D8: Compl_Chk-RB_Business_Interests-status | E8: c1167a19-1e87-44e5-b7de-40b8b674f691 | F8: Completeness | G8: DED_Attribute_0727 | H8: status | I8: status,rec_status | J8: DED_Data_Table_063 | K8: VIRTUAL_BUSINESS_INTERESTS_OF_ | L8: rb_business_interests | M8: 2
A9: DQO-2345 | B9: EntityDep-RB_Business_Interests-share_percentage | C9: 65ef2327-e9d4-4def-98d7-67b79c8b6353 | D9: EntityDep-RB_Business_Interests-share_percentage | E9: 83abbb1d-98f4-4885-a57e-1fcecee8d5bd | F9: Consistency | G9: DED_Attribute_0724 | H9: share_percentage | I9: share_percentage,entity_name,rec_status | J9: DED_Data_Table_063 | K9: VIRTUAL_BUSINESS_INTERESTS_OF_ | L9: rb_business_interests | M9: 2
A10: DQO-2346 | B10: EntityDep-RB_Business_Interests-date_of_join | C10: 729a8d4a-f729-45f9-94ad-17420f865f2d | D10: EntityDep-RB_Business_Interests-date_of_join | E10: 7d296af3-0586-49fc-ba29-c0269e9a94f9 | F10: Consistency | G10: DED_Attribute_0720 | H10: date_of_join | I10: date_of_join,entity_name,rec_status | J10: DED_Data_Table_063 | K10: VIRTUAL_BUSINESS_INTERESTS_OF_ | L10: rb_business_interests | M10: 2
A11: DQO-2347 | B11: StatusDep-RB_Business_Interests-status | C11: cebc5332-eb83-4689-a48f-d07ef07672c4 | D11: StatusDep-RB_Business_Interests-status | E11: e8964086-611c-4f4b-94a2-b30d5601a82a | F11: Consistency | G11: DED_Attribute_0727 | H11: status | I11: status,entity_name,rec_status | J11: DED_Data_Table_063 | K11: VIRTUAL_BUSINESS_INTERESTS_OF_ | L11: rb_business_interests | M11: 2
A12: DQO-2405 | B12: Acc_Chk-VR_BUSINESS_INTERESTS_OF_-Source_of_PEP | C12: 93a79b11-2852-476f-8356-8fa416202127 | D12: Accuracy_Check-RB_Business_Interests-Source_of_PEP | E12: 400ba501-74e2-47a8-8a2a-f9a3ee6b5916 | F12: Accuracy | G12: DED_Attribute_0726 | H12: Source_of_PEP | I12: source_of_pep | J12: DED_Data_Table_063 | K12: VIRTUAL_BUSINESS_INTERESTS_OF_ | L12: rb_business_interests | M12: 2
A13: DQO-1758 | B13: DataTyp_Chk-rb_bus_intr-dt_of_join | C13: 2ab94d5e-b876-4a70-b70a-11a24b310bf0 | D13: DataTyp_Chk-RB_Business_Interests-dt_of_join | E13: c46a08e5-8bf7-4a78-ba8a-dd8bdc2463af | F13: Conformity | G13: DED_Attribute_0720 | H13: date_of_join | I13: date_of_join,rec_status | J13: DED_Data_Table_063 | K13: VIRTUAL_BUSINESS_INTERESTS_OF_ | L13: rb_business_interests | M13: 2
A14: DQO-1759 | B14: Consec_Spc_Chk-rb_bus_intr-dt_of_join | C14: 1f2a1677-94f9-40f2-a7ba-56b4c0baac6d | D14: Consec_Spc_Chk-RB_Business_Interests-dt_of_join | E14: 0bd51d1d-c3be-4648-9038-8dc8c095fff9 | F14: Conformity | G14: DED_Attribute_0720 | H14: date_of_join | I14: date_of_join,rec_status | J14: DED_Data_Table_063 | K14: VIRTUAL_BUSINESS_INTERESTS_OF_ | L14: rb_business_interests | M14: 2
A15: DQO-1794 | B15: DataTyp_Chk-rb_bus_intr-ent_name | C15: 12c8d249-ffab-4a6b-b8af-f833a24ff797 | D15: DataTyp_Chk-RB_Business_Interests-ent_name | E15: 8dcc3bc9-8cd9-43d6-bc09-47c31ed5159d | F15: Conformity | G15: DED_Attribute_0721 | H15: entity_name | I15: entity_name,rec_status | J15: DED_Data_Table_063 | K15: VIRTUAL_BUSINESS_INTERESTS_OF_ | L15: rb_business_interests | M15: 2
... A24: DQO-1125 | B24: Completeness_Chk-VIRTUAL_SPARE_PART_DETAILS-unit | C24: ff38bda0-ac19-489d-bed8-35858110a316 | D24: Completeness_Chk-IDB_Spare_Part-unit | E24: 42f7c3e8-2331-42ac-a35d-ffcfac5b590d | F24: Completeness | G24: DED_Attribute_1372 | H24: unit | I24: unit,rec_status | J24: DED_Data_Table_101 | K24: VIRTUAL_SPARE_PART_DETAILS | L24: idb_spare_part | M24: 2
A25: DQO-1133 | B25: Freshness_Chk-VIRTUAL_SPARE_PART_DETAILS | C25: 87db84c5-d43f-4078-b09c-161d67a0418f | D25: Freshness_Chk-IDB_Spare_Part | E25: 2ba05ad9-c111-43f0-ad37-f3b294fe5cfb | F25: Timeliness | G25: N/A | H25: NA - Table level rule | I25: 0 | J25: DED_Data_Table_101 | K25: VIRTUAL_SPARE_PART_DETAILS | L25: idb_spare_part | M25: 2
A26: DQO-1158 | B26: Uniqueness_Chk-VIRTUAL_SPARE_PART_DETAILS | C26: 3fa374d3-1e95-4d2f-a316-c58defca7a20 | D26: Uniqueness_Chk-IDB_Spare_Part | E26: 1f628b85-2756-471b-bf8b-8fbcd58b1b35 | F26: Uniqueness | G26: N/A | H26: SERV_PROV_CODE, B1_PER_ID1, B1_PER_ID2, B1_PER_ID3, SPARE_PART_ID | I26: serv_prov_code,b1_per_id1,b1_per_id2,b1_per_id3,spare_part_id | J26: DED_Data_Table_101 | K26: VIRTUAL_SPARE_PART_DETAILS | L26: idb_spare_part | M26: 2
A27: DQO-1350 | B27: Compl_Chk-VIRTUAL_SPARE_PART_DETAILS-chapter | C27: 56293579-2a1d-4ea3-932a-ef1352c72c04 | D27: Compl_Chk-IDB_Spare_Part-chapter | E27: ae6b4d39-fddd-46de-8fe7-936e7ec24252 | F27: Completeness | G27: DED_Attribute_1351 | H27: chapter | I27: chapter,rec_status | J27: DED_Data_Table_101 | K27: VIRTUAL_SPARE_PART_DETAILS | L27: idb_spare_part | M27: 2
A28: DQO-1351 | B28: Compl_Chk-V_SPARE_PAR-duration_to_replace_the_part | C28: fdc9e3a9-d493-4954-aa20-fe1ca8cba3a1 | D28: Compl_Chk-IDB_Spare_P-duration_to_replace_the_part | E28: 7d272a2d-4e9b-46ed-8259-dece8ed328af | F28: Completeness | G28: DED_Attribute_1352 | H28: duration_to_replace_the_part | I28: duration_to_replace_the_part,rec_status | J28: DED_Data_Table_101 | K28: VIRTUAL_SPARE_PART_DETAILS | L28: idb_spare_part | M28: 2
A29: DQO-1352 | B29: Compl_Chk-V_SPARE_PART-hs_code_description_arabic | C29: 7f1eae03-c42b-463d-b566-495c6e9b5a34 | D29: Compl_Chk-IDB_Spare_Par-hs_code_description_arabic | E29: 6866f6cf-1759-426a-9112-3d5ce4e09500 | F29: Completeness | G29: DED_Attribute_1354 | H29: hs_code_description_arabic | I29: hs_code_description_arabic,rec_status | J29: DED_Data_Table_101 | K29: VIRTUAL_SPARE_PART_DETAILS | L29: idb_spare_part | M29: 2
A30: DQO-1353 | B30: Compl_Chk-V_SPARE_PART-hs_code_description_english | C30: 756a4e7d-d5c2-4d10-9d17-50afb8ba56b7 | D30: Compl_Chk-IDB_Spare_Pa-hs_code_description_english | E30: 3f81032c-025d-4731-8f20-1d2dffef61f8 | F30: Completeness | G30: DED_Attribute_1355 | H30: hs_code_description_english | I30: hs_code_description_english,rec_status | J30: DED_Data_Table_101 | K30: VIRTUAL_SPARE_PART_DETAILS | L30: idb_spare_part | M30: 2
A31: DQO-1354 | B31: Compl_Chk-VIRTUAL_SPARE_PART_DETAILS-heading | C31: cdea03a4-3ae7-425a-992c-262dde800268 | D31: Compl_Chk-IDB_Spare_Part-heading | E31: c7174035-3657-40d0-8e7a-4498dcd74dea | F31: Completeness | G31: DED_Attribute_1356 | H31: heading | I31: heading,rec_status | J31: DED_Data_Table_101 | K31: VIRTUAL_SPARE_PART_DETAILS | L31: idb_spare_part | M31: 2
A32: DQO-1355 | B32: Compl_Chk-V_SPARE_P-machine_brand_and_year_of_manu | C32: 5732b5cd-2473-48e4-aa5f-f3528e936f48 | D32: Compl_Chk-IDB_Spare-machine_brand_and_year_of_manu | E32: 6f334409-d31f-45a7-8304-c4cf2785e15b | F32: Completeness | G32: DED_Attribute_1357 | H32: machine_brand_and_year_of_manu | I32: machine_brand_and_year_of_manu,rec_status | J32: DED_Data_Table_101 | K32: VIRTUAL_SPARE_PART_DETAILS | L32: idb_spare_part | M32: 2
A33: DQO-1356 | B33: Compl_Chk-V_SPARE_PART_DETAILS-machine_hs_code | C33: 584a2321-6d8b-437a-91fe-2d8335335e09 | D33: Compl_Chk-IDB_Spare_Part-machine_hs_code | E33: d273b91c-cd09-4ee5-8889-42e590429f1f | F33: Completeness | G33: DED_Attribute_1358 | H33: machine_hs_code | I33: machine_hs_code,rec_status | J33: DED_Data_Table_101 | K33: VIRTUAL_SPARE_PART_DETAILS | L33: idb_spare_part | M33: 2
A34: DQO-1357 | B34: Compl_Chk-V_SPARE_PART_DETAILS-machine_name_list | C34: b18263e9-e2d1-410e-abeb-de6f7406bbc7 | D34: Compl_Chk-IDB_Spare_Part-machine_name_list | E34: 2bf069db-a34d-433c-8f59-e5f95cbdaee8 | F34: Completeness | G34: DED_Attribute_1359 | H34: machine_name_list | I34: machine_name_list,rec_status | J34: DED_Data_Table_101 | K34: VIRTUAL_SPARE_PART_DETAILS | L34: idb_spare_part | M34: 2
A35: DQO-1358 | B35: Compl_Chk-V_SPARE_PAR-machine_name_and_description | C35: 3b9046e8-4c59-4d30-a95c-6795df1c1ae6 | D35: Compl_Chk-IDB_Spare_P-machine_name_and_description | E35: 828c45ad-89b2-4342-9f77-cc3e420f9227 | F35: Completeness | G35: DED_Attribute_1360 | H35: machine_name_and_description | I35: machine_name_and_description,rec_status | J35: DED_Data_Table_101 | K35: VIRTUAL_SPARE_PART_DETAILS | L35: idb_spare_part | M35: 2
A36: DQO-1359 | B36: Compl_Chk-V_SPARE_P-number_of_machines_using_this_ | C36: 7736eb97-41cb-45d8-bce9-6fd1c27dc5cd | D36: Compl_Chk-IDB_Spare-number_of_machines_using_this_ | E36: 292a8f71-89fe-4bf2-9cb5-b6e1ed779de4 | F36: Completeness | G36: DED_Attribute_1362 | H36: number_of_machines_using_this_ | I36: number_of_machines_using_this_,rec_status | J36: DED_Data_Table_101 | K36: VIRTUAL_SPARE_PART_DETAILS | L36: idb_spare_part | M36: 2
A37: DQO-1360 | B37: Compl_Chk-V_SPARE_P-number_of_parts_in_the_machine | C37: a9aa233e-293e-409b-9bae-4217c4d9b7da | D37: Compl_Chk-IDB_Spare-number_of_parts_in_the_machine | E37: 7ca5ad9e-965e-46ce-b234-40ad548bfd75 | F37: Completeness | G37: DED_Attribute_1363 | H37: number_of_parts_in_the_machine | I37: number_of_parts_in_the_machine,rec_status | J37: DED_Data_Table_101 | K37: VIRTUAL_SPARE_PART_DETAILS | L37: idb_spare_part | M37: 2
... A84: DQO-1118 | B84: Completeness_Chk-VIRTUAL_SIGN_BOARD-width | C84: 5ff02c25-1512-4e4a-a00c-5c86d7972649 | D84: Completeness_Chk-Permit_Sign_Board-width | E84: 17719cf5-509a-44e6-92e6-64a45eba985c | F84: Completeness | G84: DED_Attribute_1285 | H84: width | I84: width,rec_status | J84: DED_Data_Table_098 | K84: VIRTUAL_SIGN_BOARD | L84: permit_sign_board | M84: 2
A85: DQO-1144 | B85: Freshness_Chk-VIRTUAL_SIGN_BOARD | C85: c1f4998d-2c25-439e-a005-907b13427c0f | D85: Freshness_Chk-Permit_Sign_Board | E85: 1ab82fda-c629-4c74-9697-de0038328c6c | F85: Timeliness | G85: N/A | H85: NA - Table level rule | I85: 0 | J85: DED_Data_Table_098 | K85: VIRTUAL_SIGN_BOARD | L85: permit_sign_board | M85: 2
A86: DQO-1164 | B86: Uniqueness_Chk-VIRTUAL_SIGN_BOARD | C86: ad39653d-7bda-43af-82b1-68042c1e823a | D86: Uniqueness_Chk-Permit_Sign_Board | E86: c923a0e9-97af-4c78-b88a-941a9c64bdfd | F86: Uniqueness | G86: N/A | H86: SERV_PROV_CODE, B1_PER_ID1, B1_PER_ID2, B1_PER_ID3, ROW_INDEX | I86: serv_prov_code,b1_per_id1,b1_per_id2,b1_per_id3,row_index | J86: DED_Data_Table_098 | K86: VIRTUAL_SIGN_BOARD | L86: permit_sign_board | M86: 2
A87: DQO-1606 | B87: DataTyp_Chk-Virt_Sign_Board-length | C87: d16a6460-dd8d-4dfc-aa04-44b1f4c79e69 | D87: DataTyp_Chk-Permit_Sign_Board-length | E87: 214ff657-19c6-4380-bcb3-001b7bf29cdd | F87: Conformity | G87: DED_Attribute_1282 | H87: length | I87: length,rec_status | J87: DED_Data_Table_098 | K87: VIRTUAL_SIGN_BOARD | L87: permit_sign_board | M87: 2
A88: DQO-1607 | B88: Num_Range_Chk-Virt_Sign_Board-length | C88: 797b4ea4-a8c7-4548-a4b5-6379539da8d0 | D88: Num_Range_Chk-Permit_Sign_Board-length | E88: e07e9309-d5b5-4c6d-8112-37d297e7ff78 | F88: Conformity | G88: DED_Attribute_1282 | H88: length | I88: length,rec_status | J88: DED_Data_Table_098 | K88: VIRTUAL_SIGN_BOARD | L88: permit_sign_board | M88: 2
A89: DQO-1608 | B89: DataTyp_Chk-Virt_Sign_Board-total_area | C89: 0e8a015b-b9b0-459e-a624-5b5f96b2e358 | D89: DataTyp_Chk-Permit_Sign_Board-total_area | E89: df3a4aa8-3ad2-476b-87b7-d40c04414aca | F89: Conformity | G89: DED_Attribute_1284 | H89: total_area | I89: total_area,rec_status | J89: DED_Data_Table_098 | K89: VIRTUAL_SIGN_BOARD | L89: permit_sign_board | M89: 2
A90: DQO-1609 | B90: Num_Range_Chk-Virt_Sign_Board-total_area | C90: ac45d288-24bd-42fc-80a0-f31ba74ddaf4 | D90: Num_Range_Chk-Permit_Sign_Board-total_area | E90: 515ab08d-4a5a-4ae9-9b20-bc4df4fd82cc | F90: Conformity | G90: DED_Attribute_1284 | H90: total_area | I90: total_area,rec_status | J90: DED_Data_Table_098 | K90: VIRTUAL_SIGN_BOARD | L90: permit_sign_board | M90: 2
A91: DQO-1610 | B91: DataTyp_Chk-Virt_Sign_Board-width | C91: b2e6c2eb-2599-4864-abfd-4e1ee5d566b9 | D91: DataTyp_Chk-Permit_Sign_Board-width | E91: 957c57d3-1272-4ede-bfdb-c4de83f273c7 | F91: Conformity | G91: DED_Attribute_1285 | H91: width | I91: width,rec_status | J91: DED_Data_Table_098 | K91: VIRTUAL_SIGN_BOARD | L91: permit_sign_board | M91: 2
A92: DQO-1611 | B92: Num_Range_Chk-Virt_Sign_Board-width | C92: 134f7ee6-cd5f-41af-9b0a-2c65922797f5 | D92: Num_Range_Chk-Permit_Sign_Board-width | E92: 2e11655e-8541-4daa-9c2d-a13e0e15b47a | F92: Conformity | G92: DED_Attribute_1285 | H92: width | I92: width,rec_status | J92: DED_Data_Table_098 | K92: VIRTUAL_SIGN_BOARD | L92: permit_sign_board | M92: 2
A93: DQO-1637 | B93: Area_Calc_Cons_Chk-virtual_sign_board | C93: 9a60739c-f8a3-4415-9aa0-fefae65bda6f | D93: Area_Calc_Cons_Chk-Permit_Sign_Board | E93: baffb06d-3d8a-4824-80e5-4e7cead11765 | F93: Consistency | G93: DED_Attribute_1282 | H93: length | I93: total_area,length,width,rec_status | J93: DED_Data_Table_098 | K93: VIRTUAL_SIGN_BOARD | L93: permit_sign_board | M93: 2
A94: DQO-1138 | B94: Freshness_Chk-VIRTUAL_OFFER_TASTING_CAMPAIGN | C94: a6029e8e-d054-4e35-8e7e-602302daeb27 | D94: Freshness_Chk-Offer_Tasting_Campaign | E94: 0c19d5e3-cb72-4a6b-85da-59f62c70008b | F94: Timeliness | G94: N/A | H94: NA - Table level rule | I94: 0 | J94: DED_Data_Table_085 | K94: VIRTUAL_OFFER_TASTING_CAMPAIGN | L94: offer_tasting_campaign | M94: 2
...

Sheet S3
A1: DQO | B1: Rule_Title_B | C1: Purview_B | D1: Rule_Title_S | E1: Purview_S | F1: Dimension | G1: Attribute_ID | H1: Attribute_Name_From-Rule_Book | I1: Attribute_Name from file | J1: Asset_ID | K1: Asset_Name_B | L1: Asset_Name_S | M1: Sprint
A2: DQO-2816 | B2: Freshness_Check-br_vehicle_info | C2: 74354977-278f-414a-91c9-19cbd2dd4ed4 | D2: Freshness_Check-vehicle_info | E2: ebe3f8c9-42f7-44ab-a950-73f51acba554 | F2: Timeliness | G2: N/A | H2: NA - Table level rule | I2: 0 | J2: DED_Data_Table_234 | K2: br_vehicle_info | L2: vehicle_info | M2: 3
A3: DQO-2868 | B3: Uniqueness_Chk-br_vehicle_info | C3: 4fe6f2f0-048d-4058-8757-8ee0e37004db | D3: Uniqueness_Chk-vehicle_info | E3: e6c54235-c451-46b7-9879-4da37cbbbe5e | F3: Uniqueness | G3: N/A | H3: serv_prov_code, b1_per_id1, b1_per_id2, b1_per_id3, b1_per_type, b1_per_sub_type | I3: serv_prov_code,b1_per_id1,b1_per_id2,b1_per_id3,b1_per_type,b1_per_sub_type | J3: DED_Data_Table_234 | K3: br_vehicle_info | L3: vehicle_info | M3: 3
A4: DQO-3322 | B4: Comp_Check-br_vehicle_info-advertisement_type | C4: 66cb20b9-6585-4543-affc-e08d3da005a9 | D4: Comp_Check-vehicle_info-advertisement_type | E4: 042123b0-b029-4b15-a2b2-cb45e3c7cf39 | F4: Completeness | G4: DED_Attribute_3581 | H4: advertisement_type | I4: advertisement_type,rec_status | J4: DED_Data_Table_234 | K4: br_vehicle_info | L4: vehicle_info | M4: 3
A5: DQO-3323 | B5: Comp_Check-br_vehicle_info-plate_or_chassis_number | C5: 48fec99b-5d7a-4478-a9c5-82b6d404ae0d | D5: Comp_Check-vehicle_info-plate_or_chassis_number | E5: 55f853a9-b760-4ac8-8011-a0dfffa464f8 | F5: Completeness | G5: DED_Attribute_3582 | H5: plate_or_chassis_number | I5: plate_or_chassis_number,rec_status | J5: DED_Data_Table_234 | K5: br_vehicle_info | L5: vehicle_info | M5: 3
A6: DQO-3324 | B6: Completeness_Check-br_vehicle_info-plate_category | C6: f635f932-938a-4b23-983a-6b906b839906 | D6: Completeness_Check-vehicle_info-plate_category | E6: d0ed6e2a-9d4c-4e01-b8ed-567b00de28bc | F6: Completeness | G6: DED_Attribute_3584 | H6: plate_category | I6: plate_category,rec_status | J6: DED_Data_Table_234 | K6: br_vehicle_info | L6: vehicle_info | M6: 3
A7: DQO-3832 | B7: Consec_Spc_Chk-br_vehicle_info-advertisement_type | C7: 38566350-dc23-4c14-bfda-a0ae40236872 | D7: Consec_Chk-vehicle_info-advertisement_type | E7: 6c81ca7b-8272-48dc-9d3c-5c84e43b115c | F7: Conformity | G7: DED_Attribute_3581 | H7: advertisement_type | I7: advertisement_type,rec_status | J7: DED_Data_Table_234 | K7: br_vehicle_info | L7: vehicle_info | M7: 3
A8: DQO-3833 | B8: Consec_Chk-br_vehicle-plate_or_chassis_number | C8: de11a497-9e76-4dda-b450-8a3f751ebadf | D8: Consec_Chk-vehicle_info-plate_or_chassis_number | E8: 3781b14c-65f8-485b-83e9-fc130e0bfd27 | F8: Conformity | G8: DED_Attribute_3582 | H8: plate_or_chassis_number | I8: plate_or_chassis_number,rec_status | J8: DED_Data_Table_234 | K8: br_vehicle_info | L8: vehicle_info | M8: 3
A9: DQO-3834 | B9: Consec_Spc_Chk-br_vehicle_info-plate_category | C9: 73bceaf8-4afd-4ea0-9826-370e22ec3d85 | D9: Consec_Chk-vehicle_info-plate_category | E9: aa6c389a-11f2-4ade-9239-8632f62bbca7 | F9: Conformity | G9: DED_Attribute_3584 | H9: plate_category | I9: plate_category,rec_status | J9: DED_Data_Table_234 | K9: br_vehicle_info | L9: vehicle_info | M9: 3
A10: DQO-3850 | B10: Val_Chk-br_vehicle_info-advertisement_type | C10: cecbe143-89da-4ae8-96a8-fd2409cbb799 | D10: Val_Chk-vehicle_info-advertisement_type | E10: 8952cd38-2e5b-44ac-8533-17e0ad60c063 | F10: Conformity | G10: DED_Attribute_3581 | H10: advertisement_type | I10: advertisement_type,rec_status | J10: DED_Data_Table_234 | K10: br_vehicle_info | L10: vehicle_info | M10: 3
A11: DQO-4178 | B11: Val_Chk-br_vehicle_info-plate_or_chassis_number | C11: 11093150-ca17-4844-805a-e8bbdd234314 | D11: Val_Chk-vehicle_info-plate_or_chassis_number | E11: a84faf4a-9b09-4a0f-8a01-146d054033fc | F11: Conformity | G11: DED_Attribute_3582 | H11: plate_or_chassis_number | I11: plate_or_chassis_number,rec_status | J11: DED_Data_Table_234 | K11: br_vehicle_info | L11: vehicle_info | M11: 3
A12: DQO-2776 | B12: Freshness_Check-br_communication_information | C12: f2d6e45a-b245-4e6a-9ef6-843eb1cffe8b | D12: Freshness_Check-communication_information | E12: 1495efb5-61e2-49cb-9ba0-3f7715ee4066 | F12: Timeliness | G12: N/A | H12: NA - Table level rule | I12: 0 | J12: DED_Data_Table_187 | K12: br_communication_information | L12: communication_information | M12: 3
A13: DQO-2828 | B13: Uniqueness_Chk-br_communication_information | C13: f855ec72-9069-4702-a5d4-2066d0974b07 | D13: Uniqueness_Chk-communication_information | E13: 0b71cff7-3b7a-4a49-b8f9-c7f98ad4d3fa | F13: Uniqueness | G13: N/A | H13: serv_prov_code, b1_per_id1, b1_per_id2, b1_per_id3, b1_per_type, b1_per_sub_type | I13: serv_prov_code,b1_per_id1,b1_per_id2,b1_per_id3,b1_per_type,b1_per_sub_type | J13: DED_Data_Table_187 | K13: br_communication_information | L13: communication_information | M13: 3
A14: DQO-3055 | B14: Comp_Chk-br_com_informati-enterprise_mobile_number | C14: 75d38dc1-51d5-4a79-816a-bfe7155fb416 | D14: Comp_Chk-com_informati-enterprise_mobile_number | E14: 24ed94a7-78d3-4bdc-a1a7-9018219a90f1 | F14: Completeness | G14: DED_Attribute_2830 | H14: enterprise_mobile_number | I14: enterprise_mobile_number,rec_status | J14: DED_Data_Table_187 | K14: br_communication_information | L14: communication_information | M14: 3
A15: DQO-3056 | B15: Comp_Chk-br_communicatio_information-email_address | C15: 318b4e70-dcb5-4c4f-95e8-0dc05ed364f4 | D15: Comp_Chk-communicatio_information-email_address | E15: c6c8ec63-8b77-4d5c-853e-29a1725ebfeb | F15: Completeness | G15: DED_Attribute_2831 | H15: email_address | I15: email_address,rec_status | J15: DED_Data_Table_187 | K15: br_communication_information | L15: communication_information | M15: 3
A16: DQO-3057 | B16: Comp_Chk-br_com_info-authorized_sign_mobile_number | C16: 20e01c36-65c4-49c9-90fd-bbf3678165bd | D16: Comp_Chk-com_info-authorized_sign_mobile_number | E16: 05b6f9d8-7bad-4db5-89f1-eee94195ef46 | F16: Completeness | G16: DED_Attribute_2832 | H16: authorized_signatory_mobile_number | I16: authorized_signatory_mobile_number,rec_status | J16: DED_Data_Table_187 | K16: br_communication_information | L16: communication_information | M16: 3
A17: DQO-3529 | B17: Consec_Chk-br_comm_info-enterprise_mobile_number | C17: 14ee25f1-2597-43ef-a323-eb1d922b4f3a | D17: Consec_Chk-comm_info-enterprise_mobile_number | E17: 687dc888-1e42-4fc8-80ae-e514266f44fd | F17: Conformity | G17: DED_Attribute_2830 | H17: enterprise_mobile_number | I17: enterprise_mobile_number,rec_status | J17: DED_Data_Table_187 | K17: br_communication_information | L17: communication_information | M17: 3
A18: DQO-3530 | B18: Consec_Chk-br_comm_info-email_address | C18: 4e37718c-5b66-412d-aa46-b0545a6924ff | D18: Consec_Chk-communication_information-email_address | E18: 06dce948-fb71-4e21-8641-af7daf25c2a7 | F18: Conformity | G18: DED_Attribute_2831 | H18: email_address | I18: email_address,rec_status | J18: DED_Data_Table_187 | K18: br_communication_information | L18: communication_information | M18: 3
A19: DQO-3531 | B19: Consec_Chk-br_comm_info-auth_signatory_mobile_no | C19: cad119e5-2946-42b7-a87a-fdf89e4c9aa7 | D19: Consec_Chk-com_info-authorized_signatory_mob_nbr | E19: 3b6451ba-94f7-4f86-a416-2a6d7ca95e90 | F19: Conformity | G19: DED_Attribute_2832 | H19: authorized_signatory_mobile_number | I19: authorized_signatory_mobile_number,rec_status | J19: DED_Data_Table_187 | K19: br_communication_information | L19: communication_information | M19: 3
A20: DQO-3939 | B20: LTS_Chk-br_communication_information-email_address | C20: 3f9362f9-1435-40f9-910b-3eac266f8ad9 | D20: LTS_Chk-communication_information-email_address | E20: 2b9f4dc7-7321-4aa2-ac01-703e06f77ee9 | F20: Conformity | G20: DED_Attribute_2831 | H20: email_address | I20: email_address,rec_status | J20: DED_Data_Table_187 | K20: br_communication_information | L20: communication_information | M20: 3
A21: DQO-3953 | B21: Val_Chk-br_communication_info-enterprise_mob_numbr | C21: c5a0939c-e685-40bd-b078-78e8597e1e99 | D21: Val_Chk-communication_info-enterprise_mobile_numbr | E21: 6deae9f5-504d-4e84-bdb3-5c4659bb3b40 | F21: Conformity | G21: DED_Attribute_2830 | H21: enterprise_mobile_number | I21: enterprise_mobile_number,rec_status | J21: DED_Data_Table_187 | K21: br_communication_information | L21: communication_information | M21: 3
A22: DQO-2472 | B22: Validity_Check-br_COMM_INFO-Email_Address | C22: d1c84537-89a5-4dfd-a090-bf1021765ab6 | D22: Validity_Check-COMM_INFO-Email_Address | E22: dfbabc06-5f68-46cd-9502-de63c026d176 | F22: Conformity | G22: DED_Attribute_2831 | H22: email_address | I22: email_address,rec_status | J22: DED_Data_Table_187 | K22: br_communication_information | L22: communication_information | M22: 3
A23: DQO-2781 | B23: Freshness_Check-br_house_information | C23: 1d3b831d-1d1d-4d47-9cd7-43673c7ba95b | D23: Freshness_Check-house_information | E23: 8f3de390-a1ea-47cc-8c65-2477668618ef | F23: Timeliness | G23: N/A | H23: NA - Table level rule | I23: 0 | J23: DED_Data_Table_192 | K23: br_house_information | L23: house_information | M23: 3
A24: DQO-2833 | B24: Uniqueness_Chk-br_house_information | C24: 4857027d-0101-4d52-8d78-54627348fcf8 | D24: Uniqueness_Chk-house_information | E24: de6f9d57-4c98-4776-8ac6-bd68de042c05 | F24: Uniqueness | G24: N/A | H24: serv_prov_code, b1_per_id1, b1_per_id2, b1_per_id3, b1_per_type, b1_per_sub_type | I24: serv_prov_code,b1_per_id1,b1_per_id2,b1_per_id3,b1_per_type,b1_per_sub_type | J24: DED_Data_Table_192 | K24: br_house_information | L24: house_information | M24: 3
A25: DQO-3124 | B25: Comp_Chk-br_hou_inf-allow_insp__ab_fca_enter_home | C25: 84b04a93-6a61-45b3-8bfe-150977ba0239 | D25: Comp_Chk-hou_inf-allow_insp__ab_fca_enter_home | E25: dc5444a3-eec0-44c8-97e6-91eb210922ee | F25: Completeness | G25: DED_Attribute_2956 | H25: allow_the_inspectors_of_the_abu_dhabi_food_control_authority_to_enter_the_house_specified_above_and | I25: allow_the_inspectors_of_the_abu_dhabi_food_control_authority_to_enter_the_house_specified_above_and,rec_status | J25: DED_Data_Table_192 | K25: br_house_information | L25: house_information | M25: 3
A26: DQO-3125 | B26: Comp_Check-br_house_information-building_number | C26: 7ff0a420-d0c9-41c2-8928-047b7277128c | D26: Comp_Check-house_information-building_number | E26: 6b73f90e-4685-4016-8efe-da4d0712c689 | F26: Completeness | G26: DED_Attribute_2957 | H26: building_number | I26: building_number,rec_status | J26: DED_Data_Table_192 | K26: br_house_information | L26: house_information | M26: 3
A27: DQO-3126 | B27: Completeness_Check-br_house_information-mobile_no | C27: 7b193835-05e4-4953-a88c-239ffa8deee3 | D27: Completeness_Check-house_information-mobile_no | E27: 14163141-b0b3-4fd0-baf5-e8ef4ea8dfd0 | F27: Completeness | G27: DED_Attribute_2958 | H27: mobile_no | I27: mobile_no,rec_status | J27: DED_Data_Table_192 | K27: br_house_information | L27: house_information | M27: 3
A28: DQO-3127 | B28: Comp_Check-br_house_information-emirates_id_number | C28: f4c77479-cf3a-4a0b-84da-d44c3b8681df | D28: Comp_Check-house_information-emirates_id_number | E28: 0c54cd11-f5e8-40fa-9495-bbacf2c14385 | F28: Completeness | G28: DED_Attribute_2960 | H28: emirates_id_number | I28: emirates_id_number,rec_status | J28: DED_Data_Table_192 | K28: br_house_information | L28: house_information | M28: 3
A29: DQO-3128 | B29: Completeness_Check-br_house_information-owner_name | C29: 430c41cf-54dd-4d21-824d-534be122b093 | D29: Completeness_Check-house_information-owner_name | E29: cf3ae9c9-3fa0-4d82-96c7-75c613a888e3 | F29: Completeness | G29: DED_Attribute_2961 | H29: owner_name | I29: owner_name,rec_status | J29: DED_Data_Table_192 | K29: br_house_information | L29: house_information | M29: 3
A30: DQO-3129 | B30: Completeness_Check-br_house_information-district | C30: 7cfe423d-fee7-4c0b-a7b2-39fe459efb57 | D30: Completeness_Check-house_information-district | E30: fb1f6c5a-c315-4ae2-8951-eaa3e0bdbd13 | F30: Completeness | G30: DED_Attribute_2962 | H30: district | I30: district,rec_status | J30: DED_Data_Table_192 | K30: br_house_information | L30: house_information | M30: 3
A31: DQO-3600 | B31: Consec_Chk-br_house_info-allow_inspectors_house | C31: 9aca6464-a4a3-4cb7-8764-aff76363f90a | D31: Consec_Chk-house_info-allow_inspectors_enter_house | E31: 069c569b-4941-45be-83af-d006ebd44ce4 | F31: Conformity | G31: DED_Attribute_2956 | H31: allow_the_inspectors_of_the_abu_dhabi_food_control_authority_to_enter_the_house_specified_above_and | I31: allow_the_inspectors_of_the_abu_dhabi_food_control_authority_to_enter_the_house_specified_above_and,rec_status | J31: DED_Data_Table_192 | K31: br_house_information | L31: house_information | M31: 3
A32: DQO-3601 | B32: Consec_Chk-br_house_info-building_number | C32: 06ad5681-6e78-413c-bbfe-f5ce9466b7e3 | D32: Consec_Chk-house_information-building_number | E32: 2cc9bebd-fa43-4c4e-8beb-d7be39b1ef57 | F32: Conformity | G32: DED_Attribute_2957 | H32: building_number | I32: building_number,rec_status | J32: DED_Data_Table_192 | K32: br_house_information | L32: house_information | M32: 3
A33: DQO-3602 | B33: Consec_Spc_Chk-br_house_information-mobile_no | C33: 80197de1-c173-4412-8213-3ae85f4077df | D33: Consec_Chk-house_information-mobile_no | E33: ffb13abf-1dda-4c2b-88b2-47bb71a30387 | F33: Conformity | G33: DED_Attribute_2958 | H33: mobile_no | I33: mobile_no,rec_status | J33: DED_Data_Table_192 | K33: br_house_information | L33: house_information | M33: 3
A34: DQO-3603 | B34: Consec_Chk-br_house_info-emirates_id_number | C34: eb747fde-296b-42a7-b8c7-cc4deb604a33 | D34: Consec_Chk-house_information-emirates_id_number | E34: 41432962-a1f6-48f5-9bec-1da9e2acf564 | F34: Conformity | G34: DED_Attribute_2960 | H34: emirates_id_number | I34: emirates_id_number,rec_status | J34: DED_Data_Table_192 | K34: br_house_information | L34: house_information | M34: 3
A35: DQO-3604 | B35: Consec_Spc_Chk-br_house_information-owner_name | C35: 913ed33e-0991-4762-83d5-ea82750ae0db | D35: Consec_Chk-house_information-owner_name | E35: daa9817a-294c-462b-8ed1-cc2566960c7c | F35: Conformity | G35: DED_Attribute_2961 | H35: owner_name | I35: owner_name,rec_status | J35: DED_Data_Table_192 | K35: br_house_information | L35: house_information | M35: 3
... A43: DQO-2475 | B43: Validity_Check-br_HOUSE_INFO-Emirates_Id_No | C43: a12c1961-254e-4bb6-a6da-301d9e02b268 | D43: Validity_Check-HOUSE_INFO-Emirates_Id_No | E43: 504d103b-b46a-4b88-b1a1-6231f2155a73 | F43: Conformity | G43: DED_Attribute_2960 | H43: emirates_id_number | I43: emirates_id_number,rec_status | J43: DED_Data_Table_192 | K43: br_house_information | L43: house_information | M43: 3
A44: DQO-2782 | B44: Freshness_Check-br_hscode | C44: ce1b9af1-b1d3-4dec-9460-97365223bd84 | D44: Freshness_Check-hscode | E44: fe5a8895-0d87-4b81-9f93-46963dbb7256 | F44: Timeliness | G44: N/A | H44: NA - Table level rule | I44: 0 | J44: DED_Data_Table_193 | K44: br_hscode | L44: hscode | M44: 3
A45: DQO-3130 | B45: Comp_Check-br_hscode-hs_code_arabic_description | C45: 0a0b6541-8497-4e1f-8605-89db58f00d31 | D45: Comp_Check-hscode-hs_code_arabic_description | E45: 77133f77-e9e5-4952-9183-25c15a7df5eb | F45: Completeness | G45: DED_Attribute_2971 | H45: hs_code_arabic_description | I45: hs_code_arabic_description,rec_status | J45: DED_Data_Table_193 | K45: br_hscode | L45: hscode | M45: 3
A46: DQO-3131 | B46: Completeness_Check-br_hscode-hazard_item | C46: 53339466-7bb6-48da-aadf-5d1f19dc63e0 | D46: Completeness_Check-hscode-hazard_item | E46: 82db8d4f-b51a-4a12-a0bf-95c330496501 | F46: Completeness | G46: DED_Attribute_2972 | H46: hazard_item | I46: hazard_item,rec_status | J46: DED_Data_Table_193 | K46: br_hscode | L46: hscode | M46: 3
A47: DQO-3132 | B47: Completeness_Check-br_hscode-spare_part | C47: 8e7ca0ce-ffde-46b5-a3f5-26a6dc12e14e | D47: Completeness_Check-hscode-spare_part | E47: 0e36a6fe-4fd2-449e-9bd1-fac1291679f7 | F47: Completeness | G47: DED_Attribute_2973 | H47: spare_part | I47: spare_part,rec_status | J47: DED_Data_Table_193 | K47: br_hscode | L47: hscode | M47: 3
...

Sheet A
A1: Data Asset ID | B1: Data Asset Name (English, Silver) | C1: Sprint | D1: Domain | E1: Bronze Name
A2: DED_Data_Table_001 | B2: Financial_Audit_Trail | C2: Sprint 1 | D2: Financial Information | E2: ACCOUNTING_AUDIT_TRAIL
A3: DED_Data_Table_002 | B3: Status_Lookup | C3: Sprint 1 | D3: Economic Licenses | E3: APP_STATUS_GROUP
A4: DED_Data_Table_003 | B4: Status_Lookup_Language | C4: Sprint 1 | D4: Economic Licenses | E4: APP_STATUS_GROUP_I18N
A5: DED_Data_Table_004 | B5: Application_Master | C5: Sprint 1 | D5: Economic Licenses | E5: B1PERMIT
A6: DED_Data_Table_005 | B6: License_Expiration | C6: Sprint 1 | D6: Economic Licenses | E6: B1_EXPIRATION
A7: DED_Data_Table_006 | B7: Application_Address | C7: Sprint 1 | D7: Economic Licenses | E7: B3ADDRES
A8: DED_Data_Table_007 | B8: Application_District | C8: Sprint 1 | D8: Economic Licenses | E8: B3ADDRES_DISTRICT
A9: DED_Data_Table_008 | B9: Investor | C9: Sprint 1 | D9: Economic Licenses | E9: B3CONTACT
A10: DED_Data_Table_009 | B10: Company_Name | C10: Sprint 1 | D10: Economic Licenses | E10: B3CONTRA
A11: DED_Data_Table_010 | B11: Requirement_Condition | C11: Sprint 1 | D11: Economic Licenses | E11: B6CONDIT
A12: DED_Data_Table_011 | B12: Requirement_Condition_Dtl | C12: Sprint 1 | D12: Economic Licenses | E12: B6CONDIT_DETAIL
... A139: DED_Data_Table_236 | B139: rapo_attribute_i18n | C139: Sprint 2 | D139: Economic Licenses | E139: RAPO_ATTRIBUTE_I18N

Sheet Sheet1

Sheet T
A1: Data Attribute ID | B1: Data Attribute Name (English, Silver) | C1: Data Asset ID | D1: Data Asset Name (English, Silver)
A2: DED_Attribute_0001 | B2: SERV_PROV_CODE | C2: DED_Data_Table_001 | D2: Financial_Audit_Trail
A3: DED_Attribute_0002 | B3: B1_PER_ID1 | C3: DED_Data_Table_001 | D3: Financial_Audit_Trail
A4: DED_Attribute_0003 | B4: ACC_AUDIT_SEQ_NBR | C4: DED_Data_Table_001 | D4: Financial_Audit_Trail
A5: DED_Attribute_0004 | B5: B1_PER_ID2 | C5: DED_Data_Table_022 | D5: Financial_Audit_Trail
A6: DED_Attribute_0005 | B6: B1_PER_ID3 | C6: DED_Data_Table_001 | D6: Financial_Audit_Trail
A7: DED_Attribute_0006 | B7: INVOICE_NBR | C7: DED_Data_Table_001 | D7: Financial_Audit_Trail
A8: DED_Attribute_0007 | B8: RECEIPT_NBR | C8: DED_Data_Table_001 | D8: Financial_Audit_Trail
A9: DED_Attribute_0008 | B9: PAYMENT_SEQ_NBR | C9: DED_Data_Table_001 | D9: Financial_Audit_Trail
A10: DED_Attribute_0009 | B10: RECEIPT_AMOUNT | C10: DED_Data_Table_001 | D10: Financial_Audit_Trail
A11: DED_Attribute_0010 | B11: ACTION | C11: DED_Data_Table_001 | D11: Financial_Audit_Trail
A12: DED_Attribute_0011 | B12: FEEITEM_SEQ_NBR | C12: DED_Data_Table_001 | D12: Financial_Audit_Trail
... A4384: DED_Attribute_5684 | B4384: zip | C4384: DED_Data_Table_047 | D4384: license_professional

Sheet Sprint 1 Silver Dump
A1: name | B1: rule_id | C1: domain_id | D1: product_id | E1: asset_id | F1: dataset_name | G1: rule_expression_logic | H1: filter_Expression_logic | I1: null_Expression_logic | J1: column | K1: status | L1: dimension | M1: score | N1: type | O1: description | P1: typeProperties
A2: Completeness_Check-Application_Invoice-INVOICE_NBR | B2: d0745851-8329-4553-a2d9-4cfcf98b6cb2 | C2: 5718e0f6-886b-4e80-9980-37bac024cb4e | D2: 0ab78cb4-2cfa-409c-98c9-f784133fa8ff | E2: 93a78fa2-4157-4b13-b61c-06329e3c5377 | F2: application_invoice | J2: invoice_nbr | K2: Active | L2: Completeness | M2: 1 | N2: NotNull | O2: Checks that Application_Invoice-INVOICE_NBR is populated for every in-scope record and is not null, blank, or whitespace-only. Business meaning: Invoice number associated with the financial transaction recorded in the audit trail. | P2: {'column': {'type': 'Column', 'value': 'invoice_nbr'}}
A3: DataTypeValidity_Check- Appl_Inv-INVOICE_NBR | B3: 842f973e-0bb7-4e98-b887-21ac21339054 | C3: 5718e0f6-886b-4e80-9980-37bac024cb4e | D3: 0ab78cb4-2cfa-409c-98c9-f784133fa8ff | E3: 93a78fa2-4157-4b13-b61c-06329e3c5377 | F3: application_invoice | J3: invoice_nbr | K3: Active | L3: Consistency | M3: 1 | N3: TypeMatch | O3: Checks that Application_Invoice-INVOICE_NBR conforms to the expected source/Purview data type (NUMBER) so the value can be parsed and used consistently. Business meaning: Invoice number associated with the financial transaction recorded in the audit trail. | P3: {'column': {'type': 'Column', 'value': 'invoice_nbr'}}
A4: NumericValidity_Check-Appl_Inv-INVOICE_NBR | B4: eb731fa7-08c6-4d5d-a3d6-a66d17816269 | C4: 5718e0f6-886b-4e80-9980-37bac024cb4e | D4: 0ab78cb4-2cfa-409c-98c9-f784133fa8ff | E4: 93a78fa2-4157-4b13-b61c-06329e3c5377 | F4: application_invoice | G4: invoice_nbr >= 0 | H4: rec_status = 'A' AND invoice_nbr IS NOT NULL | J4: invoice_nbr,rec_status | K4: Active | L4: Conformity | M4: 1 | N4: CustomSQL | O4: Checks that non-null Application_Invoice-INVOICE_NBR values are positive whole-number identifiers, rejecting decimals, zero, negative, and non-numeric values. Business meaning: Invoice number associated with the financial transaction recorded in the audit trail. | P4: {'condition': 'invoice_nbr >= 0', 'columns': [{'value': 'invoice_nbr', 'type': 'Column'}, {'value': 'rec_status', 'type': 'Column'}], 'emptyCriteria': None, 'filterCriteria': "rec_status = 'A' AND invoice_nbr IS NOT NULL", 'ruleDialect': 'SparkSQL'}
A5: Completeness_Check-Appl_Inv-INVOICE_AMOUNT | B5: a5d78de9-918a-45f7-933a-8fc6ad551cf0 | C5: 5718e0f6-886b-4e80-9980-37bac024cb4e | D5: 0ab78cb4-2cfa-409c-98c9-f784133fa8ff | E5: 93a78fa2-4157-4b13-b61c-06329e3c5377 | F5: application_invoice | J5: invoice_amount | K5: Active | L5: Completeness | M5: 1 | N5: NotNull | O5: Checks that Application_Invoice-INVOICE_AMOUNT is populated for every in-scope record and is not null, blank, or whitespace-only. Business meaning: Amount of money associated with the financial item (fee, payment, refund, or adjustment) recorded for this transaction. | P5: {'column': {'type': 'Column', 'value': 'invoice_amount'}}
A6: DataTypeValidity_Check-Appl_Inv-INVOICE_AMOUNT | B6: 0a8f8f4d-9802-40f9-bb3a-a3de9d839fc4 | C6: 5718e0f6-886b-4e80-9980-37bac024cb4e | D6: 0ab78cb4-2cfa-409c-98c9-f784133fa8ff | E6: 93a78fa2-4157-4b13-b61c-06329e3c5377 | F6: application_invoice | J6: invoice_amount | K6: Active | L6: Consistency | M6: 1 | N6: TypeMatch | O6: Checks that Application_Invoice-INVOICE_AMOUNT conforms to the expected source/Purview data type (NUMBER) so the value can be parsed and used consistently. Business meaning: Amount of money associated with the financial item (fee, payment, refund, or adjustment) recorded for this transaction. | P6: {'column': {'type': 'Column', 'value': 'invoice_amount'}}
A7: RangeValidity_Check-Appl_Inv-INVOICE_AMOUNT | B7: 84be5831-a889-4861-bc7b-26192148d3f1 | C7: 5718e0f6-886b-4e80-9980-37bac024cb4e | D7: 0ab78cb4-2cfa-409c-98c9-f784133fa8ff | E7: 93a78fa2-4157-4b13-b61c-06329e3c5377 | F7: application_invoice | G7: invoice_amount >= 0 | J7: invoice_amount | K7: Disabled | L7: Conformity | M7: 0.8785779 | N7: CustomSQL | O7: Checks Application_Invoice.INVOICE_AMOUNT with the configured Purview Regex to enforce: >= 99.5% non-negative, with documented exceptions for voids, refunds, adjustments, and reversals.. Business meaning: Amount of money associated with the financial item (fee, payment, refund, or adjustment) recorded for this transaction. | P7: {'condition': ' invoice_amount >= 0', 'columns': [{'value': 'invoice_amount', 'type': 'Column'}], 'ruleDialect': 'SparkSQL'}
A8: Completeness_Check-Appl_Inv-INVOICE_DATE | B8: 9fc68d2e-cf36-4bed-bbb0-22fdeb181241 | C8: 5718e0f6-886b-4e80-9980-37bac024cb4e | D8: 0ab78cb4-2cfa-409c-98c9-f784133fa8ff | E8: 93a78fa2-4157-4b13-b61c-06329e3c5377 | F8: application_invoice | J8: invoice_date | K8: Active | L8: Completeness | M8: 1 | N8: NotNull | O8: Checks that Application_Invoice-INVOICE_DATE is populated for every in-scope record and is not null, blank, or whitespace-only. Business meaning: Business date associated with this record event (creation, update, status change, or processing), used for reporting and audit tracking. | P8: {'column': {'type': 'Column', 'value': 'invoice_date'}}
A9: DataTypeValidity_Check-Appl_Inv-INVOICE_DATE | B9: bec351be-650f-4fb7-b8e9-fb2e383bee44 | C9: 5718e0f6-886b-4e80-9980-37bac024cb4e | D9: 0ab78cb4-2cfa-409c-98c9-f784133fa8ff | E9: 93a78fa2-4157-4b13-b61c-06329e3c5377 | F9: application_invoice | J9: invoice_date | K9: Active | L9: Consistency | M9: 1 | N9: TypeMatch | O9: Checks that Application_Invoice-INVOICE_DATE conforms to the expected source/Purview data type (DATE) so the value can be parsed and used consistently. Business meaning: Business date associated with this record event (creation, update, status change, or processing), used for reporting and audit tracking. | P9: {'column': {'type': 'Column', 'value': 'invoice_date'}}
A10: DupRows_Check-Appl_Inv-SERV_PROV_CODE_INVOICE_NBR | B10: 8375ac64-aea6-4421-bcac-937afe68e528 | C10: 5718e0f6-886b-4e80-9980-37bac024cb4e | D10: 0ab78cb4-2cfa-409c-98c9-f784133fa8ff | E10: 93a78fa2-4157-4b13-b61c-06329e3c5377 | F10: application_invoice | J10: serv_prov_code,invoice_nbr | K10: Active | L10: Accuracy | M10: 1 | N10: Duplicate | O10: Checks that Application_Invoice has no duplicate active logical records for the approved business key (SERV_PROV_CODE, INVOICE_NBR). | P10: {'columns': [{'value': 'serv_prov_code', 'type': 'Column'}, {'value': 'invoice_nbr', 'type': 'Column'}]}
A11: Freshness_Check-SLA-Appl_Inv | B11: 3de58782-3397-4045-af8c-a98eb905dc8e | C11: 5718e0f6-886b-4e80-9980-37bac024cb4e | D11: 0ab78cb4-2cfa-409c-98c9-f784133fa8ff | E11: 93a78fa2-4157-4b13-b61c-06329e3c5377 | F11: application_invoice | G11: 172800000 | K11: Active | L11: Timeliness | M11: 1 | N11: Timeliness | O11: Checks that the Application_Invoice asset is refreshed within the approved operational SLA so its CDE values remain current for reporting and downstream consumption. | P11: {'timeDifference': 172800000}
A12: Concistency_Check-Appl_Inv-Invoice_Amt | B12: 666e2480-1776-431f-8061-635ec42fa7f6 | C12: 5718e0f6-886b-4e80-9980-37bac024cb4e | D12: 0ab78cb4-2cfa-409c-98c9-f784133fa8ff | E12: 93a78fa2-4157-4b13-b61c-06329e3c5377 | F12: application_invoice | G12: invoice_amount IS NOT NULL OR (invoice_date IS NOT NULL AND invoice_amount IS NOT NULL) | J12: invoice_amount,invoice_date | K12: Active | L12: Consistency | M12: 1 | N12: CustomSQL | O12: Checks that related fields in Application_Invoice satisfy the invoice amount/date consistency condition using a single-dataset Purview Custom row expression. Expected outcome: 100% of invoice amount records must have an invoice date. This prevents logically incomplete or inconsistent records without requiring cross-table joins. | P12: {'condition': 'invoice_amount IS NOT NULL OR (invoice_date IS NOT NULL AND invoice_amount IS NOT NULL)', 'filterCriteria': '', 'columns': [{'value': 'invoice_amount', 'type': 'Column'}, {'value': 'invoice_date', 'type': 'Column'}], 'ruleDialect': 'SparkSQL'}
